Workbook

Sheet 使用说明
A1: 项目 | B1: 使用方法与公式 | C1: 意义及简化范围
A2: 先改配置 | B2: 配置与结果B6:E9选择基准/对比塑造和原心相增幅。面板B15:K18输入自己的装备后数值。 | C2: 基准和对比共用面板、木桩、流程，只比较所选效果变化。
A3: 看结果 | B3: H/I为基准/对比，J差额，K比例。逐档收益每行改变一项配置。 | C3: 全队期望包含队友收益；一名辅助的收益不等于仅看自己的伤害。
A4: 百分比输入 | B4: 暴击率70%输入70%。总暴创202.5%输入202.5%。倍率1500%在效果参数填1500%。 | C4: Excel保存为数值，不要输入文本。显示暴创的精度可依自己游戏面板依据修正。
A5: 当前角色与心相 | B5: 红弩箭SP、37狂想IV、小瑞安侬、J狂想IV，原四种心相Lv60。 | C5: 可改变0～5塑与1～5增幅。换心相类型需新增完整效果及重新录入装备面板，本版没有自动换装功能。
A6: 固定流程 | B6: 固定流程页仅供查看：36次行动、3个普通回合＋13次洞穿，4次补充算式、2次黑莓。当前只比较配置，不在Excel内修改牌序。 | C6: 不模拟随机发牌、行动点、激情、灵光、使役能量、洞知点和额外行动机会。流程用于同口径比较，不表示所有0塑配置都能开局照此打。
A7: 状态近似 | B7: 短窗口内触发的群鸟、数维、雨声、灵犀、J团队增伤等不计算到期。灵犀按回合开始及普通咒语消费默契累积并限上限。 | C7: 不追踪灵犀分批到期、回合末默契、额外回合。37持续时间塑造及小瑞能量塑造收益可能被低估。
A8: 红弩箭计时 | B8: 按普通回合推进雷鸣/极限，回合末雷鸣+3增压，首次俯冲按塑造+1/+2，满10下回合进入极限2回合。 | C8: 洞穿不消耗此计时。固定高阶牌不核算获取，部分塑造预备牌收益没有计入。
A9: J燃烧 | B9: 默认自身按该塑造燃烧上限、木桩预置30层。H24改0可比较指定固定层数。 | C9: 没有燃烧伤害、扣层、护盾或受击反击。J硬度测试仍计反击，伤后叠家庭仪式威力。J1塑高温回火提升在本木桩可能显示0收益，属于场景限制。
A10: J仪式疑点 | B10: 有效溢出倍率=游戏文本×H27。默认H27=2：0塑每层100%，4塑起按文本75%推算为150%。 | C10: 0塑100%由原测试支持；4塑/5塑150%尚未独立测试。可将H27改1看游戏文本口径。
A11: 有效攻击 | B11: 战前攻击×角色百分比增益＋数维固定攻击＋尘酿鹰固定攻击，再向下取整。数维和尘酿鹰用各自施放时近似快照。 | C11: 小瑞入战5%与雨声入战攻击另加；J每层燃烧攻击按塑造/狂想。心相静态属性已在输入面板，不重复加。
A12: 主伤 | B12: MAX(攻击×最低攻防比例，攻击−有效防御)×技能倍率×普通创伤区×威力区×克制区。分别算不暴击、暴击并取整。 | C12: 普通创伤区含角色伤加、雨声、瑞升华、J团队、反击伤加，减去木桩固定受创减免。
... A22: 使用建议 | B22: 一次只改一个选项，比较角色与全队两种收益；再改木桩防御/暴防，看结论是否稳定。 | C22: 没有实测伤害输入参与结果。其他玩家可按自己的面板使用同一固定流程估算。

Sheet 配置与结果
A1: 洞知队固定流程配置对比
A2: 固定3个普通回合＋1次洞穿。木桩不攻击、不施加状态。结果按暴击概率加权，用于比较塑造及原心相的增幅收益。黄色可改，绿色为公式。
A5: 角色 | B5: 基准塑造 | C5: 对比塑造 | D5: 基准增幅 | E5: 对比增幅 | F5: 固定心相 | G5: 结果 | H5: 基准 | I5: 对比 | J5: 差额 | K5: 提升率 | L5: 说明
A6: 红弩箭 | B6: 0 | C6: 2 | D6: 5 | E6: 5 | F6: 立于风暴脊 | G6: 全队合计 | H6: =IF(ISNUMBER(方案参数!M3),方案参数!M3,"") -> 8766612 | I6: =IF(ISNUMBER(方案参数!M4),方案参数!M4,"") -> 13566810 | J6: =IF(AND(ISNUMBER(H6),ISNUMBER(I6)),I6-H6,"") -> 4800198 | K6: =IF(AND(ISNUMBER(H6),ISNUMBER(I6),H6>0),I6/H6-1,"") -> 0.54755452 | L6: =IF(AND(ISNUMBER(H6),ISNUMBER(I6)),"固定流程期望","待补效果参数") -> 固定流程期望
A7: 37 | B7: 0 | C7: 0 | D7: 1 | E7: 1 | F7: 灵知当齐一 | G7: 普通阶段 | H7: =IF(ISNUMBER(方案参数!N3),方案参数!N3,"") -> 3133250.7 | I7: =IF(ISNUMBER(方案参数!N4),方案参数!N4,"") -> 4620699.7 | J7: =IF(AND(ISNUMBER(H7),ISNUMBER(I7)),I7-H7,"") -> 1487449 | K7: =IF(AND(ISNUMBER(H7),ISNUMBER(I7),H7>0),I7/H7-1,"") -> 0.47473029 | L7: =IF(AND(ISNUMBER(H7),ISNUMBER(I7)),"固定流程期望","待补效果参数") -> 固定流程期望
A8: 小瑞安侬 | B8: 0 | C8: 0 | D8: 5 | E8: 5 | F8: 昨日雨声轻 | G8: 洞穿阶段 | H8: =IF(ISNUMBER(方案参数!O3),方案参数!O3,"") -> 5633361.3 | I8: =IF(ISNUMBER(方案参数!O4),方案参数!O4,"") -> 8946110.3 | J8: =IF(AND(ISNUMBER(H8),ISNUMBER(I8)),I8-H8,"") -> 3312749 | K8: =IF(AND(ISNUMBER(H8),ISNUMBER(I8),H8>0),I8/H8-1,"") -> 0.58805904 | L8: =IF(AND(ISNUMBER(H8),ISNUMBER(I8)),"固定流程期望","待补效果参数") -> 固定流程期望
A9: J | B9: 0 | C9: 0 | D9: 1 | E9: 1 | F9: 家庭指导员 | G9: 红弩箭合计 | H9: =IF(ISNUMBER(方案参数!P3),方案参数!P3,"") -> 7363386 | I9: =IF(ISNUMBER(方案参数!P4),方案参数!P4,"") -> 12163584 | J9: =IF(AND(ISNUMBER(H9),ISNUMBER(I9)),I9-H9,"") -> 4800198 | K9: =IF(AND(ISNUMBER(H9),ISNUMBER(I9),H9>0),I9/H9-1,"") -> 0.65190091 | L9: =IF(AND(ISNUMBER(H9),ISNUMBER(I9)),"固定流程期望","待补效果参数") -> 固定流程期望
G10: 37合计 | H10: =IF(ISNUMBER(方案参数!Q3),方案参数!Q3,"") -> 642844.12 | I10: =IF(ISNUMBER(方案参数!Q4),方案参数!Q4,"") -> 642844.12 | J10: =IF(AND(ISNUMBER(H10),ISNUMBER(I10)),I10-H10,"") -> 0 | K10: =IF(AND(ISNUMBER(H10),ISNUMBER(I10),H10>0),I10/H10-1,"") -> 0 | L10: =IF(AND(ISNUMBER(H10),ISNUMBER(I10)),"固定流程期望","待补效果参数") -> 固定流程期望
A11: 面板使用已装备原心相后的战前数值。增幅仅改变战斗效果，不重复加静态属性。37/J固定狂想IV。其他心相换装不在本版范围。 | G11: 小瑞安侬合计 | H11: =IF(ISNUMBER(方案参数!R3),方案参数!R3,"") -> 489818.29 | I11: =IF(ISNUMBER(方案参数!R4),方案参数!R4,"") -> 489818.29 | J11: =IF(AND(ISNUMBER(H11),ISNUMBER(I11)),I11-H11,"") -> 0 | K11: =IF(AND(ISNUMBER(H11),ISNUMBER(I11),H11>0),I11/H11-1,"") -> 0 | L11: =IF(AND(ISNUMBER(H11),ISNUMBER(I11)),"固定流程期望","待补效果参数") -> 固定流程期望
G12: J合计 | H12: =IF(ISNUMBER(方案参数!S3),方案参数!S3,"") -> 270563.56 | I12: =IF(ISNUMBER(方案参数!S4),方案参数!S4,"") -> 270563.56 | J12: =IF(AND(ISNUMBER(H12),ISNUMBER(I12)),I12-H12,"") -> 0 | K12: =IF(AND(ISNUMBER(H12),ISNUMBER(I12),H12>0),I12/H12-1,"") -> 0 | L12: =IF(AND(ISNUMBER(H12),ISNUMBER(I12)),"固定流程期望","待补效果参数") -> 固定流程期望
A14: 角色 | B14: 攻击 | C14: 生命 | D14: 暴击率 | E14: 计算暴创 | F14: 创伤加成 | G14: 术法威力 | H14: 仪式威力 | I14: 穿透率 | J14: 本源增益 | K14: 自然克制？ | L14: 说明
A15: 红弩箭 | B15: 2296 | C15: 9354 | D15: 0.7 | E15: 2.025 | F15: 0.1 | G15: 0 | H15: 0 | I15: 0 | J15: 0 | K15: 0 | L15: 显示202.6%，本例按202.5%计算
A16: 37 | B16: 2306 | C16: 11089 | D16: 0.46 | E16: 1.928 | F16: 0.005 | G16: 0 | H16: 0 | I16: 0 | J16: 0 | K16: 0 | L16: 洞悉15%＋灵知暴创按增幅
A17: 小瑞安侬 | B17: 2597 | C17: 12240 | D17: 0.255 | E17: 1.55 | F17: 0.035 | G17: 0 | H17: 0 | I17: 0 | J17: 0 | K17: 0 | L17: 心相入战攻击及洞悉另加
A18: J | B18: 1906 | C18: 12876 | D18: 0.367 | E18: 1.717 | F18: 0.025 | G18: 0 | H18: 0 | I18: 0 | J18: 0 | K18: 0 | L18: 显示171.8%，本例按171.7%计算
A20: 计算暴创为总倍率：202.5%请输入202.5%，不是102.5%。自然克制0=不克制、1=克制。黑莓固定视为克制。生命只保留面板信息，当前木桩模型没有生命比例增伤。
A23: 木桩基础属性（全程固定） | G23: 简化场景假设
A24: 现实防御 | B24: 1200 | C24: 所有现实攻击使用此防御 | G24: J燃烧取角色上限 | H24: 1 | I24: 1=比较满燃烧；0=使用下行固定层数
A25: 精神防御 | B25: 1000 | C25: 所有精神攻击使用此防御 | G25: J固定燃烧层数 | H25: 35 | I25: 选择0时生效，仍不超过该塑造上限
A26: 暴击防御 | B26: 0.4 | C26: 从暴击创伤扣百分点 | G26: 木桩预置燃烧 | H26: 30 | I26: 仅算J仪式溢出，不模拟结算及扣层
A27: 抗暴率 | B27: 0 | C27: 从角色暴击概率扣百分点 | G27: J溢出实测/文本比例 | H27: 2 | I27: 0塑文本50%，本例有效100%；高塑按相同比例推算，未独立验证
A28: 普通受创减免 | B28: 0.4 | C28: 普通创伤乘区扣减 | G28: 固定追击次数 | H28: 4 | I28: 37补充算式固定4次；不随灵光生成变化
A29: 洞知受创减免 | B29: 0 | C29: 洞知威力区扣减 | G29: 状态持续时间 | H29: 短循环近似 | I29: 增益一旦触发，本窗口内不再到期；用于配置相对收益
A30: 直接本源减免 | B30: 0 | C30: 仅影响37技能自带本源 | G30: 洞穿开始 | H30: 固定第3回合后 | I30: 不计算洞知点及提前进入收益
A31: 最低攻防比例 | B31: 0.1 | C31: 高防时攻防项最低为攻击×此比例 | G31: 受击反击次数 | H31: 0 | I31: 木桩不攻击，高温回火不触发
A32: 普通创伤区下限 | B32: 0.3 | C32: 与原验证模型保持一致
A33: 基础克制加成 | B33: 0.3 | C33: 克制基础倍率1＋此值
A35: 木桩没有关卡仰望、保守主义、分段生命减伤、非克制追加暴防及全员术法−40%。角色产生的创伤、暴防降低及洞知减免降低仍计算为技能修正。各方案共用相同流程和木桩。
A38: 看逐档收益：每次只改变一名角色的塑造或心相增幅，其余配置保持基准。增量=本档相对上一档；累计=本档相对0塑或增幅1。固定流程忽略额外行动机会、提前洞穿和卡牌获取收益。缺失参数时不显示受影响结果。

Sheet 逐档收益
A1: 塑造与心相逐档收益
A2: 每行仅替换一名角色的一个配置项，其余角色保持配置与结果页的基准。上一档提升按相邻档比较；累计按0塑/增幅1比较。普通阶段在红0塑洞知参数缺失时仍可显示。
A5: 变化项 | B5: 档位 | C5: 全队期望 | D5: 上一档提升 | E5: 累计提升 | F5: 该角色期望 | G5: 普通阶段 | H5: 洞穿阶段 | I5: 说明
A6: 红弩箭 | B6: 0 | C6: =IF(ISNUMBER(方案参数!M5),方案参数!M5,"") -> 8766612 | D6: ="" | E6: =IF(AND(ISNUMBER(方案参数!M5),ISNUMBER(方案参数!M5),方案参数!M5>0),方案参数!M5/方案参数!M5-1,"") -> 0 | F6: =IF(ISNUMBER(方案参数!P5),方案参数!P5,"") -> 7363386 | G6: =IF(ISNUMBER(方案参数!N5),方案参数!N5,"") -> 3133250.7 | H6: =IF(ISNUMBER(方案参数!O5),方案参数!O5,"") -> 5633361.3 | I6: =IF(ISNUMBER(C6),"固定次数的相对收益","待补参数；普通阶段可单独查看") -> 固定次数的相对收益
A7: 红弩箭 | B7: 1 | C7: =IF(ISNUMBER(方案参数!M6),方案参数!M6,"") -> 12079361 | D7: =IF(AND(ISNUMBER(方案参数!M6),ISNUMBER(方案参数!M5),方案参数!M5>0),方案参数!M6/方案参数!M5-1,"") -> 0.37788247 | E7: =IF(AND(ISNUMBER(方案参数!M6),ISNUMBER(方案参数!M5),方案参数!M5>0),方案参数!M6/方案参数!M5-1,"") -> 0.37788247 | F7: =IF(ISNUMBER(方案参数!P6),方案参数!P6,"") -> 10676135 | G7: =IF(ISNUMBER(方案参数!N6),方案参数!N6,"") -> 3133250.7 | H7: =IF(ISNUMBER(方案参数!O6),方案参数!O6,"") -> 8946110.3 | I7: =IF(ISNUMBER(C7),"固定次数的相对收益","待补参数；普通阶段可单独查看") -> 固定次数的相对收益
A8: 红弩箭 | B8: 2 | C8: =IF(ISNUMBER(方案参数!M7),方案参数!M7,"") -> 13566810 | D8: =IF(AND(ISNUMBER(方案参数!M7),ISNUMBER(方案参数!M6),方案参数!M6>0),方案参数!M7/方案参数!M6-1,"") -> 0.12313971 | E8: =IF(AND(ISNUMBER(方案参数!M7),ISNUMBER(方案参数!M5),方案参数!M5>0),方案参数!M7/方案参数!M5-1,"") -> 0.54755452 | F8: =IF(ISNUMBER(方案参数!P7),方案参数!P7,"") -> 12163584 | G8: =IF(ISNUMBER(方案参数!N7),方案参数!N7,"") -> 4620699.7 | H8: =IF(ISNUMBER(方案参数!O7),方案参数!O7,"") -> 8946110.3 | I8: =IF(ISNUMBER(C8),"固定次数的相对收益","待补参数；普通阶段可单独查看") -> 固定次数的相对收益
A9: 红弩箭 | B9: 3 | C9: =IF(ISNUMBER(方案参数!M8),方案参数!M8,"") -> 15110630 | D9: =IF(AND(ISNUMBER(方案参数!M8),ISNUMBER(方案参数!M7),方案参数!M7>0),方案参数!M8/方案参数!M7-1,"") -> 0.11379388 | E9: =IF(AND(ISNUMBER(方案参数!M8),ISNUMBER(方案参数!M5),方案参数!M5>0),方案参数!M8/方案参数!M5-1,"") -> 0.72365676 | F9: =IF(ISNUMBER(方案参数!P8),方案参数!P8,"") -> 13707404 | G9: =IF(ISNUMBER(方案参数!N8),方案参数!N8,"") -> 6164519.7 | H9: =IF(ISNUMBER(方案参数!O8),方案参数!O8,"") -> 8946110.3 | I9: =IF(ISNUMBER(C9),"固定次数的相对收益","待补参数；普通阶段可单独查看") -> 固定次数的相对收益
A10: 红弩箭 | B10: 4 | C10: =IF(ISNUMBER(方案参数!M9),方案参数!M9,"") -> 16284949 | D10: =IF(AND(ISNUMBER(方案参数!M9),ISNUMBER(方案参数!M8),方案参数!M8>0),方案参数!M9/方案参数!M8-1,"") -> 0.077714761 | E10: =IF(AND(ISNUMBER(方案参数!M9),ISNUMBER(方案参数!M5),方案参数!M5>0),方案参数!M9/方案参数!M5-1,"") -> 0.85761033 | F10: =IF(ISNUMBER(方案参数!P9),方案参数!P9,"") -> 14881723 | G10: =IF(ISNUMBER(方案参数!N9),方案参数!N9,"") -> 7338838.7 | H10: =IF(ISNUMBER(方案参数!O9),方案参数!O9,"") -> 8946110.3 | I10: =IF(ISNUMBER(C10),"固定次数的相对收益","待补参数；普通阶段可单独查看") -> 固定次数的相对收益
A11: 红弩箭 | B11: 5 | C11: =IF(ISNUMBER(方案参数!M10),方案参数!M10,"") -> 20939648 | D11: =IF(AND(ISNUMBER(方案参数!M10),ISNUMBER(方案参数!M9),方案参数!M9>0),方案参数!M10/方案参数!M9-1,"") -> 0.28582828 | E11: =IF(AND(ISNUMBER(方案参数!M10),ISNUMBER(方案参数!M5),方案参数!M5>0),方案参数!M10/方案参数!M5-1,"") -> 1.3885679 | F11: =IF(ISNUMBER(方案参数!P10),方案参数!P10,"") -> 19536422 | G11: =IF(ISNUMBER(方案参数!N10),方案参数!N10,"") -> 7338838.7 | H11: =IF(ISNUMBER(方案参数!O10),方案参数!O10,"") -> 13600809 | I11: =IF(ISNUMBER(C11),"固定次数的相对收益","待补参数；普通阶段可单独查看") -> 固定次数的相对收益
A12: 37 | B12: 0 | C12: =IF(ISNUMBER(方案参数!M11),方案参数!M11,"") -> 8766612 | D12: ="" | E12: =IF(AND(ISNUMBER(方案参数!M11),ISNUMBER(方案参数!M11),方案参数!M11>0),方案参数!M11/方案参数!M11-1,"") -> 0 | F12: =IF(ISNUMBER(方案参数!Q11),方案参数!Q11,"") -> 642844.12 | G12: =IF(ISNUMBER(方案参数!N11),方案参数!N11,"") -> 3133250.7 | H12: =IF(ISNUMBER(方案参数!O11),方案参数!O11,"") -> 5633361.3 | I12: =IF(ISNUMBER(C12),"固定次数的相对收益","待补参数；普通阶段可单独查看") -> 固定次数的相对收益
A13: 37 | B13: 1 | C13: =IF(ISNUMBER(方案参数!M12),方案参数!M12,"") -> 8981207.9 | D13: =IF(AND(ISNUMBER(方案参数!M12),ISNUMBER(方案参数!M11),方案参数!M11>0),方案参数!M12/方案参数!M11-1,"") -> 0.02447877 | E13: =IF(AND(ISNUMBER(方案参数!M12),ISNUMBER(方案参数!M11),方案参数!M11>0),方案参数!M12/方案参数!M11-1,"") -> 0.02447877 | F13: =IF(ISNUMBER(方案参数!Q12),方案参数!Q12,"") -> 744289 | G13: =IF(ISNUMBER(方案参数!N12),方案参数!N12,"") -> 3265669.9 | H13: =IF(ISNUMBER(方案参数!O12),方案参数!O12,"") -> 5715538 | I13: =IF(ISNUMBER(C13),"固定次数的相对收益","待补参数；普通阶段可单独查看") -> 固定次数的相对收益
A14: 37 | B14: 2 | C14: =IF(ISNUMBER(方案参数!M13),方案参数!M13,"") -> 11519916 | D14: =IF(AND(ISNUMBER(方案参数!M13),ISNUMBER(方案参数!M12),方案参数!M12>0),方案参数!M13/方案参数!M12-1,"") -> 0.28266888 | E14: =IF(AND(ISNUMBER(方案参数!M13),ISNUMBER(方案参数!M11),方案参数!M11>0),方案参数!M13/方案参数!M11-1,"") -> 0.31406704 | F14: =IF(ISNUMBER(方案参数!Q13),方案参数!Q13,"") -> 1156054 | G14: =IF(ISNUMBER(方案参数!N13),方案参数!N13,"") -> 3326324.9 | H14: =IF(ISNUMBER(方案参数!O13),方案参数!O13,"") -> 8193591 | I14: =IF(ISNUMBER(C14),"固定次数的相对收益","待补参数；普通阶段可单独查看") -> 固定次数的相对收益
A15: 37 | B15: 3 | C15: =IF(ISNUMBER(方案参数!M14),方案参数!M14,"") -> 12114966 | D15: =IF(AND(ISNUMBER(方案参数!M14),ISNUMBER(方案参数!M13),方案参数!M13>0),方案参数!M14/方案参数!M13-1,"") -> 0.051654062 | E15: =IF(AND(ISNUMBER(方案参数!M14),ISNUMBER(方案参数!M11),方案参数!M11>0),方案参数!M14/方案参数!M11-1,"") -> 0.38194394 | F15: =IF(ISNUMBER(方案参数!Q14),方案参数!Q14,"") -> 1211568 | G15: =IF(ISNUMBER(方案参数!N14),方案参数!N14,"") -> 3479932.3 | H15: =IF(ISNUMBER(方案参数!O14),方案参数!O14,"") -> 8635034 | I15: =IF(ISNUMBER(C15),"固定次数的相对收益","待补参数；普通阶段可单独查看") -> 固定次数的相对收益
A16: 37 | B16: 4 | C16: =IF(ISNUMBER(方案参数!M15),方案参数!M15,"") -> 12216608 | D16: =IF(AND(ISNUMBER(方案参数!M15),ISNUMBER(方案参数!M14),方案参数!M14>0),方案参数!M15/方案参数!M14-1,"") -> 0.0083897881 | E16: =IF(AND(ISNUMBER(方案参数!M15),ISNUMBER(方案参数!M11),方案参数!M11>0),方案参数!M15/方案参数!M11-1,"") -> 0.39353816 | F16: =IF(ISNUMBER(方案参数!Q15),方案参数!Q15,"") -> 1313210 | G16: =IF(ISNUMBER(方案参数!N15),方案参数!N15,"") -> 3581574.3 | H16: =IF(ISNUMBER(方案参数!O15),方案参数!O15,"") -> 8635034 | I16: =IF(ISNUMBER(C16),"固定次数的相对收益","待补参数；普通阶段可单独查看") -> 固定次数的相对收益
A17: 37 | B17: 5 | C17: =IF(ISNUMBER(方案参数!M16),方案参数!M16,"") -> 15496514 | D17: =IF(AND(ISNUMBER(方案参数!M16),ISNUMBER(方案参数!M15),方案参数!M15>0),方案参数!M16/方案参数!M15-1,"") -> 0.26847926 | E17: =IF(AND(ISNUMBER(方案参数!M16),ISNUMBER(方案参数!M11),方案参数!M11>0),方案参数!M16/方案参数!M11-1,"") -> 0.76767426 | F17: =IF(ISNUMBER(方案参数!Q16),方案参数!Q16,"") -> 1814117 | G17: =IF(ISNUMBER(方案参数!N16),方案参数!N16,"") -> 3581574.3 | H17: =IF(ISNUMBER(方案参数!O16),方案参数!O16,"") -> 11914940 | I17: =IF(ISNUMBER(C17),"固定次数的相对收益","待补参数；普通阶段可单独查看") -> 固定次数的相对收益
A18: 小瑞安侬 | B18: 0 | C18: =IF(ISNUMBER(方案参数!M17),方案参数!M17,"") -> 8766612 | D18: ="" | E18: =IF(AND(ISNUMBER(方案参数!M17),ISNUMBER(方案参数!M17),方案参数!M17>0),方案参数!M17/方案参数!M17-1,"") -> 0 | F18: =IF(ISNUMBER(方案参数!R17),方案参数!R17,"") -> 489818.29 | G18: =IF(ISNUMBER(方案参数!N17),方案参数!N17,"") -> 3133250.7 | H18: =IF(ISNUMBER(方案参数!O17),方案参数!O17,"") -> 5633361.3 | I18: =IF(ISNUMBER(C18),"固定次数的相对收益","待补参数；普通阶段可单独查看") -> 固定次数的相对收益
A19: 小瑞安侬 | B19: 1 | C19: =IF(ISNUMBER(方案参数!M18),方案参数!M18,"") -> 8986839.7 | D19: =IF(AND(ISNUMBER(方案参数!M18),ISNUMBER(方案参数!M17),方案参数!M17>0),方案参数!M18/方案参数!M17-1,"") -> 0.025121192 | E19: =IF(AND(ISNUMBER(方案参数!M18),ISNUMBER(方案参数!M17),方案参数!M17>0),方案参数!M18/方案参数!M17-1,"") -> 0.025121192 | F19: =IF(ISNUMBER(方案参数!R18),方案参数!R18,"") -> 546336.91 | G19: =IF(ISNUMBER(方案参数!N18),方案参数!N18,"") -> 3353478.4 | H19: =IF(ISNUMBER(方案参数!O18),方案参数!O18,"") -> 5633361.3 | I19: =IF(ISNUMBER(C19),"固定次数的相对收益","待补参数；普通阶段可单独查看") -> 固定次数的相对收益
A20: 小瑞安侬 | B20: 2 | C20: =IF(ISNUMBER(方案参数!M19),方案参数!M19,"") -> 9754459.6 | D20: =IF(AND(ISNUMBER(方案参数!M19),ISNUMBER(方案参数!M18),方案参数!M18>0),方案参数!M19/方案参数!M18-1,"") -> 0.085415994 | E20: =IF(AND(ISNUMBER(方案参数!M19),ISNUMBER(方案参数!M17),方案参数!M17>0),方案参数!M19/方案参数!M17-1,"") -> 0.11268294 | F20: =IF(ISNUMBER(方案参数!R19),方案参数!R19,"") -> 1311975.8 | G20: =IF(ISNUMBER(方案参数!N19),方案参数!N19,"") -> 4121098.3 | H20: =IF(ISNUMBER(方案参数!O19),方案参数!O19,"") -> 5633361.3 | I20: =IF(ISNUMBER(C20),"固定次数的相对收益","待补参数；普通阶段可单独查看") -> 固定次数的相对收益
A21: 小瑞安侬 | B21: 3 | C21: =IF(ISNUMBER(方案参数!M20),方案参数!M20,"") -> 10642502 | D21: =IF(AND(ISNUMBER(方案参数!M20),ISNUMBER(方案参数!M19),方案参数!M19>0),方案参数!M20/方案参数!M19-1,"") -> 0.091039677 | E21: =IF(AND(ISNUMBER(方案参数!M20),ISNUMBER(方案参数!M17),方案参数!M17>0),方案参数!M20/方案参数!M17-1,"") -> 0.21398123 | F21: =IF(ISNUMBER(方案参数!R20),方案参数!R20,"") -> 1471186.2 | G21: =IF(ISNUMBER(方案参数!N20),方案参数!N20,"") -> 4550742.1 | H21: =IF(ISNUMBER(方案参数!O20),方案参数!O20,"") -> 6091760.3 | I21: =IF(ISNUMBER(C21),"固定次数的相对收益","待补参数；普通阶段可单独查看") -> 固定次数的相对收益
A22: 小瑞安侬 | B22: 4 | C22: =IF(ISNUMBER(方案参数!M21),方案参数!M21,"") -> 10947941 | D22: =IF(AND(ISNUMBER(方案参数!M21),ISNUMBER(方案参数!M20),方案参数!M20>0),方案参数!M21/方案参数!M20-1,"") -> 0.028699895 | E22: =IF(AND(ISNUMBER(方案参数!M21),ISNUMBER(方案参数!M17),方案参数!M17>0),方案参数!M21/方案参数!M17-1,"") -> 0.24882237 | F22: =IF(ISNUMBER(方案参数!R21),方案参数!R21,"") -> 1471186.2 | G22: =IF(ISNUMBER(方案参数!N21),方案参数!N21,"") -> 4658778.8 | H22: =IF(ISNUMBER(方案参数!O21),方案参数!O21,"") -> 6289162.3 | I22: =IF(ISNUMBER(C22),"固定次数的相对收益","待补参数；普通阶段可单独查看") -> 固定次数的相对收益
A23: 小瑞安侬 | B23: 5 | C23: =IF(ISNUMBER(方案参数!M22),方案参数!M22,"") -> 12584225 | D23: =IF(AND(ISNUMBER(方案参数!M22),ISNUMBER(方案参数!M21),方案参数!M21>0),方案参数!M22/方案参数!M21-1,"") -> 0.14946038 | E23: =IF(AND(ISNUMBER(方案参数!M22),ISNUMBER(方案参数!M17),方案参数!M17>0),方案参数!M22/方案参数!M17-1,"") -> 0.43547184 | F23: =IF(ISNUMBER(方案参数!R22),方案参数!R22,"") -> 3103342 | G23: =IF(ISNUMBER(方案参数!N22),方案参数!N22,"") -> 6295062.3 | H23: =IF(ISNUMBER(方案参数!O22),方案参数!O22,"") -> 6289162.3 | I23: =IF(ISNUMBER(C23),"固定次数的相对收益","待补参数；普通阶段可单独查看") -> 固定次数的相对收益
A24: J | B24: 0 | C24: =IF(ISNUMBER(方案参数!M23),方案参数!M23,"") -> 8766612 | D24: ="" | E24: =IF(AND(ISNUMBER(方案参数!M23),ISNUMBER(方案参数!M23),方案参数!M23>0),方案参数!M23/方案参数!M23-1,"") -> 0 | F24: =IF(ISNUMBER(方案参数!S23),方案参数!S23,"") -> 270563.56 | G24: =IF(ISNUMBER(方案参数!N23),方案参数!N23,"") -> 3133250.7 | H24: =IF(ISNUMBER(方案参数!O23),方案参数!O23,"") -> 5633361.3 | I24: =IF(ISNUMBER(C24),"固定次数的相对收益","待补参数；普通阶段可单独查看") -> 固定次数的相对收益
A25: J | B25: 1 | C25: =IF(ISNUMBER(方案参数!M24),方案参数!M24,"") -> 8766612 | D25: =IF(AND(ISNUMBER(方案参数!M24),ISNUMBER(方案参数!M23),方案参数!M23>0),方案参数!M24/方案参数!M23-1,"") -> 0 | E25: =IF(AND(ISNUMBER(方案参数!M24),ISNUMBER(方案参数!M23),方案参数!M23>0),方案参数!M24/方案参数!M23-1,"") -> 0 | F25: =IF(ISNUMBER(方案参数!S24),方案参数!S24,"") -> 270563.56 | G25: =IF(ISNUMBER(方案参数!N24),方案参数!N24,"") -> 3133250.7 | H25: =IF(ISNUMBER(方案参数!O24),方案参数!O24,"") -> 5633361.3 | I25: =IF(ISNUMBER(C25),"固定次数的相对收益","待补参数；普通阶段可单独查看") -> 固定次数的相对收益
A26: J | B26: 2 | C26: =IF(ISNUMBER(方案参数!M25),方案参数!M25,"") -> 8855228.9 | D26: =IF(AND(ISNUMBER(方案参数!M25),ISNUMBER(方案参数!M24),方案参数!M24>0),方案参数!M25/方案参数!M24-1,"") -> 0.010108461 | E26: =IF(AND(ISNUMBER(方案参数!M25),ISNUMBER(方案参数!M23),方案参数!M23>0),方案参数!M25/方案参数!M23-1,"") -> 0.010108461 | F26: =IF(ISNUMBER(方案参数!S25),方案参数!S25,"") -> 359180.52 | G26: =IF(ISNUMBER(方案参数!N25),方案参数!N25,"") -> 3221867.7 | H26: =IF(ISNUMBER(方案参数!O25),方案参数!O25,"") -> 5633361.3 | I26: =IF(ISNUMBER(C26),"固定次数的相对收益","待补参数；普通阶段可单独查看") -> 固定次数的相对收益
A27: J | B27: 3 | C27: =IF(ISNUMBER(方案参数!M26),方案参数!M26,"") -> 9783412.3 | D27: =IF(AND(ISNUMBER(方案参数!M26),ISNUMBER(方案参数!M25),方案参数!M25>0),方案参数!M26/方案参数!M25-1,"") -> 0.10481755 | E27: =IF(AND(ISNUMBER(方案参数!M26),ISNUMBER(方案参数!M23),方案参数!M23>0),方案参数!M26/方案参数!M23-1,"") -> 0.11598556 | F27: =IF(ISNUMBER(方案参数!S26),方案参数!S26,"") -> 492226.36 | G27: =IF(ISNUMBER(方案参数!N26),方案参数!N26,"") -> 3604233.1 | H27: =IF(ISNUMBER(方案参数!O26),方案参数!O26,"") -> 6179179.2 | I27: =IF(ISNUMBER(C27),"固定次数的相对收益","待补参数；普通阶段可单独查看") -> 固定次数的相对收益
A28: J | B28: 4 | C28: =IF(ISNUMBER(方案参数!M27),方案参数!M27,"") -> 9971031.4 | D28: =IF(AND(ISNUMBER(方案参数!M27),ISNUMBER(方案参数!M26),方案参数!M26>0),方案参数!M27/方案参数!M26-1,"") -> 0.019177263 | E28: =IF(AND(ISNUMBER(方案参数!M27),ISNUMBER(方案参数!M23),方案参数!M23>0),方案参数!M27/方案参数!M23-1,"") -> 0.1373871 | F28: =IF(ISNUMBER(方案参数!S27),方案参数!S27,"") -> 679845.43 | G28: =IF(ISNUMBER(方案参数!N27),方案参数!N27,"") -> 3791852.2 | H28: =IF(ISNUMBER(方案参数!O27),方案参数!O27,"") -> 6179179.2 | I28: =IF(ISNUMBER(C28),"固定次数的相对收益","待补参数；普通阶段可单独查看") -> 固定次数的相对收益
A29: J | B29: 5 | C29: =IF(ISNUMBER(方案参数!M28),方案参数!M28,"") -> 10158553 | D29: =IF(AND(ISNUMBER(方案参数!M28),ISNUMBER(方案参数!M27),方案参数!M27>0),方案参数!M28/方案参数!M27-1,"") -> 0.018806674 | E29: =IF(AND(ISNUMBER(方案参数!M28),ISNUMBER(方案参数!M23),方案参数!M23>0),方案参数!M28/方案参数!M23-1,"") -> 0.15877757 | F29: =IF(ISNUMBER(方案参数!S28),方案参数!S28,"") -> 867367.37 | G29: =IF(ISNUMBER(方案参数!N28),方案参数!N28,"") -> 3979374.1 | H29: =IF(ISNUMBER(方案参数!O28),方案参数!O28,"") -> 6179179.2 | I29: =IF(ISNUMBER(C29),"固定次数的相对收益","待补参数；普通阶段可单独查看") -> 固定次数的相对收益
A30: 立于风暴脊 | B30: 1 | C30: =IF(ISNUMBER(方案参数!M29),方案参数!M29,"") -> 7967879 | D30: ="" | E30: =IF(AND(ISNUMBER(方案参数!M29),ISNUMBER(方案参数!M29),方案参数!M29>0),方案参数!M29/方案参数!M29-1,"") -> 0 | F30: =IF(ISNUMBER(方案参数!P29),方案参数!P29,"") -> 6564653 | G30: =IF(ISNUMBER(方案参数!N29),方案参数!N29,"") -> 3056550.7 | H30: =IF(ISNUMBER(方案参数!O29),方案参数!O29,"") -> 4911328.3 | I30: =IF(ISNUMBER(C30),"固定次数的相对收益","待补参数；普通阶段可单独查看") -> 固定次数的相对收益
A31: 立于风暴脊 | B31: 2 | C31: =IF(ISNUMBER(方案参数!M30),方案参数!M30,"") -> 8075580 | D31: =IF(AND(ISNUMBER(方案参数!M30),ISNUMBER(方案参数!M29),方案参数!M29>0),方案参数!M30/方案参数!M29-1,"") -> 0.013516897 | E31: =IF(AND(ISNUMBER(方案参数!M30),ISNUMBER(方案参数!M29),方案参数!M29>0),方案参数!M30/方案参数!M29-1,"") -> 0.013516897 | F31: =IF(ISNUMBER(方案参数!P30),方案参数!P30,"") -> 6672354 | G31: =IF(ISNUMBER(方案参数!N30),方案参数!N30,"") -> 3094900.7 | H31: =IF(ISNUMBER(方案参数!O30),方案参数!O30,"") -> 4980679.3 | I31: =IF(ISNUMBER(C31),"固定次数的相对收益","待补参数；普通阶段可单独查看") -> 固定次数的相对收益
A32: 立于风暴脊 | B32: 3 | C32: =IF(ISNUMBER(方案参数!M31),方案参数!M31,"") -> 8362785 | D32: =IF(AND(ISNUMBER(方案参数!M31),ISNUMBER(方案参数!M30),方案参数!M30>0),方案参数!M31/方案参数!M30-1,"") -> 0.035564628 | E32: =IF(AND(ISNUMBER(方案参数!M31),ISNUMBER(方案参数!M29),方案参数!M29>0),方案参数!M31/方案参数!M29-1,"") -> 0.049562249 | F32: =IF(ISNUMBER(方案参数!P31),方案参数!P31,"") -> 6959559 | G32: =IF(ISNUMBER(方案参数!N31),方案参数!N31,"") -> 3094900.7 | H32: =IF(ISNUMBER(方案参数!O31),方案参数!O31,"") -> 5267884.3 | I32: =IF(ISNUMBER(C32),"固定次数的相对收益","待补参数；普通阶段可单独查看") -> 固定次数的相对收益
A33: 立于风暴脊 | B33: 4 | C33: =IF(ISNUMBER(方案参数!M32),方案参数!M32,"") -> 8474949 | D33: =IF(AND(ISNUMBER(方案参数!M32),ISNUMBER(方案参数!M31),方案参数!M31>0),方案参数!M32/方案参数!M31-1,"") -> 0.013412278 | E33: =IF(AND(ISNUMBER(方案参数!M32),ISNUMBER(方案参数!M29),方案参数!M29>0),方案参数!M32/方案参数!M29-1,"") -> 0.06363927 | F33: =IF(ISNUMBER(方案参数!P32),方案参数!P32,"") -> 7071723 | G33: =IF(ISNUMBER(方案参数!N32),方案参数!N32,"") -> 3133250.7 | H33: =IF(ISNUMBER(方案参数!O32),方案参数!O32,"") -> 5341698.3 | I33: =IF(ISNUMBER(C33),"固定次数的相对收益","待补参数；普通阶段可单独查看") -> 固定次数的相对收益
A34: 立于风暴脊 | B34: 5 | C34: =IF(ISNUMBER(方案参数!M33),方案参数!M33,"") -> 8766612 | D34: =IF(AND(ISNUMBER(方案参数!M33),ISNUMBER(方案参数!M32),方案参数!M32>0),方案参数!M33/方案参数!M32-1,"") -> 0.03441472 | E34: =IF(AND(ISNUMBER(方案参数!M33),ISNUMBER(方案参数!M29),方案参数!M29>0),方案参数!M33/方案参数!M29-1,"") -> 0.10024412 | F34: =IF(ISNUMBER(方案参数!P33),方案参数!P33,"") -> 7363386 | G34: =IF(ISNUMBER(方案参数!N33),方案参数!N33,"") -> 3133250.7 | H34: =IF(ISNUMBER(方案参数!O33),方案参数!O33,"") -> 5633361.3 | I34: =IF(ISNUMBER(C34),"固定次数的相对收益","待补参数；普通阶段可单独查看") -> 固定次数的相对收益
A35: 灵知当齐一 | B35: 1 | C35: =IF(ISNUMBER(方案参数!M34),方案参数!M34,"") -> 8766612 | D35: ="" | E35: =IF(AND(ISNUMBER(方案参数!M34),ISNUMBER(方案参数!M34),方案参数!M34>0),方案参数!M34/方案参数!M34-1,"") -> 0 | F35: =IF(ISNUMBER(方案参数!Q34),方案参数!Q34,"") -> 642844.12 | G35: =IF(ISNUMBER(方案参数!N34),方案参数!N34,"") -> 3133250.7 | H35: =IF(ISNUMBER(方案参数!O34),方案参数!O34,"") -> 5633361.3 | I35: =IF(ISNUMBER(C35),"固定次数的相对收益","待补参数；普通阶段可单独查看") -> 固定次数的相对收益
A36: 灵知当齐一 | B36: 2 | C36: =IF(ISNUMBER(方案参数!M35),方案参数!M35,"") -> 8888625.2 | D36: =IF(AND(ISNUMBER(方案参数!M35),ISNUMBER(方案参数!M34),方案参数!M34>0),方案参数!M35/方案参数!M34-1,"") -> 0.013917947 | E36: =IF(AND(ISNUMBER(方案参数!M35),ISNUMBER(方案参数!M34),方案参数!M34>0),方案参数!M35/方案参数!M34-1,"") -> 0.013917947 | F36: =IF(ISNUMBER(方案参数!Q35),方案参数!Q35,"") -> 663562.36 | G36: =IF(ISNUMBER(方案参数!N35),方案参数!N35,"") -> 3134747.1 | H36: =IF(ISNUMBER(方案参数!O35),方案参数!O35,"") -> 5753878.1 | I36: =IF(ISNUMBER(C36),"固定次数的相对收益","待补参数；普通阶段可单独查看") -> 固定次数的相对收益
A37: 灵知当齐一 | B37: 3 | C37: =IF(ISNUMBER(方案参数!M36),方案参数!M36,"") -> 9010937.1 | D37: =IF(AND(ISNUMBER(方案参数!M36),ISNUMBER(方案参数!M35),方案参数!M35>0),方案参数!M36/方案参数!M35-1,"") -> 0.013760499 | E37: =IF(AND(ISNUMBER(方案参数!M36),ISNUMBER(方案参数!M34),方案参数!M34>0),方案参数!M36/方案参数!M34-1,"") -> 0.027869964 | F37: =IF(ISNUMBER(方案参数!Q36),方案参数!Q36,"") -> 684576.28 | G37: =IF(ISNUMBER(方案参数!N36),方案参数!N36,"") -> 3136245.9 | H37: =IF(ISNUMBER(方案参数!O36),方案参数!O36,"") -> 5874691.3 | I37: =IF(ISNUMBER(C37),"固定次数的相对收益","待补参数；普通阶段可单独查看") -> 固定次数的相对收益
A38: 灵知当齐一 | B38: 4 | C38: =IF(ISNUMBER(方案参数!M37),方案参数!M37,"") -> 9133551.1 | D38: =IF(AND(ISNUMBER(方案参数!M37),ISNUMBER(方案参数!M36),方案参数!M36>0),方案参数!M37/方案参数!M36-1,"") -> 0.013607233 | E38: =IF(AND(ISNUMBER(方案参数!M37),ISNUMBER(方案参数!M34),方案参数!M34>0),方案参数!M37/方案参数!M34-1,"") -> 0.04185643 | F38: =IF(ISNUMBER(方案参数!Q37),方案参数!Q37,"") -> 705893.2 | G38: =IF(ISNUMBER(方案参数!N37),方案参数!N37,"") -> 3137743.8 | H38: =IF(ISNUMBER(方案参数!O37),方案参数!O37,"") -> 5995807.2 | I38: =IF(ISNUMBER(C38),"固定次数的相对收益","待补参数；普通阶段可单独查看") -> 固定次数的相对收益
A39: 灵知当齐一 | B39: 5 | C39: =IF(ISNUMBER(方案参数!M38),方案参数!M38,"") -> 9256463.1 | D39: =IF(AND(ISNUMBER(方案参数!M38),ISNUMBER(方案参数!M37),方案参数!M37>0),方案参数!M38/方案参数!M37-1,"") -> 0.013457197 | E39: =IF(AND(ISNUMBER(方案参数!M38),ISNUMBER(方案参数!M34),方案参数!M34>0),方案参数!M38/方案参数!M34-1,"") -> 0.055876898 | F39: =IF(ISNUMBER(方案参数!Q38),方案参数!Q38,"") -> 727506.2 | G39: =IF(ISNUMBER(方案参数!N38),方案参数!N38,"") -> 3139241.8 | H39: =IF(ISNUMBER(方案参数!O38),方案参数!O38,"") -> 6117221.3 | I39: =IF(ISNUMBER(C39),"固定次数的相对收益","待补参数；普通阶段可单独查看") -> 固定次数的相对收益
A40: 昨日雨声轻 | B40: 1 | C40: =IF(ISNUMBER(方案参数!M39),方案参数!M39,"") -> 8291958.4 | D40: ="" | E40: =IF(AND(ISNUMBER(方案参数!M39),ISNUMBER(方案参数!M39),方案参数!M39>0),方案参数!M39/方案参数!M39-1,"") -> 0 | F40: =IF(ISNUMBER(方案参数!R39),方案参数!R39,"") -> 435716.05 | G40: =IF(ISNUMBER(方案参数!N39),方案参数!N39,"") -> 2930760.4 | H40: =IF(ISNUMBER(方案参数!O39),方案参数!O39,"") -> 5361198 | I40: =IF(ISNUMBER(C40),"固定次数的相对收益","待补参数；普通阶段可单独查看") -> 固定次数的相对收益
A41: 昨日雨声轻 | B41: 2 | C41: =IF(ISNUMBER(方案参数!M40),方案参数!M40,"") -> 8402306.9 | D41: =IF(AND(ISNUMBER(方案参数!M40),ISNUMBER(方案参数!M39),方案参数!M39>0),方案参数!M40/方案参数!M39-1,"") -> 0.013307895 | E41: =IF(AND(ISNUMBER(方案参数!M40),ISNUMBER(方案参数!M39),方案参数!M39>0),方案参数!M40/方案参数!M39-1,"") -> 0.013307895 | F41: =IF(ISNUMBER(方案参数!R40),方案参数!R40,"") -> 446538.38 | G41: =IF(ISNUMBER(方案参数!N40),方案参数!N40,"") -> 2976743.5 | H41: =IF(ISNUMBER(方案参数!O40),方案参数!O40,"") -> 5425563.4 | I41: =IF(ISNUMBER(C41),"固定次数的相对收益","待补参数；普通阶段可单独查看") -> 固定次数的相对收益
A42: 昨日雨声轻 | B42: 3 | C42: =IF(ISNUMBER(方案参数!M41),方案参数!M41,"") -> 8513503.4 | D42: =IF(AND(ISNUMBER(方案参数!M41),ISNUMBER(方案参数!M40),方案参数!M40>0),方案参数!M41/方案参数!M40-1,"") -> 0.013234038 | E42: =IF(AND(ISNUMBER(方案参数!M41),ISNUMBER(方案参数!M39),方案参数!M39>0),方案参数!M41/方案参数!M39-1,"") -> 0.026718051 | F42: =IF(ISNUMBER(方案参数!R41),方案参数!R41,"") -> 457532.8 | G42: =IF(ISNUMBER(方案参数!N41),方案参数!N41,"") -> 3023154.5 | H42: =IF(ISNUMBER(方案参数!O41),方案参数!O41,"") -> 5490348.9 | I42: =IF(ISNUMBER(C42),"固定次数的相对收益","待补参数；普通阶段可单独查看") -> 固定次数的相对收益
...

Sheet 效果参数
A1: 塑造及心相效果参数
A2: 塑造效果逐档累计，37/J均为狂想IV后的有效数值。黄色可按游戏改版修正。倍数100%=1；百分点使用百分比。空白不是0。来源及未验证推算写在右侧。
A5: 角色 | B5: 参数 | C5: 0塑 | D5: 1塑 | E5: 2塑 | F5: 3塑 | G5: 4塑 | H5: 5塑 | I5: 单位 | J5: 来源 | K5: 说明
A6: 红弩箭 | B6: 俯冲基础 | C6: 2 | D6: 2 | E6: 3 | F6: 3 | G6: 3 | H6: 3 | I6: 倍率 | J6: 用户提供塑造/狂想文本；0塑沿用实测验证表
A7: 红弩箭 | B7: 俯冲雷鸣追加 | C7: 4 | D7: 4 | E7: 6 | F7: 6 | G7: 6 | H7: 6 | I7: 倍率 | J7: 用户提供塑造/狂想文本；0塑沿用实测验证表
A8: 红弩箭 | B8: 俯冲极限追加 | C8: 8 | D8: 8 | E8: 12 | F8: 12 | G8: 12 | H8: 12 | I8: 倍率 | J8: 用户提供塑造/狂想文本；0塑沿用实测验证表
A9: 红弩箭 | B9: 雷鸣俯冲伤加Ⅰ | C9: 0.1 | D9: 0.1 | E9: 0.3 | F9: 0.3 | G9: 0.3 | H9: 0.3 | I9: 百分点 | J9: 用户提供塑造/狂想文本；0塑沿用实测验证表 | K9: Ⅱ/Ⅲ阶额外+10/+20个百分点
A10: 红弩箭 | B10: 极限俯冲伤加Ⅰ | C10: 0.2 | D10: 0.2 | E10: 0.6 | F10: 0.6 | G10: 0.6 | H10: 0.6 | I10: 百分点 | J10: 用户提供塑造/狂想文本；0塑沿用实测验证表 | K10: Ⅱ/Ⅲ阶额外+20/+40个百分点
A11: 红弩箭 | B11: 雷鸣术法 | C11: 0.6 | D11: 0.6 | E11: 0.6 | F11: 0.6 | G11: 1 | H11: 1 | I11: 倍率 | J11: 用户提供塑造/狂想文本；0塑沿用实测验证表
A12: 红弩箭 | B12: 极限术法 | C12: 1.2 | D12: 1.2 | E12: 1.2 | F12: 1.2 | G12: 2 | H12: 2 | I12: 倍率 | J12: 用户提供塑造/狂想文本；0塑沿用实测验证表
A13: 红弩箭 | B13: 每增压术法 | C13: 0.06 | D13: 0.06 | E13: 0.06 | F13: 0.06 | G13: 0.1 | H13: 0.1 | I13: 倍率 | J13: 用户提供塑造/狂想文本；0塑沿用实测验证表
A14: 红弩箭 | B14: 首次眼镜蛇增压 | C14: 3 | D14: 3 | E14: 5 | F14: 5 | G14: 5 | H14: 5 | I14: 层/点 | J14: 用户提供塑造/狂想文本；0塑沿用实测验证表
A15: 红弩箭 | B15: 首次俯冲增压 | C15: 1 | D15: 1 | E15: 2 | F15: 2 | G15: 2 | H15: 2 | I15: 层/点 | J15: 用户提供塑造/狂想文本；0塑沿用实测验证表
A16: 红弩箭 | B16: 每弹药仪式 | C16: 0.025 | D16: 0.025 | E16: 0.025 | F16: 0.025 | G16: 0.05 | H16: 0.05 | I16: 倍率 | J16: 用户提供塑造/狂想文本；0塑沿用实测验证表
A17: 红弩箭 | B17: 仪式主目标基础 | C17: 18 | D17: 18 | E17: 18 | F17: 36 | G17: 36 | H17: 36 | I17: 倍率 | J17: 用户提供塑造/狂想文本；0塑沿用实测验证表 | K17: 基础＋主目标追加合并；高塑1800%＋1800%
A18: 红弩箭 | B18: 消耗弹药追加 | C18: 18 | D18: 18 | E18: 18 | F18: 36 | G18: 36 | H18: 36 | I18: 倍率 | J18: 用户提供塑造/狂想文本；0塑沿用实测验证表
A19: 红弩箭 | B19: 消耗弹药仪式 | C19: 1 | D19: 1 | E19: 1 | F19: 1.8 | G19: 1.8 | H19: 1.8 | I19: 倍率 | J19: 用户提供塑造/狂想文本；0塑沿用实测验证表
A20: 红弩箭 | B20: 消耗弹药暴创 | C20: 1 | D20: 1 | E20: 1 | F20: 1.8 | G20: 1.8 | H20: 1.8 | I20: 倍率 | J20: 用户提供塑造/狂想文本；0塑沿用实测验证表
A21: 红弩箭 | B21: 消耗弹药穿透 | C21: 0.2 | D21: 0.2 | E21: 0.2 | F21: 0.5 | G21: 0.5 | H21: 0.5 | I21: 倍率 | J21: 用户提供塑造/狂想文本；0塑沿用实测验证表
A22: 红弩箭 | B22: 洞知普通 | C22: 9 | D22: 15 | E22: 15 | F22: 15 | G22: 15 | H22: 22 | I22: 倍率 | J22: 用户提供塑造/狂想文本；0塑沿用实测验证表 | K22: 0塑900%，用户最新完整文本确认
A23: 红弩箭 | B23: 洞知第三击 | C23: 20 | D23: 32 | E23: 32 | F23: 32 | G23: 32 | H23: 48 | I23: 倍率 | J23: 用户提供塑造/狂想文本；0塑沿用实测验证表
A24: 红弩箭 | B24: 洞知终结 | C24: 30 | D24: 50 | E24: 50 | F24: 50 | G24: 50 | H24: 70 | I24: 倍率 | J24: 用户提供塑造/狂想文本；0塑沿用实测验证表
A25: 红弩箭 | B25: 终结每行动追加 | C25: 1.5 | D25: 2.5 | E25: 2.5 | F25: 2.5 | G25: 2.5 | H25: 3.5 | I25: 倍率 | J25: 用户提供塑造/狂想文本；0塑沿用实测验证表
A26: 红弩箭 | B26: 洞知普通暴创 | C26: 0.6 | D26: 0.6 | E26: 0.6 | F26: 0.6 | G26: 0.6 | H26: 0.8 | I26: 倍率 | J26: 用户提供塑造/狂想文本；0塑沿用实测验证表
A27: 红弩箭 | B27: 洞知第三暴创 | C27: 0.8 | D27: 0.8 | E27: 0.8 | F27: 0.8 | G27: 0.8 | H27: 1 | I27: 倍率 | J27: 用户提供塑造/狂想文本；0塑沿用实测验证表
A28: 红弩箭 | B28: 洞知终结暴创 | C28: 1 | D28: 1 | E28: 1 | F28: 1 | G28: 1 | H28: 1.25 | I28: 倍率 | J28: 用户提供塑造/狂想文本；0塑沿用实测验证表
A29: 红弩箭 | B29: 洞知倍率已确认 | C29: 1 | D29: 1 | E29: 1 | F29: 1 | G29: 1 | H29: 1 | I29: 开关 | J29: 用户提供塑造/狂想文本；0塑沿用实测验证表 | K29: 0～5塑基础倍率已由用户完整文字补齐
A30: 37 | B30: 入战全队暴击 | C30: 0.3 | D30: 0.6 | E30: 0.6 | F30: 0.6 | G30: 0.6 | H30: 0.6 | I30: 百分点 | J30: 用户提供塑造/狂想文本；0塑沿用实测验证表 | K30: 用户提供当前有效全队提升60%；不再乘狂想50%
A31: 37 | B31: 数维攻击比例 | C31: 0.2 | D31: 0.2 | E31: 0.2 | F31: 0.24 | G31: 0.24 | H31: 0.24 | I31: 倍率 | J31: 用户提供塑造/狂想文本；0塑沿用实测验证表
A32: 37 | B32: 数维攻击上限 | C32: 500 | D32: 500 | E32: 500 | F32: 600 | G32: 600 | H32: 600 | I32: 攻击值 | J32: 用户提供塑造/狂想文本；0塑沿用实测验证表
A33: 37 | B33: 洞穿减免降低 | C33: 0.4 | D33: 0.4 | E33: 0.7 | F33: 0.7 | G33: 0.7 | H33: 1 | I33: 倍率 | J33: 用户提供塑造/狂想文本；0塑沿用实测验证表
A34: 37 | B34: 两分悖论比例 | C34: 0.4 | D34: 0.4 | E34: 0.6 | F34: 0.6 | G34: 0.6 | H34: 0.8 | I34: 倍率 | J34: 用户提供塑造/狂想文本；0塑沿用实测验证表
A35: 37 | B35: 三角正论基础 | C35: 2.8 | D35: 2.8 | E35: 2.8 | F35: 3 | G35: 3 | H35: 3 | I35: 倍率 | J35: 用户提供塑造/狂想文本；0塑沿用实测验证表 | K35: Ⅱ阶×1.5，Ⅲ阶×2.5
A36: 37 | B36: 曲线映射基础 | C36: 1.4 | D36: 1.4 | E36: 1.4 | F36: 1.6 | G36: 1.6 | H36: 1.6 | I36: 倍率 | J36: 用户提供塑造/狂想文本；0塑沿用实测验证表
A37: 37 | B37: 普通咒语本源 | C37: 0.8 | D37: 0.8 | E37: 0.8 | F37: 1 | G37: 1 | H37: 1 | I37: 倍率 | J37: 用户提供塑造/狂想文本；0塑沿用实测验证表
A38: 37 | B38: 补充算式精神 | C38: 3 | D38: 3 | E38: 4.5 | F38: 4.5 | G38: 6 | H38: 6 | I38: 倍率 | J38: 用户提供塑造/狂想文本；0塑沿用实测验证表
A39: 37 | B39: 补充算式本源 | C39: 1 | D39: 1 | E39: 1.5 | F39: 1.5 | G39: 2 | H39: 2 | I39: 倍率 | J39: 用户提供塑造/狂想文本；0塑沿用实测验证表
A40: 37 | B40: 仪式启迪层数 | C40: 2 | D40: 2 | E40: 2 | F40: 3 | G40: 3 | H40: 3 | I40: 层/点 | J40: 用户提供塑造/狂想文本；0塑沿用实测验证表
A41: 37 | B41: 启迪本源增加 | C41: 1 | D41: 1 | E41: 1 | F41: 1 | G41: 2 | H41: 2 | I41: 倍率 | J41: 用户提供塑造/狂想文本；0塑沿用实测验证表
A42: 37 | B42: 洞知精神 | C42: 8 | D42: 8 | E42: 9 | F42: 9 | G42: 9 | H42: 10 | I42: 倍率 | J42: 用户提供塑造/狂想文本；0塑沿用实测验证表
...

Sheet 固定流程
A1: 固定计算流程
A2: 各方案固定同一36次玩家行动，不模拟发牌、激情合法性、灵光生成或洞知点。普通阶段4次补充算式、2次黑莓固定，不随塑造改变数量。无Boss行动及高温回火。
A5: 序号 | B5: 阶段 | C5: 普通回合 | D5: 角色 | E5: 技能 | F5: 阶次 | G5: 角色编号 | H5: 动作代码 | I5: 说明
A6: 1 | B6: 普通 | C6: 1 | D6: 小瑞安侬 | E6: 唱予无忧之诗 | F6: 1 | G6: 3 | H6: RHI_ULT | I6: 固定主动技能，小瑞普通咒语假定处于加护
A7: 2 | B7: 普通 | C7: 1 | D7: 小瑞安侬 | E7: 悄冥冥术阵·加护 | F7: 1 | G7: 3 | H7: RHI_BUFF | I7: 固定主动技能，小瑞普通咒语假定处于加护
A8: 3 | B8: 普通 | C8: 1 | D8: 红弩箭 | E8: 眼镜蛇机动Ⅰ | F8: 1 | G8: 1 | H8: LILYA_COBRA | I8: 固定主动技能，小瑞普通咒语假定处于加护
A9: 4 | B9: 普通 | C9: 1 | D9: 红弩箭 | E9: 极限俯冲 | F9: 1 | G9: 1 | H9: LILYA_DIVE | I9: 固定主动技能，小瑞普通咒语假定处于加护
A10: 5 | B10: 普通 | C10: 1 | D10: 37 | E10: 三角正论 | F10: 1 | G10: 2 | H10: 37_TRIANGLE | I10: 固定主动技能，小瑞普通咒语假定处于加护
A11: 6 | B11: 普通 | C11: 1 | D11: 37 | E11: 补充算式 | F11: 1 | G11: 2 | H11: 37_FOLLOW | I11: 固定额外行动；计入心相灵知叠层
A12: 7 | B12: 普通 | C12: 1 | D12: J | E12: 硬度测试 | F12: 1 | G12: 4 | H12: J_HARD | I12: 主动出牌同时视为反击，触发家庭指导员
A13: 8 | B13: 普通 | C13: 2 | D13: 小瑞安侬 | E13: 囫囵囵咒·加护 | F13: 1 | G13: 3 | H13: RHI_ATTACK | I13: 固定主动技能，小瑞普通咒语假定处于加护
A14: 9 | B14: 普通 | C14: 2 | D14: 红弩箭 | E14: 极限俯冲 | F14: 3 | G14: 1 | H14: LILYA_DIVE | I14: 固定主动技能，小瑞普通咒语假定处于加护
A15: 10 | B15: 普通 | C15: 2 | D15: J | E15: 硬度测试 | F15: 1 | G15: 4 | H15: J_HARD | I15: 主动出牌同时视为反击，触发家庭指导员
A16: 11 | B16: 普通 | C16: 2 | D16: 37 | E16: 曲线映射 | F16: 1 | G16: 2 | H16: 37_CURVE | I16: 固定主动技能，小瑞普通咒语假定处于加护
A17: 12 | B17: 普通 | C17: 2 | D17: 37 | E17: 补充算式 | F17: 1 | G17: 2 | H17: 37_FOLLOW | I17: 固定额外行动；计入心相灵知叠层
... A41: 36 | B41: 洞穿 | C41: 3 | D41: 红弩箭 | E41: 洞知终结 | F41: 1 | G41: 1 | H41: LILYA_FINISH | I41: 固定洞穿顺序，不核算洞知点消耗

Sheet 方案参数
A2: 方案号 | B2: 方案 | C2: 红塑造 | D2: 37塑造 | E2: 瑞塑造 | F2: J塑造 | G2: 红增幅 | H2: 37增幅 | I2: 瑞增幅 | J2: J增幅 | K2: 普通参数完整 | L2: 洞穿参数完整 | M2: 全队合计 | N2: 普通合计 | O2: 洞穿合计 | P2: 红弩箭总伤 | Q2: 37总伤 | R2: 小瑞安侬总伤 | S2: J总伤 | T2: 相对基准 | U2: 灵知每额外行动 | V2: 风暴洞知每行动 | W2: 雨声每主动伤害 | X2: 雨声仪式暴创 | Y2: 雨声入战攻击 | Z2: 家庭反击仪式 | AA2: 家庭每激情暴创 | AB2: 入战全队暴击 | AC2: 数维攻击比例 | AD2: 数维攻击上限 | AE2: 洞穿减免降低 | AF2: 两分悖论比例 | AG2: 群鸟威力 | AH2: 每灵犀克制 | AI2: 灵犀上限 | AJ2: 回合开始灵犀 | AK2: 消费默契灵犀 | AL2: 尘酿鹰攻击比例 | AM2: 尘酿鹰攻击上限 | AN2: 升华群体伤加 | AO2: 升华伤加额外上限 | AP2: 升华降低暴防 | AQ2: 升华暴防额外上限 | AR2: 自身燃烧上限 | AS2: 燃烧攻击比例 | AT2: 仪式基础 | AU2: 仪式文本溢出 | AV2: 俯冲基础 | AW2: 俯冲雷鸣追加 | AX2: 俯冲极限追加 | AY2: 雷鸣俯冲伤加Ⅰ | AZ2: 极限俯冲伤加Ⅰ | BA2: 雷鸣术法 | BB2: 极限术法 | BC2: 每增压术法 | BD2: 首次眼镜蛇增压 | BE2: 首次俯冲增压 | BF2: 每弹药仪式 | BG2: 仪式主目标基础 | BH2: 消耗弹药追加 | BI2: 消耗弹药仪式 | BJ2: 消耗弹药暴创 | BK2: 消耗弹药穿透 | BL2: 洞知普通 | BM2: 洞知第三击 | BN2: 洞知终结 | BO2: 终结每行动追加 | BP2: 洞知普通暴创 | BQ2: 洞知第三暴创 | BR2: 洞知终结暴创 | BS2: 三角正论基础 | BT2: 曲线映射基础 | BU2: 普通咒语本源 | BV2: 补充算式精神 | BW2: 补充算式本源 | BX2: 仪式启迪层数 | BY2: 启迪本源增加 | BZ2: J燃烧 | CA2: 小瑞入战攻击 | CB2: 数维快照攻击 | CC2: 尘酿鹰快照攻击 | CD2: 风暴入战伤害 | CE2: 洞知精神 | CF2: 黑莓基础 | CG2: 黑莓每灵犀 | CH2: 灵知入战暴创
A3: =0 -> 0 | B3: ="基准配置" -> 基准配置 | C3: =配置与结果!B6 -> 0 | D3: =配置与结果!B7 -> 0 | E3: =配置与结果!B8 -> 0 | F3: =配置与结果!B9 -> 0 | G3: =配置与结果!D6 -> 5 | H3: =配置与结果!D7 -> 1 | I3: =配置与结果!D8 -> 5 | J3: =配置与结果!D9 -> 1 | K3: =INDEX(效果参数!$C$105:$G$105,1,J3) -> 1 | L3: =AND(K3=1,INDEX(效果参数!$C$99:$G$99,1,H3)=1,INDEX(效果参数!$C$29:$H$29,1,C3+1)=1) -> TRUE | M3: =IF(AND(K3=1,L3),SUM(行动计算!AU6:AU41),"") -> 8766612 | N3: =IF(K3=1,SUMIFS(行动计算!AU6:AU41,行动计算!D6:D41,1),"") -> 3133250.7 | O3: =IF(L3,SUMIFS(行动计算!AU6:AU41,行动计算!D6:D41,2),"") -> 5633361.3 | P3: =IF(AND(K3=1,L3),SUMIFS(行动计算!AU6:AU41,行动计算!F6:F41,1),"") -> 7363386 | Q3: =IF(AND(K3=1,L3),SUMIFS(行动计算!AU6:AU41,行动计算!F6:F41,2),"") -> 642844.12 | R3: =IF(AND(K3=1,L3),SUMIFS(行动计算!AU6:AU41,行动计算!F6:F41,3),"") -> 489818.29 | S3: =IF(AND(K3=1,L3),SUMIFS(行动计算!AU6:AU41,行动计算!F6:F41,4),"") -> 270563.56 | T3: =IF(AND(ISNUMBER(M3),ISNUMBER($M$3),$M$3>0),M3/$M$3-1,"") -> 0 | U3: =INDEX(效果参数!$C$98:$G$98,1,H3) -> 0.04 | V3: =INDEX(效果参数!$C$97:$G$97,1,G3) -> 0.06 | W3: =INDEX(效果参数!$C$101:$G$101,1,I3) -> 0.02 | X3: =INDEX(效果参数!$C$102:$G$102,1,I3) -> 0.16 | Y3: =INDEX(效果参数!$C$100:$G$100,1,I3) -> 0.1 | Z3: =INDEX(效果参数!$C$103:$G$103,1,J3) -> 0.04 | AA3: =INDEX(效果参数!$C$104:$G$104,1,J3) -> 0.004 | AB3: =INDEX(效果参数!$C$30:$H$30,1,D3+1) -> 0.3 | AC3: =INDEX(效果参数!$C$31:$H$31,1,D3+1) -> 0.2 | AD3: =INDEX(效果参数!$C$32:$H$32,1,D3+1) -> 500 | AE3: =INDEX(效果参数!$C$33:$H$33,1,D3+1) -> 0.4 | AF3: =INDEX(效果参数!$C$34:$H$34,1,D3+1) -> 0.4 | AG3: =INDEX(效果参数!$C$43:$H$43,1,E3+1) -> 0.3 | AH3: =INDEX(效果参数!$C$44:$H$44,1,E3+1) -> 0.04 | AI3: =INDEX(效果参数!$C$45:$H$45,1,E3+1) -> 5 | AJ3: =INDEX(效果参数!$C$46:$H$46,1,E3+1) -> 1 | AK3: =INDEX(效果参数!$C$47:$H$47,1,E3+1) -> 2 | AL3: =INDEX(效果参数!$C$48:$H$48,1,E3+1) -> 0.08 | AM3: =INDEX(效果参数!$C$49:$H$49,1,E3+1) -> 250 | AN3: =INDEX(效果参数!$C$50:$H$50,1,E3+1) -> 0.15 | AO3: =INDEX(效果参数!$C$51:$H$51,1,E3+1) -> 0.15 | AP3: =INDEX(效果参数!$C$52:$H$52,1,E3+1) -> 0.15 | AQ3: =INDEX(效果参数!$C$53:$H$53,1,E3+1) -> 0.15 | AR3: =INDEX(效果参数!$C$56:$H$56,1,F3+1) -> 35 | AS3: =INDEX(效果参数!$C$57:$H$57,1,F3+1) -> 0.01 | AT3: =INDEX(效果参数!$C$58:$H$58,1,F3+1) -> 7 | AU3: =INDEX(效果参数!$C$59:$H$59,1,F3+1) -> 0.5 | AV3: =INDEX(效果参数!$C$6:$H$6,1,C3+1) -> 2 | AW3: =INDEX(效果参数!$C$7:$H$7,1,C3+1) -> 4 | AX3: =INDEX(效果参数!$C$8:$H$8,1,C3+1) -> 8 | AY3: =INDEX(效果参数!$C$9:$H$9,1,C3+1) -> 0.1 | AZ3: =INDEX(效果参数!$C$10:$H$10,1,C3+1) -> 0.2 | BA3: =INDEX(效果参数!$C$11:$H$11,1,C3+1) -> 0.6 | BB3: =INDEX(效果参数!$C$12:$H$12,1,C3+1) -> 1.2 | BC3: =INDEX(效果参数!$C$13:$H$13,1,C3+1) -> 0.06 | BD3: =INDEX(效果参数!$C$14:$H$14,1,C3+1) -> 3 | BE3: =INDEX(效果参数!$C$15:$H$15,1,C3+1) -> 1 | BF3: =INDEX(效果参数!$C$16:$H$16,1,C3+1) -> 0.025 | BG3: =INDEX(效果参数!$C$17:$H$17,1,C3+1) -> 18 | BH3: =INDEX(效果参数!$C$18:$H$18,1,C3+1) -> 18 | BI3: =INDEX(效果参数!$C$19:$H$19,1,C3+1) -> 1 | BJ3: =INDEX(效果参数!$C$20:$H$20,1,C3+1) -> 1 | BK3: =INDEX(效果参数!$C$21:$H$21,1,C3+1) -> 0.2 | BL3: =INDEX(效果参数!$C$22:$H$22,1,C3+1) -> 9 | BM3: =INDEX(效果参数!$C$23:$H$23,1,C3+1) -> 20 | BN3: =INDEX(效果参数!$C$24:$H$24,1,C3+1) -> 30 | BO3: =INDEX(效果参数!$C$25:$H$25,1,C3+1) -> 1.5 | BP3: =INDEX(效果参数!$C$26:$H$26,1,C3+1) -> 0.6 | BQ3: =INDEX(效果参数!$C$27:$H$27,1,C3+1) -> 0.8 | BR3: =INDEX(效果参数!$C$28:$H$28,1,C3+1) -> 1 | BS3: =INDEX(效果参数!$C$35:$H$35,1,D3+1) -> 2.8 | BT3: =INDEX(效果参数!$C$36:$H$36,1,D3+1) -> 1.4 | BU3: =INDEX(效果参数!$C$37:$H$37,1,D3+1) -> 0.8 | BV3: =INDEX(效果参数!$C$38:$H$38,1,D3+1) -> 3 | BW3: =INDEX(效果参数!$C$39:$H$39,1,D3+1) -> 1 | BX3: =INDEX(效果参数!$C$40:$H$40,1,D3+1) -> 2 | BY3: =INDEX(效果参数!$C$41:$H$41,1,D3+1) -> 1 | BZ3: =IF(配置与结果!$H$24=1,AR3,MIN(AR3,MAX(0,配置与结果!$H$25))) -> 35 | CA3: =ROUNDDOWN(配置与结果!$B$17*(1+0.05+Y3),0) -> 2986 | CB3: =MIN(AD3,ROUNDDOWN((配置与结果!$B$16+CC3)*AC3,0)) -> 500 | CC3: =MIN(AM3,ROUNDDOWN(CA3*AL3,0)) -> 238 | CD3: =INDEX(效果参数!$C$96:$G$96,1,G3) -> 0.16 | CE3: =INDEX(效果参数!$C$42:$H$42,1,D3+1) -> 8 | CF3: =INDEX(效果参数!$C$54:$H$54,1,E3+1) -> 15 | CG3: =INDEX(效果参数!$C$55:$H$55,1,E3+1) -> 1.5 | CH3: =INDEX(效果参数!$C$106:$G$106,1,H3) -> 0.12
A4: =1 -> 1 | B4: ="对比配置" -> 对比配置 | C4: =配置与结果!C6 -> 2 | D4: =配置与结果!C7 -> 0 | E4: =配置与结果!C8 -> 0 | F4: =配置与结果!C9 -> 0 | G4: =配置与结果!E6 -> 5 | H4: =配置与结果!E7 -> 1 | I4: =配置与结果!E8 -> 5 | J4: =配置与结果!E9 -> 1 | K4: =INDEX(效果参数!$C$105:$G$105,1,J4) -> 1 | L4: =AND(K4=1,INDEX(效果参数!$C$99:$G$99,1,H4)=1,INDEX(效果参数!$C$29:$H$29,1,C4+1)=1) -> TRUE | M4: =IF(AND(K4=1,L4),SUM(行动计算!AU42:AU77),"") -> 13566810 | N4: =IF(K4=1,SUMIFS(行动计算!AU42:AU77,行动计算!D42:D77,1),"") -> 4620699.7 | O4: =IF(L4,SUMIFS(行动计算!AU42:AU77,行动计算!D42:D77,2),"") -> 8946110.3 | P4: =IF(AND(K4=1,L4),SUMIFS(行动计算!AU42:AU77,行动计算!F42:F77,1),"") -> 12163584 | Q4: =IF(AND(K4=1,L4),SUMIFS(行动计算!AU42:AU77,行动计算!F42:F77,2),"") -> 642844.12 | R4: =IF(AND(K4=1,L4),SUMIFS(行动计算!AU42:AU77,行动计算!F42:F77,3),"") -> 489818.29 | S4: =IF(AND(K4=1,L4),SUMIFS(行动计算!AU42:AU77,行动计算!F42:F77,4),"") -> 270563.56 | T4: =IF(AND(ISNUMBER(M4),ISNUMBER($M$3),$M$3>0),M4/$M$3-1,"") -> 0.54755452 | U4: =INDEX(效果参数!$C$98:$G$98,1,H4) -> 0.04 | V4: =INDEX(效果参数!$C$97:$G$97,1,G4) -> 0.06 | W4: =INDEX(效果参数!$C$101:$G$101,1,I4) -> 0.02 | X4: =INDEX(效果参数!$C$102:$G$102,1,I4) -> 0.16 | Y4: =INDEX(效果参数!$C$100:$G$100,1,I4) -> 0.1 | Z4: =INDEX(效果参数!$C$103:$G$103,1,J4) -> 0.04 | AA4: =INDEX(效果参数!$C$104:$G$104,1,J4) -> 0.004 | AB4: =INDEX(效果参数!$C$30:$H$30,1,D4+1) -> 0.3 | AC4: =INDEX(效果参数!$C$31:$H$31,1,D4+1) -> 0.2 | AD4: =INDEX(效果参数!$C$32:$H$32,1,D4+1) -> 500 | AE4: =INDEX(效果参数!$C$33:$H$33,1,D4+1) -> 0.4 | AF4: =INDEX(效果参数!$C$34:$H$34,1,D4+1) -> 0.4 | AG4: =INDEX(效果参数!$C$43:$H$43,1,E4+1) -> 0.3 | AH4: =INDEX(效果参数!$C$44:$H$44,1,E4+1) -> 0.04 | AI4: =INDEX(效果参数!$C$45:$H$45,1,E4+1) -> 5 | AJ4: =INDEX(效果参数!$C$46:$H$46,1,E4+1) -> 1 | AK4: =INDEX(效果参数!$C$47:$H$47,1,E4+1) -> 2 | AL4: =INDEX(效果参数!$C$48:$H$48,1,E4+1) -> 0.08 | AM4: =INDEX(效果参数!$C$49:$H$49,1,E4+1) -> 250 | AN4: =INDEX(效果参数!$C$50:$H$50,1,E4+1) -> 0.15 | AO4: =INDEX(效果参数!$C$51:$H$51,1,E4+1) -> 0.15 | AP4: =INDEX(效果参数!$C$52:$H$52,1,E4+1) -> 0.15 | AQ4: =INDEX(效果参数!$C$53:$H$53,1,E4+1) -> 0.15 | AR4: =INDEX(效果参数!$C$56:$H$56,1,F4+1) -> 35 | AS4: =INDEX(效果参数!$C$57:$H$57,1,F4+1) -> 0.01 | AT4: =INDEX(效果参数!$C$58:$H$58,1,F4+1) -> 7 | AU4: =INDEX(效果参数!$C$59:$H$59,1,F4+1) -> 0.5 | AV4: =INDEX(效果参数!$C$6:$H$6,1,C4+1) -> 3 | AW4: =INDEX(效果参数!$C$7:$H$7,1,C4+1) -> 6 | AX4: =INDEX(效果参数!$C$8:$H$8,1,C4+1) -> 12 | AY4: =INDEX(效果参数!$C$9:$H$9,1,C4+1) -> 0.3 | AZ4: =INDEX(效果参数!$C$10:$H$10,1,C4+1) -> 0.6 | BA4: =INDEX(效果参数!$C$11:$H$11,1,C4+1) -> 0.6 | BB4: =INDEX(效果参数!$C$12:$H$12,1,C4+1) -> 1.2 | BC4: =INDEX(效果参数!$C$13:$H$13,1,C4+1) -> 0.06 | BD4: =INDEX(效果参数!$C$14:$H$14,1,C4+1) -> 5 | BE4: =INDEX(效果参数!$C$15:$H$15,1,C4+1) -> 2 | BF4: =INDEX(效果参数!$C$16:$H$16,1,C4+1) -> 0.025 | BG4: =INDEX(效果参数!$C$17:$H$17,1,C4+1) -> 18 | BH4: =INDEX(效果参数!$C$18:$H$18,1,C4+1) -> 18 | BI4: =INDEX(效果参数!$C$19:$H$19,1,C4+1) -> 1 | BJ4: =INDEX(效果参数!$C$20:$H$20,1,C4+1) -> 1 | BK4: =INDEX(效果参数!$C$21:$H$21,1,C4+1) -> 0.2 | BL4: =INDEX(效果参数!$C$22:$H$22,1,C4+1) -> 15 | BM4: =INDEX(效果参数!$C$23:$H$23,1,C4+1) -> 32 | BN4: =INDEX(效果参数!$C$24:$H$24,1,C4+1) -> 50 | BO4: =INDEX(效果参数!$C$25:$H$25,1,C4+1) -> 2.5 | BP4: =INDEX(效果参数!$C$26:$H$26,1,C4+1) -> 0.6 | BQ4: =INDEX(效果参数!$C$27:$H$27,1,C4+1) -> 0.8 | BR4: =INDEX(效果参数!$C$28:$H$28,1,C4+1) -> 1 | BS4: =INDEX(效果参数!$C$35:$H$35,1,D4+1) -> 2.8 | BT4: =INDEX(效果参数!$C$36:$H$36,1,D4+1) -> 1.4 | BU4: =INDEX(效果参数!$C$37:$H$37,1,D4+1) -> 0.8 | BV4: =INDEX(效果参数!$C$38:$H$38,1,D4+1) -> 3 | BW4: =INDEX(效果参数!$C$39:$H$39,1,D4+1) -> 1 | BX4: =INDEX(效果参数!$C$40:$H$40,1,D4+1) -> 2 | BY4: =INDEX(效果参数!$C$41:$H$41,1,D4+1) -> 1 | BZ4: =IF(配置与结果!$H$24=1,AR4,MIN(AR4,MAX(0,配置与结果!$H$25))) -> 35 | CA4: =ROUNDDOWN(配置与结果!$B$17*(1+0.05+Y4),0) -> 2986 | CB4: =MIN(AD4,ROUNDDOWN((配置与结果!$B$16+CC4)*AC4,0)) -> 500 | CC4: =MIN(AM4,ROUNDDOWN(CA4*AL4,0)) -> 238 | CD4: =INDEX(效果参数!$C$96:$G$96,1,G4) -> 0.16 | CE4: =INDEX(效果参数!$C$42:$H$42,1,D4+1) -> 8 | CF4: =INDEX(效果参数!$C$54:$H$54,1,E4+1) -> 15 | CG4: =INDEX(效果参数!$C$55:$H$55,1,E4+1) -> 1.5 | CH4: =INDEX(效果参数!$C$106:$G$106,1,H4) -> 0.12
A5: =2 -> 2 | B5: ="红弩箭 0塑" -> 红弩箭 0塑 | C5: =0 -> 0 | D5: =配置与结果!B7 -> 0 | E5: =配置与结果!B8 -> 0 | F5: =配置与结果!B9 -> 0 | G5: =配置与结果!D6 -> 5 | H5: =配置与结果!D7 -> 1 | I5: =配置与结果!D8 -> 5 | J5: =配置与结果!D9 -> 1 | K5: =INDEX(效果参数!$C$105:$G$105,1,J5) -> 1 | L5: =AND(K5=1,INDEX(效果参数!$C$99:$G$99,1,H5)=1,INDEX(效果参数!$C$29:$H$29,1,C5+1)=1) -> TRUE | M5: =IF(AND(K5=1,L5),SUM(行动计算!AU78:AU113),"") -> 8766612 | N5: =IF(K5=1,SUMIFS(行动计算!AU78:AU113,行动计算!D78:D113,1),"") -> 3133250.7 | O5: =IF(L5,SUMIFS(行动计算!AU78:AU113,行动计算!D78:D113,2),"") -> 5633361.3 | P5: =IF(AND(K5=1,L5),SUMIFS(行动计算!AU78:AU113,行动计算!F78:F113,1),"") -> 7363386 | Q5: =IF(AND(K5=1,L5),SUMIFS(行动计算!AU78:AU113,行动计算!F78:F113,2),"") -> 642844.12 | R5: =IF(AND(K5=1,L5),SUMIFS(行动计算!AU78:AU113,行动计算!F78:F113,3),"") -> 489818.29 | S5: =IF(AND(K5=1,L5),SUMIFS(行动计算!AU78:AU113,行动计算!F78:F113,4),"") -> 270563.56 | T5: =IF(AND(ISNUMBER(M5),ISNUMBER($M$3),$M$3>0),M5/$M$3-1,"") -> 0 | U5: =INDEX(效果参数!$C$98:$G$98,1,H5) -> 0.04 | V5: =INDEX(效果参数!$C$97:$G$97,1,G5) -> 0.06 | W5: =INDEX(效果参数!$C$101:$G$101,1,I5) -> 0.02 | X5: =INDEX(效果参数!$C$102:$G$102,1,I5) -> 0.16 | Y5: =INDEX(效果参数!$C$100:$G$100,1,I5) -> 0.1 | Z5: =INDEX(效果参数!$C$103:$G$103,1,J5) -> 0.04 | AA5: =INDEX(效果参数!$C$104:$G$104,1,J5) -> 0.004 | AB5: =INDEX(效果参数!$C$30:$H$30,1,D5+1) -> 0.3 | AC5: =INDEX(效果参数!$C$31:$H$31,1,D5+1) -> 0.2 | AD5: =INDEX(效果参数!$C$32:$H$32,1,D5+1) -> 500 | AE5: =INDEX(效果参数!$C$33:$H$33,1,D5+1) -> 0.4 | AF5: =INDEX(效果参数!$C$34:$H$34,1,D5+1) -> 0.4 | AG5: =INDEX(效果参数!$C$43:$H$43,1,E5+1) -> 0.3 | AH5: =INDEX(效果参数!$C$44:$H$44,1,E5+1) -> 0.04 | AI5: =INDEX(效果参数!$C$45:$H$45,1,E5+1) -> 5 | AJ5: =INDEX(效果参数!$C$46:$H$46,1,E5+1) -> 1 | AK5: =INDEX(效果参数!$C$47:$H$47,1,E5+1) -> 2 | AL5: =INDEX(效果参数!$C$48:$H$48,1,E5+1) -> 0.08 | AM5: =INDEX(效果参数!$C$49:$H$49,1,E5+1) -> 250 | AN5: =INDEX(效果参数!$C$50:$H$50,1,E5+1) -> 0.15 | AO5: =INDEX(效果参数!$C$51:$H$51,1,E5+1) -> 0.15 | AP5: =INDEX(效果参数!$C$52:$H$52,1,E5+1) -> 0.15 | AQ5: =INDEX(效果参数!$C$53:$H$53,1,E5+1) -> 0.15 | AR5: =INDEX(效果参数!$C$56:$H$56,1,F5+1) -> 35 | AS5: =INDEX(效果参数!$C$57:$H$57,1,F5+1) -> 0.01 | AT5: =INDEX(效果参数!$C$58:$H$58,1,F5+1) -> 7 | AU5: =INDEX(效果参数!$C$59:$H$59,1,F5+1) -> 0.5 | AV5: =INDEX(效果参数!$C$6:$H$6,1,C5+1) -> 2 | AW5: =INDEX(效果参数!$C$7:$H$7,1,C5+1) -> 4 | AX5: =INDEX(效果参数!$C$8:$H$8,1,C5+1) -> 8 | AY5: =INDEX(效果参数!$C$9:$H$9,1,C5+1) -> 0.1 | AZ5: =INDEX(效果参数!$C$10:$H$10,1,C5+1) -> 0.2 | BA5: =INDEX(效果参数!$C$11:$H$11,1,C5+1) -> 0.6 | BB5: =INDEX(效果参数!$C$12:$H$12,1,C5+1) -> 1.2 | BC5: =INDEX(效果参数!$C$13:$H$13,1,C5+1) -> 0.06 | BD5: =INDEX(效果参数!$C$14:$H$14,1,C5+1) -> 3 | BE5: =INDEX(效果参数!$C$15:$H$15,1,C5+1) -> 1 | BF5: =INDEX(效果参数!$C$16:$H$16,1,C5+1) -> 0.025 | BG5: =INDEX(效果参数!$C$17:$H$17,1,C5+1) -> 18 | BH5: =INDEX(效果参数!$C$18:$H$18,1,C5+1) -> 18 | BI5: =INDEX(效果参数!$C$19:$H$19,1,C5+1) -> 1 | BJ5: =INDEX(效果参数!$C$20:$H$20,1,C5+1) -> 1 | BK5: =INDEX(效果参数!$C$21:$H$21,1,C5+1) -> 0.2 | BL5: =INDEX(效果参数!$C$22:$H$22,1,C5+1) -> 9 | BM5: =INDEX(效果参数!$C$23:$H$23,1,C5+1) -> 20 | BN5: =INDEX(效果参数!$C$24:$H$24,1,C5+1) -> 30 | BO5: =INDEX(效果参数!$C$25:$H$25,1,C5+1) -> 1.5 | BP5: =INDEX(效果参数!$C$26:$H$26,1,C5+1) -> 0.6 | BQ5: =INDEX(效果参数!$C$27:$H$27,1,C5+1) -> 0.8 | BR5: =INDEX(效果参数!$C$28:$H$28,1,C5+1) -> 1 | BS5: =INDEX(效果参数!$C$35:$H$35,1,D5+1) -> 2.8 | BT5: =INDEX(效果参数!$C$36:$H$36,1,D5+1) -> 1.4 | BU5: =INDEX(效果参数!$C$37:$H$37,1,D5+1) -> 0.8 | BV5: =INDEX(效果参数!$C$38:$H$38,1,D5+1) -> 3 | BW5: =INDEX(效果参数!$C$39:$H$39,1,D5+1) -> 1 | BX5: =INDEX(效果参数!$C$40:$H$40,1,D5+1) -> 2 | BY5: =INDEX(效果参数!$C$41:$H$41,1,D5+1) -> 1 | BZ5: =IF(配置与结果!$H$24=1,AR5,MIN(AR5,MAX(0,配置与结果!$H$25))) -> 35 | CA5: =ROUNDDOWN(配置与结果!$B$17*(1+0.05+Y5),0) -> 2986 | CB5: =MIN(AD5,ROUNDDOWN((配置与结果!$B$16+CC5)*AC5,0)) -> 500 | CC5: =MIN(AM5,ROUNDDOWN(CA5*AL5,0)) -> 238 | CD5: =INDEX(效果参数!$C$96:$G$96,1,G5) -> 0.16 | CE5: =INDEX(效果参数!$C$42:$H$42,1,D5+1) -> 8 | CF5: =INDEX(效果参数!$C$54:$H$54,1,E5+1) -> 15 | CG5: =INDEX(效果参数!$C$55:$H$55,1,E5+1) -> 1.5 | CH5: =INDEX(效果参数!$C$106:$G$106,1,H5) -> 0.12
A6: =3 -> 3 | B6: ="红弩箭 1塑" -> 红弩箭 1塑 | C6: =1 -> 1 | D6: =配置与结果!B7 -> 0 | E6: =配置与结果!B8 -> 0 | F6: =配置与结果!B9 -> 0 | G6: =配置与结果!D6 -> 5 | H6: =配置与结果!D7 -> 1 | I6: =配置与结果!D8 -> 5 | J6: =配置与结果!D9 -> 1 | K6: =INDEX(效果参数!$C$105:$G$105,1,J6) -> 1 | L6: =AND(K6=1,INDEX(效果参数!$C$99:$G$99,1,H6)=1,INDEX(效果参数!$C$29:$H$29,1,C6+1)=1) -> TRUE | M6: =IF(AND(K6=1,L6),SUM(行动计算!AU114:AU149),"") -> 12079361 | N6: =IF(K6=1,SUMIFS(行动计算!AU114:AU149,行动计算!D114:D149,1),"") -> 3133250.7 | O6: =IF(L6,SUMIFS(行动计算!AU114:AU149,行动计算!D114:D149,2),"") -> 8946110.3 | P6: =IF(AND(K6=1,L6),SUMIFS(行动计算!AU114:AU149,行动计算!F114:F149,1),"") -> 10676135 | Q6: =IF(AND(K6=1,L6),SUMIFS(行动计算!AU114:AU149,行动计算!F114:F149,2),"") -> 642844.12 | R6: =IF(AND(K6=1,L6),SUMIFS(行动计算!AU114:AU149,行动计算!F114:F149,3),"") -> 489818.29 | S6: =IF(AND(K6=1,L6),SUMIFS(行动计算!AU114:AU149,行动计算!F114:F149,4),"") -> 270563.56 | T6: =IF(AND(ISNUMBER(M6),ISNUMBER($M$3),$M$3>0),M6/$M$3-1,"") -> 0.37788247 | U6: =INDEX(效果参数!$C$98:$G$98,1,H6) -> 0.04 | V6: =INDEX(效果参数!$C$97:$G$97,1,G6) -> 0.06 | W6: =INDEX(效果参数!$C$101:$G$101,1,I6) -> 0.02 | X6: =INDEX(效果参数!$C$102:$G$102,1,I6) -> 0.16 | Y6: =INDEX(效果参数!$C$100:$G$100,1,I6) -> 0.1 | Z6: =INDEX(效果参数!$C$103:$G$103,1,J6) -> 0.04 | AA6: =INDEX(效果参数!$C$104:$G$104,1,J6) -> 0.004 | AB6: =INDEX(效果参数!$C$30:$H$30,1,D6+1) -> 0.3 | AC6: =INDEX(效果参数!$C$31:$H$31,1,D6+1) -> 0.2 | AD6: =INDEX(效果参数!$C$32:$H$32,1,D6+1) -> 500 | AE6: =INDEX(效果参数!$C$33:$H$33,1,D6+1) -> 0.4 | AF6: =INDEX(效果参数!$C$34:$H$34,1,D6+1) -> 0.4 | AG6: =INDEX(效果参数!$C$43:$H$43,1,E6+1) -> 0.3 | AH6: =INDEX(效果参数!$C$44:$H$44,1,E6+1) -> 0.04 | AI6: =INDEX(效果参数!$C$45:$H$45,1,E6+1) -> 5 | AJ6: =INDEX(效果参数!$C$46:$H$46,1,E6+1) -> 1 | AK6: =INDEX(效果参数!$C$47:$H$47,1,E6+1) -> 2 | AL6: =INDEX(效果参数!$C$48:$H$48,1,E6+1) -> 0.08 | AM6: =INDEX(效果参数!$C$49:$H$49,1,E6+1) -> 250 | AN6: =INDEX(效果参数!$C$50:$H$50,1,E6+1) -> 0.15 | AO6: =INDEX(效果参数!$C$51:$H$51,1,E6+1) -> 0.15 | AP6: =INDEX(效果参数!$C$52:$H$52,1,E6+1) -> 0.15 | AQ6: =INDEX(效果参数!$C$53:$H$53,1,E6+1) -> 0.15 | AR6: =INDEX(效果参数!$C$56:$H$56,1,F6+1) -> 35 | AS6: =INDEX(效果参数!$C$57:$H$57,1,F6+1) -> 0.01 | AT6: =INDEX(效果参数!$C$58:$H$58,1,F6+1) -> 7 | AU6: =INDEX(效果参数!$C$59:$H$59,1,F6+1) -> 0.5 | AV6: =INDEX(效果参数!$C$6:$H$6,1,C6+1) -> 2 | AW6: =INDEX(效果参数!$C$7:$H$7,1,C6+1) -> 4 | AX6: =INDEX(效果参数!$C$8:$H$8,1,C6+1) -> 8 | AY6: =INDEX(效果参数!$C$9:$H$9,1,C6+1) -> 0.1 | AZ6: =INDEX(效果参数!$C$10:$H$10,1,C6+1) -> 0.2 | BA6: =INDEX(效果参数!$C$11:$H$11,1,C6+1) -> 0.6 | BB6: =INDEX(效果参数!$C$12:$H$12,1,C6+1) -> 1.2 | BC6: =INDEX(效果参数!$C$13:$H$13,1,C6+1) -> 0.06 | BD6: =INDEX(效果参数!$C$14:$H$14,1,C6+1) -> 3 | BE6: =INDEX(效果参数!$C$15:$H$15,1,C6+1) -> 1 | BF6: =INDEX(效果参数!$C$16:$H$16,1,C6+1) -> 0.025 | BG6: =INDEX(效果参数!$C$17:$H$17,1,C6+1) -> 18 | BH6: =INDEX(效果参数!$C$18:$H$18,1,C6+1) -> 18 | BI6: =INDEX(效果参数!$C$19:$H$19,1,C6+1) -> 1 | BJ6: =INDEX(效果参数!$C$20:$H$20,1,C6+1) -> 1 | BK6: =INDEX(效果参数!$C$21:$H$21,1,C6+1) -> 0.2 | BL6: =INDEX(效果参数!$C$22:$H$22,1,C6+1) -> 15 | BM6: =INDEX(效果参数!$C$23:$H$23,1,C6+1) -> 32 | BN6: =INDEX(效果参数!$C$24:$H$24,1,C6+1) -> 50 | BO6: =INDEX(效果参数!$C$25:$H$25,1,C6+1) -> 2.5 | BP6: =INDEX(效果参数!$C$26:$H$26,1,C6+1) -> 0.6 | BQ6: =INDEX(效果参数!$C$27:$H$27,1,C6+1) -> 0.8 | BR6: =INDEX(效果参数!$C$28:$H$28,1,C6+1) -> 1 | BS6: =INDEX(效果参数!$C$35:$H$35,1,D6+1) -> 2.8 | BT6: =INDEX(效果参数!$C$36:$H$36,1,D6+1) -> 1.4 | BU6: =INDEX(效果参数!$C$37:$H$37,1,D6+1) -> 0.8 | BV6: =INDEX(效果参数!$C$38:$H$38,1,D6+1) -> 3 | BW6: =INDEX(效果参数!$C$39:$H$39,1,D6+1) -> 1 | BX6: =INDEX(效果参数!$C$40:$H$40,1,D6+1) -> 2 | BY6: =INDEX(效果参数!$C$41:$H$41,1,D6+1) -> 1 | BZ6: =IF(配置与结果!$H$24=1,AR6,MIN(AR6,MAX(0,配置与结果!$H$25))) -> 35 | CA6: =ROUNDDOWN(配置与结果!$B$17*(1+0.05+Y6),0) -> 2986 | CB6: =MIN(AD6,ROUNDDOWN((配置与结果!$B$16+CC6)*AC6,0)) -> 500 | CC6: =MIN(AM6,ROUNDDOWN(CA6*AL6,0)) -> 238 | CD6: =INDEX(效果参数!$C$96:$G$96,1,G6) -> 0.16 | CE6: =INDEX(效果参数!$C$42:$H$42,1,D6+1) -> 8 | CF6: =INDEX(效果参数!$C$54:$H$54,1,E6+1) -> 15 | CG6: =INDEX(效果参数!$C$55:$H$55,1,E6+1) -> 1.5 | CH6: =INDEX(效果参数!$C$106:$G$106,1,H6) -> 0.12
A7: =4 -> 4 | B7: ="红弩箭 2塑" -> 红弩箭 2塑 | C7: =2 -> 2 | D7: =配置与结果!B7 -> 0 | E7: =配置与结果!B8 -> 0 | F7: =配置与结果!B9 -> 0 | G7: =配置与结果!D6 -> 5 | H7: =配置与结果!D7 -> 1 | I7: =配置与结果!D8 -> 5 | J7: =配置与结果!D9 -> 1 | K7: =INDEX(效果参数!$C$105:$G$105,1,J7) -> 1 | L7: =AND(K7=1,INDEX(效果参数!$C$99:$G$99,1,H7)=1,INDEX(效果参数!$C$29:$H$29,1,C7+1)=1) -> TRUE | M7: =IF(AND(K7=1,L7),SUM(行动计算!AU150:AU185),"") -> 13566810 | N7: =IF(K7=1,SUMIFS(行动计算!AU150:AU185,行动计算!D150:D185,1),"") -> 4620699.7 | O7: =IF(L7,SUMIFS(行动计算!AU150:AU185,行动计算!D150:D185,2),"") -> 8946110.3 | P7: =IF(AND(K7=1,L7),SUMIFS(行动计算!AU150:AU185,行动计算!F150:F185,1),"") -> 12163584 | Q7: =IF(AND(K7=1,L7),SUMIFS(行动计算!AU150:AU185,行动计算!F150:F185,2),"") -> 642844.12 | R7: =IF(AND(K7=1,L7),SUMIFS(行动计算!AU150:AU185,行动计算!F150:F185,3),"") -> 489818.29 | S7: =IF(AND(K7=1,L7),SUMIFS(行动计算!AU150:AU185,行动计算!F150:F185,4),"") -> 270563.56 | T7: =IF(AND(ISNUMBER(M7),ISNUMBER($M$3),$M$3>0),M7/$M$3-1,"") -> 0.54755452 | U7: =INDEX(效果参数!$C$98:$G$98,1,H7) -> 0.04 | V7: =INDEX(效果参数!$C$97:$G$97,1,G7) -> 0.06 | W7: =INDEX(效果参数!$C$101:$G$101,1,I7) -> 0.02 | X7: =INDEX(效果参数!$C$102:$G$102,1,I7) -> 0.16 | Y7: =INDEX(效果参数!$C$100:$G$100,1,I7) -> 0.1 | Z7: =INDEX(效果参数!$C$103:$G$103,1,J7) -> 0.04 | AA7: =INDEX(效果参数!$C$104:$G$104,1,J7) -> 0.004 | AB7: =INDEX(效果参数!$C$30:$H$30,1,D7+1) -> 0.3 | AC7: =INDEX(效果参数!$C$31:$H$31,1,D7+1) -> 0.2 | AD7: =INDEX(效果参数!$C$32:$H$32,1,D7+1) -> 500 | AE7: =INDEX(效果参数!$C$33:$H$33,1,D7+1) -> 0.4 | AF7: =INDEX(效果参数!$C$34:$H$34,1,D7+1) -> 0.4 | AG7: =INDEX(效果参数!$C$43:$H$43,1,E7+1) -> 0.3 | AH7: =INDEX(效果参数!$C$44:$H$44,1,E7+1) -> 0.04 | AI7: =INDEX(效果参数!$C$45:$H$45,1,E7+1) -> 5 | AJ7: =INDEX(效果参数!$C$46:$H$46,1,E7+1) -> 1 | AK7: =INDEX(效果参数!$C$47:$H$47,1,E7+1) -> 2 | AL7: =INDEX(效果参数!$C$48:$H$48,1,E7+1) -> 0.08 | AM7: =INDEX(效果参数!$C$49:$H$49,1,E7+1) -> 250 | AN7: =INDEX(效果参数!$C$50:$H$50,1,E7+1) -> 0.15 | AO7: =INDEX(效果参数!$C$51:$H$51,1,E7+1) -> 0.15 | AP7: =INDEX(效果参数!$C$52:$H$52,1,E7+1) -> 0.15 | AQ7: =INDEX(效果参数!$C$53:$H$53,1,E7+1) -> 0.15 | AR7: =INDEX(效果参数!$C$56:$H$56,1,F7+1) -> 35 | AS7: =INDEX(效果参数!$C$57:$H$57,1,F7+1) -> 0.01 | AT7: =INDEX(效果参数!$C$58:$H$58,1,F7+1) -> 7 | AU7: =INDEX(效果参数!$C$59:$H$59,1,F7+1) -> 0.5 | AV7: =INDEX(效果参数!$C$6:$H$6,1,C7+1) -> 3 | AW7: =INDEX(效果参数!$C$7:$H$7,1,C7+1) -> 6 | AX7: =INDEX(效果参数!$C$8:$H$8,1,C7+1) -> 12 | AY7: =INDEX(效果参数!$C$9:$H$9,1,C7+1) -> 0.3 | AZ7: =INDEX(效果参数!$C$10:$H$10,1,C7+1) -> 0.6 | BA7: =INDEX(效果参数!$C$11:$H$11,1,C7+1) -> 0.6 | BB7: =INDEX(效果参数!$C$12:$H$12,1,C7+1) -> 1.2 | BC7: =INDEX(效果参数!$C$13:$H$13,1,C7+1) -> 0.06 | BD7: =INDEX(效果参数!$C$14:$H$14,1,C7+1) -> 5 | BE7: =INDEX(效果参数!$C$15:$H$15,1,C7+1) -> 2 | BF7: =INDEX(效果参数!$C$16:$H$16,1,C7+1) -> 0.025 | BG7: =INDEX(效果参数!$C$17:$H$17,1,C7+1) -> 18 | BH7: =INDEX(效果参数!$C$18:$H$18,1,C7+1) -> 18 | BI7: =INDEX(效果参数!$C$19:$H$19,1,C7+1) -> 1 | BJ7: =INDEX(效果参数!$C$20:$H$20,1,C7+1) -> 1 | BK7: =INDEX(效果参数!$C$21:$H$21,1,C7+1) -> 0.2 | BL7: =INDEX(效果参数!$C$22:$H$22,1,C7+1) -> 15 | BM7: =INDEX(效果参数!$C$23:$H$23,1,C7+1) -> 32 | BN7: =INDEX(效果参数!$C$24:$H$24,1,C7+1) -> 50 | BO7: =INDEX(效果参数!$C$25:$H$25,1,C7+1) -> 2.5 | BP7: =INDEX(效果参数!$C$26:$H$26,1,C7+1) -> 0.6 | BQ7: =INDEX(效果参数!$C$27:$H$27,1,C7+1) -> 0.8 | BR7: =INDEX(效果参数!$C$28:$H$28,1,C7+1) -> 1 | BS7: =INDEX(效果参数!$C$35:$H$35,1,D7+1) -> 2.8 | BT7: =INDEX(效果参数!$C$36:$H$36,1,D7+1) -> 1.4 | BU7: =INDEX(效果参数!$C$37:$H$37,1,D7+1) -> 0.8 | BV7: =INDEX(效果参数!$C$38:$H$38,1,D7+1) -> 3 | BW7: =INDEX(效果参数!$C$39:$H$39,1,D7+1) -> 1 | BX7: =INDEX(效果参数!$C$40:$H$40,1,D7+1) -> 2 | BY7: =INDEX(效果参数!$C$41:$H$41,1,D7+1) -> 1 | BZ7: =IF(配置与结果!$H$24=1,AR7,MIN(AR7,MAX(0,配置与结果!$H$25))) -> 35 | CA7: =ROUNDDOWN(配置与结果!$B$17*(1+0.05+Y7),0) -> 2986 | CB7: =MIN(AD7,ROUNDDOWN((配置与结果!$B$16+CC7)*AC7,0)) -> 500 | CC7: =MIN(AM7,ROUNDDOWN(CA7*AL7,0)) -> 238 | CD7: =INDEX(效果参数!$C$96:$G$96,1,G7) -> 0.16 | CE7: =INDEX(效果参数!$C$42:$H$42,1,D7+1) -> 8 | CF7: =INDEX(效果参数!$C$54:$H$54,1,E7+1) -> 15 | CG7: =INDEX(效果参数!$C$55:$H$55,1,E7+1) -> 1.5 | CH7: =INDEX(效果参数!$C$106:$G$106,1,H7) -> 0.12
A8: =5 -> 5 | B8: ="红弩箭 3塑" -> 红弩箭 3塑 | C8: =3 -> 3 | D8: =配置与结果!B7 -> 0 | E8: =配置与结果!B8 -> 0 | F8: =配置与结果!B9 -> 0 | G8: =配置与结果!D6 -> 5 | H8: =配置与结果!D7 -> 1 | I8: =配置与结果!D8 -> 5 | J8: =配置与结果!D9 -> 1 | K8: =INDEX(效果参数!$C$105:$G$105,1,J8) -> 1 | L8: =AND(K8=1,INDEX(效果参数!$C$99:$G$99,1,H8)=1,INDEX(效果参数!$C$29:$H$29,1,C8+1)=1) -> TRUE | M8: =IF(AND(K8=1,L8),SUM(行动计算!AU186:AU221),"") -> 15110630 | N8: =IF(K8=1,SUMIFS(行动计算!AU186:AU221,行动计算!D186:D221,1),"") -> 6164519.7 | O8: =IF(L8,SUMIFS(行动计算!AU186:AU221,行动计算!D186:D221,2),"") -> 8946110.3 | P8: =IF(AND(K8=1,L8),SUMIFS(行动计算!AU186:AU221,行动计算!F186:F221,1),"") -> 13707404 | Q8: =IF(AND(K8=1,L8),SUMIFS(行动计算!AU186:AU221,行动计算!F186:F221,2),"") -> 642844.12 | R8: =IF(AND(K8=1,L8),SUMIFS(行动计算!AU186:AU221,行动计算!F186:F221,3),"") -> 489818.29 | S8: =IF(AND(K8=1,L8),SUMIFS(行动计算!AU186:AU221,行动计算!F186:F221,4),"") -> 270563.56 | T8: =IF(AND(ISNUMBER(M8),ISNUMBER($M$3),$M$3>0),M8/$M$3-1,"") -> 0.72365676 | U8: =INDEX(效果参数!$C$98:$G$98,1,H8) -> 0.04 | V8: =INDEX(效果参数!$C$97:$G$97,1,G8) -> 0.06 | W8: =INDEX(效果参数!$C$101:$G$101,1,I8) -> 0.02 | X8: =INDEX(效果参数!$C$102:$G$102,1,I8) -> 0.16 | Y8: =INDEX(效果参数!$C$100:$G$100,1,I8) -> 0.1 | Z8: =INDEX(效果参数!$C$103:$G$103,1,J8) -> 0.04 | AA8: =INDEX(效果参数!$C$104:$G$104,1,J8) -> 0.004 | AB8: =INDEX(效果参数!$C$30:$H$30,1,D8+1) -> 0.3 | AC8: =INDEX(效果参数!$C$31:$H$31,1,D8+1) -> 0.2 | AD8: =INDEX(效果参数!$C$32:$H$32,1,D8+1) -> 500 | AE8: =INDEX(效果参数!$C$33:$H$33,1,D8+1) -> 0.4 | AF8: =INDEX(效果参数!$C$34:$H$34,1,D8+1) -> 0.4 | AG8: =INDEX(效果参数!$C$43:$H$43,1,E8+1) -> 0.3 | AH8: =INDEX(效果参数!$C$44:$H$44,1,E8+1) -> 0.04 | AI8: =INDEX(效果参数!$C$45:$H$45,1,E8+1) -> 5 | AJ8: =INDEX(效果参数!$C$46:$H$46,1,E8+1) -> 1 | AK8: =INDEX(效果参数!$C$47:$H$47,1,E8+1) -> 2 | AL8: =INDEX(效果参数!$C$48:$H$48,1,E8+1) -> 0.08 | AM8: =INDEX(效果参数!$C$49:$H$49,1,E8+1) -> 250 | AN8: =INDEX(效果参数!$C$50:$H$50,1,E8+1) -> 0.15 | AO8: =INDEX(效果参数!$C$51:$H$51,1,E8+1) -> 0.15 | AP8: =INDEX(效果参数!$C$52:$H$52,1,E8+1) -> 0.15 | AQ8: =INDEX(效果参数!$C$53:$H$53,1,E8+1) -> 0.15 | AR8: =INDEX(效果参数!$C$56:$H$56,1,F8+1) -> 35 | AS8: =INDEX(效果参数!$C$57:$H$57,1,F8+1) -> 0.01 | AT8: =INDEX(效果参数!$C$58:$H$58,1,F8+1) -> 7 | AU8: =INDEX(效果参数!$C$59:$H$59,1,F8+1) -> 0.5 | AV8: =INDEX(效果参数!$C$6:$H$6,1,C8+1) -> 3 | AW8: =INDEX(效果参数!$C$7:$H$7,1,C8+1) -> 6 | AX8: =INDEX(效果参数!$C$8:$H$8,1,C8+1) -> 12 | AY8: =INDEX(效果参数!$C$9:$H$9,1,C8+1) -> 0.3 | AZ8: =INDEX(效果参数!$C$10:$H$10,1,C8+1) -> 0.6 | BA8: =INDEX(效果参数!$C$11:$H$11,1,C8+1) -> 0.6 | BB8: =INDEX(效果参数!$C$12:$H$12,1,C8+1) -> 1.2 | BC8: =INDEX(效果参数!$C$13:$H$13,1,C8+1) -> 0.06 | BD8: =INDEX(效果参数!$C$14:$H$14,1,C8+1) -> 5 | BE8: =INDEX(效果参数!$C$15:$H$15,1,C8+1) -> 2 | BF8: =INDEX(效果参数!$C$16:$H$16,1,C8+1) -> 0.025 | BG8: =INDEX(效果参数!$C$17:$H$17,1,C8+1) -> 36 | BH8: =INDEX(效果参数!$C$18:$H$18,1,C8+1) -> 36 | BI8: =INDEX(效果参数!$C$19:$H$19,1,C8+1) -> 1.8 | BJ8: =INDEX(效果参数!$C$20:$H$20,1,C8+1) -> 1.8 | BK8: =INDEX(效果参数!$C$21:$H$21,1,C8+1) -> 0.5 | BL8: =INDEX(效果参数!$C$22:$H$22,1,C8+1) -> 15 | BM8: =INDEX(效果参数!$C$23:$H$23,1,C8+1) -> 32 | BN8: =INDEX(效果参数!$C$24:$H$24,1,C8+1) -> 50 | BO8: =INDEX(效果参数!$C$25:$H$25,1,C8+1) -> 2.5 | BP8: =INDEX(效果参数!$C$26:$H$26,1,C8+1) -> 0.6 | BQ8: =INDEX(效果参数!$C$27:$H$27,1,C8+1) -> 0.8 | BR8: =INDEX(效果参数!$C$28:$H$28,1,C8+1) -> 1 | BS8: =INDEX(效果参数!$C$35:$H$35,1,D8+1) -> 2.8 | BT8: =INDEX(效果参数!$C$36:$H$36,1,D8+1) -> 1.4 | BU8: =INDEX(效果参数!$C$37:$H$37,1,D8+1) -> 0.8 | BV8: =INDEX(效果参数!$C$38:$H$38,1,D8+1) -> 3 | BW8: =INDEX(效果参数!$C$39:$H$39,1,D8+1) -> 1 | BX8: =INDEX(效果参数!$C$40:$H$40,1,D8+1) -> 2 | BY8: =INDEX(效果参数!$C$41:$H$41,1,D8+1) -> 1 | BZ8: =IF(配置与结果!$H$24=1,AR8,MIN(AR8,MAX(0,配置与结果!$H$25))) -> 35 | CA8: =ROUNDDOWN(配置与结果!$B$17*(1+0.05+Y8),0) -> 2986 | CB8: =MIN(AD8,ROUNDDOWN((配置与结果!$B$16+CC8)*AC8,0)) -> 500 | CC8: =MIN(AM8,ROUNDDOWN(CA8*AL8,0)) -> 238 | CD8: =INDEX(效果参数!$C$96:$G$96,1,G8) -> 0.16 | CE8: =INDEX(效果参数!$C$42:$H$42,1,D8+1) -> 8 | CF8: =INDEX(效果参数!$C$54:$H$54,1,E8+1) -> 15 | CG8: =INDEX(效果参数!$C$55:$H$55,1,E8+1) -> 1.5 | CH8: =INDEX(效果参数!$C$106:$G$106,1,H8) -> 0.12
A9: =6 -> 6 | B9: ="红弩箭 4塑" -> 红弩箭 4塑 | C9: =4 -> 4 | D9: =配置与结果!B7 -> 0 | E9: =配置与结果!B8 -> 0 | F9: =配置与结果!B9 -> 0 | G9: =配置与结果!D6 -> 5 | H9: =配置与结果!D7 -> 1 | I9: =配置与结果!D8 -> 5 | J9: =配置与结果!D9 -> 1 | K9: =INDEX(效果参数!$C$105:$G$105,1,J9) -> 1 | L9: =AND(K9=1,INDEX(效果参数!$C$99:$G$99,1,H9)=1,INDEX(效果参数!$C$29:$H$29,1,C9+1)=1) -> TRUE | M9: =IF(AND(K9=1,L9),SUM(行动计算!AU222:AU257),"") -> 16284949 | N9: =IF(K9=1,SUMIFS(行动计算!AU222:AU257,行动计算!D222:D257,1),"") -> 7338838.7 | O9: =IF(L9,SUMIFS(行动计算!AU222:AU257,行动计算!D222:D257,2),"") -> 8946110.3 | P9: =IF(AND(K9=1,L9),SUMIFS(行动计算!AU222:AU257,行动计算!F222:F257,1),"") -> 14881723 | Q9: =IF(AND(K9=1,L9),SUMIFS(行动计算!AU222:AU257,行动计算!F222:F257,2),"") -> 642844.12 | R9: =IF(AND(K9=1,L9),SUMIFS(行动计算!AU222:AU257,行动计算!F222:F257,3),"") -> 489818.29 | S9: =IF(AND(K9=1,L9),SUMIFS(行动计算!AU222:AU257,行动计算!F222:F257,4),"") -> 270563.56 | T9: =IF(AND(ISNUMBER(M9),ISNUMBER($M$3),$M$3>0),M9/$M$3-1,"") -> 0.85761033 | U9: =INDEX(效果参数!$C$98:$G$98,1,H9) -> 0.04 | V9: =INDEX(效果参数!$C$97:$G$97,1,G9) -> 0.06 | W9: =INDEX(效果参数!$C$101:$G$101,1,I9) -> 0.02 | X9: =INDEX(效果参数!$C$102:$G$102,1,I9) -> 0.16 | Y9: =INDEX(效果参数!$C$100:$G$100,1,I9) -> 0.1 | Z9: =INDEX(效果参数!$C$103:$G$103,1,J9) -> 0.04 | AA9: =INDEX(效果参数!$C$104:$G$104,1,J9) -> 0.004 | AB9: =INDEX(效果参数!$C$30:$H$30,1,D9+1) -> 0.3 | AC9: =INDEX(效果参数!$C$31:$H$31,1,D9+1) -> 0.2 | AD9: =INDEX(效果参数!$C$32:$H$32,1,D9+1) -> 500 | AE9: =INDEX(效果参数!$C$33:$H$33,1,D9+1) -> 0.4 | AF9: =INDEX(效果参数!$C$34:$H$34,1,D9+1) -> 0.4 | AG9: =INDEX(效果参数!$C$43:$H$43,1,E9+1) -> 0.3 | AH9: =INDEX(效果参数!$C$44:$H$44,1,E9+1) -> 0.04 | AI9: =INDEX(效果参数!$C$45:$H$45,1,E9+1) -> 5 | AJ9: =INDEX(效果参数!$C$46:$H$46,1,E9+1) -> 1 | AK9: =INDEX(效果参数!$C$47:$H$47,1,E9+1) -> 2 | AL9: =INDEX(效果参数!$C$48:$H$48,1,E9+1) -> 0.08 | AM9: =INDEX(效果参数!$C$49:$H$49,1,E9+1) -> 250 | AN9: =INDEX(效果参数!$C$50:$H$50,1,E9+1) -> 0.15 | AO9: =INDEX(效果参数!$C$51:$H$51,1,E9+1) -> 0.15 | AP9: =INDEX(效果参数!$C$52:$H$52,1,E9+1) -> 0.15 | AQ9: =INDEX(效果参数!$C$53:$H$53,1,E9+1) -> 0.15 | AR9: =INDEX(效果参数!$C$56:$H$56,1,F9+1) -> 35 | AS9: =INDEX(效果参数!$C$57:$H$57,1,F9+1) -> 0.01 | AT9: =INDEX(效果参数!$C$58:$H$58,1,F9+1) -> 7 | AU9: =INDEX(效果参数!$C$59:$H$59,1,F9+1) -> 0.5 | AV9: =INDEX(效果参数!$C$6:$H$6,1,C9+1) -> 3 | AW9: =INDEX(效果参数!$C$7:$H$7,1,C9+1) -> 6 | AX9: =INDEX(效果参数!$C$8:$H$8,1,C9+1) -> 12 | AY9: =INDEX(效果参数!$C$9:$H$9,1,C9+1) -> 0.3 | AZ9: =INDEX(效果参数!$C$10:$H$10,1,C9+1) -> 0.6 | BA9: =INDEX(效果参数!$C$11:$H$11,1,C9+1) -> 1 | BB9: =INDEX(效果参数!$C$12:$H$12,1,C9+1) -> 2 | BC9: =INDEX(效果参数!$C$13:$H$13,1,C9+1) -> 0.1 | BD9: =INDEX(效果参数!$C$14:$H$14,1,C9+1) -> 5 | BE9: =INDEX(效果参数!$C$15:$H$15,1,C9+1) -> 2 | BF9: =INDEX(效果参数!$C$16:$H$16,1,C9+1) -> 0.05 | BG9: =INDEX(效果参数!$C$17:$H$17,1,C9+1) -> 36 | BH9: =INDEX(效果参数!$C$18:$H$18,1,C9+1) -> 36 | BI9: =INDEX(效果参数!$C$19:$H$19,1,C9+1) -> 1.8 | BJ9: =INDEX(效果参数!$C$20:$H$20,1,C9+1) -> 1.8 | BK9: =INDEX(效果参数!$C$21:$H$21,1,C9+1) -> 0.5 | BL9: =INDEX(效果参数!$C$22:$H$22,1,C9+1) -> 15 | BM9: =INDEX(效果参数!$C$23:$H$23,1,C9+1) -> 32 | BN9: =INDEX(效果参数!$C$24:$H$24,1,C9+1) -> 50 | BO9: =INDEX(效果参数!$C$25:$H$25,1,C9+1) -> 2.5 | BP9: =INDEX(效果参数!$C$26:$H$26,1,C9+1) -> 0.6 | BQ9: =INDEX(效果参数!$C$27:$H$27,1,C9+1) -> 0.8 | BR9: =INDEX(效果参数!$C$28:$H$28,1,C9+1) -> 1 | BS9: =INDEX(效果参数!$C$35:$H$35,1,D9+1) -> 2.8 | BT9: =INDEX(效果参数!$C$36:$H$36,1,D9+1) -> 1.4 | BU9: =INDEX(效果参数!$C$37:$H$37,1,D9+1) -> 0.8 | BV9: =INDEX(效果参数!$C$38:$H$38,1,D9+1) -> 3 | BW9: =INDEX(效果参数!$C$39:$H$39,1,D9+1) -> 1 | BX9: =INDEX(效果参数!$C$40:$H$40,1,D9+1) -> 2 | BY9: =INDEX(效果参数!$C$41:$H$41,1,D9+1) -> 1 | BZ9: =IF(配置与结果!$H$24=1,AR9,MIN(AR9,MAX(0,配置与结果!$H$25))) -> 35 | CA9: =ROUNDDOWN(配置与结果!$B$17*(1+0.05+Y9),0) -> 2986 | CB9: =MIN(AD9,ROUNDDOWN((配置与结果!$B$16+CC9)*AC9,0)) -> 500 | CC9: =MIN(AM9,ROUNDDOWN(CA9*AL9,0)) -> 238 | CD9: =INDEX(效果参数!$C$96:$G$96,1,G9) -> 0.16 | CE9: =INDEX(效果参数!$C$42:$H$42,1,D9+1) -> 8 | CF9: =INDEX(效果参数!$C$54:$H$54,1,E9+1) -> 15 | CG9: =INDEX(效果参数!$C$55:$H$55,1,E9+1) -> 1.5 | CH9: =INDEX(效果参数!$C$106:$G$106,1,H9) -> 0.12
