Workbook

Sheet 角色面板
A1: 洞知队｜角色基础数值与入战面板
A3: 角色 | B3: 灵感 | C3: 攻击 | D3: 生命 | E3: 现实防御 | F3: 精神防御 | G3: 暴击率 | H3: 暴击创伤 | I3: 创伤加成 | J3: 受创减免 | K3: 术法威力 | L3: 仪式威力 | M3: 伤害加成
A4: 红弩箭 | B4: 星 | C4: 2296 | D4: 9354 | E4: 797 | F4: 763 | G4: 0.7 | H4: 2.026 | I4: 0.1 | J4: 0.07 | K4: 0 | L4: 0 | M4: 0
A5: 37 | B5: 星 | C5: 2306 | D5: 11089 | E5: 760 | F5: 853 | G5: 0.46 | H5: 1.928 | I5: 0.005 | J5: 0.01 | K5: 0 | L5: 0 | M5: 0
A6: 小瑞安侬 | B6: 兽 | C6: 2597 | D6: 12240 | E6: 818 | F6: 838 | G6: 0.255 | H6: 1.55 | I6: 0.035 | J6: 0.205 | K6: 0 | L6: 0 | M6: 0
A7: J | B7: 兽 | C7: 1906 | D7: 12876 | E7: 942 | F7: 942 | G7: 0.367 | H7: 1.718 | I7: 0.025 | J7: 0.06 | K7: 0 | L7: 0 | M7: 0
A9: 入战加成｜已包含账号练度效果与本关场地Buff
A10: 角色 | B10: 来源 | C10: 攻击 | D10: 生命 | E10: 现实防御 | F10: 精神防御 | G10: 暴击率 | H10: 暴击创伤 | I10: 创伤加成 | J10: 受创减免 | K10: 术法威力 | L10: 仪式威力 | M10: 伤害加成
A11: 红弩箭 | B11: 场地+37狂想IV+洞悉II+立于风暴脊A5 | C11: 0.2 | D11: 0.2 | E11: 0.2 | F11: 0.2 | G11: 0.3 | H11: 0 | I11: 0 | J11: 0 | K11: =Boss参数!$B$58 -> -0.4 | L11: 0 | M11: 0.24
A12: 37 | B12: 场地+狂想IV+洞悉II+灵知当齐一A1 | C12: 0.2 | D12: 0.2 | E12: 0.2 | F12: 0.2 | G12: 0.3 | H12: 0.27 | I12: 0 | J12: 0 | K12: =Boss参数!$B$58 -> -0.4 | L12: 0 | M12: 0
A13: 小瑞安侬 | B13: 全员场地术法减益+洞悉II+昨日雨声轻A5+37狂想IV | C13: 0.15 | D13: 0.1 | E13: 0 | F13: 0 | G13: 0.3 | H13: 0 | I13: 0 | J13: 0 | K13: =Boss参数!$B$58 -> -0.4 | L13: 0 | M13: 0
A14: J | B14: 全员场地术法减益+洞悉II+37狂想IV | C14: 0 | D14: 0 | E14: 0 | F14: 0 | G14: 0.3 | H14: 0 | I14: 0 | J14: 0 | K14: =Boss参数!$B$58 -> -0.4 | L14: 0 | M14: 0.08
A16: 最终入战面板｜攻击、生命、双防向下取整
A17: 角色 | B17: 灵感 | C17: 攻击 | D17: 生命 | E17: 现实防御 | F17: 精神防御 | G17: 暴击率 | H17: 暴击创伤 | I17: 创伤加成 | J17: 受创减免 | K17: 术法威力 | L17: 仪式威力 | M17: 伤害加成
A18: =A4 -> 红弩箭 | B18: =B4 -> 星 | C18: =ROUNDDOWN(C4*(1+C11),0) -> 2755 | D18: =ROUNDDOWN(D4*(1+D11),0) -> 11224 | E18: =ROUNDDOWN(E4*(1+E11),0) -> 956 | F18: =ROUNDDOWN(F4*(1+F11),0) -> 915 | G18: =G4+G11 -> 1 | H18: =H4+H11 -> 2.026 | I18: =I4+I11 -> 0.1 | J18: =J4+J11 -> 0.07 | K18: =K4+K11 -> -0.4 | L18: =L4+L11 -> 0 | M18: =M4+M11 -> 0.24
A19: =A5 -> 37 | B19: =B5 -> 星 | C19: =ROUNDDOWN(C5*(1+C12),0) -> 2767 | D19: =ROUNDDOWN(D5*(1+D12),0) -> 13306 | E19: =ROUNDDOWN(E5*(1+E12),0) -> 912 | F19: =ROUNDDOWN(F5*(1+F12),0) -> 1023 | G19: =G5+G12 -> 0.76 | H19: =H5+H12 -> 2.198 | I19: =I5+I12 -> 0.005 | J19: =J5+J12 -> 0.01 | K19: =K5+K12 -> -0.4 | L19: =L5+L12 -> 0 | M19: =M5+M12 -> 0
A20: =A6 -> 小瑞安侬 | B20: =B6 -> 兽 | C20: =ROUNDDOWN(C6*(1+C13),0) -> 2986 | D20: =ROUNDDOWN(D6*(1+D13),0) -> 13464 | E20: =ROUNDDOWN(E6*(1+E13),0) -> 818 | F20: =ROUNDDOWN(F6*(1+F13),0) -> 838 | G20: =G6+G13 -> 0.555 | H20: =H6+H13 -> 1.55 | I20: =I6+I13 -> 0.035 | J20: =J6+J13 -> 0.205 | K20: =K6+K13 -> -0.4 | L20: =L6+L13 -> 0 | M20: =M6+M13 -> 0
A21: =A7 -> J | B21: =B7 -> 兽 | C21: =ROUNDDOWN(C7*(1+C14),0) -> 1906 | D21: =ROUNDDOWN(D7*(1+D14),0) -> 12876 | E21: =ROUNDDOWN(E7*(1+E14),0) -> 942 | F21: =ROUNDDOWN(F7*(1+F14),0) -> 942 | G21: =G7+G14 -> 0.667 | H21: =H7+H14 -> 1.718 | I21: =I7+I14 -> 0.025 | J21: =J7+J14 -> 0.06 | K21: =K7+K14 -> -0.4 | L21: =L7+L14 -> 0 | M21: =M7+M14 -> 0.08
A24: 账号 | B24: 红弩箭：2塑｜洞悉III 60｜共鸣13 希冀｜立于风暴脊 Lv60 A5
A25: 账号 | B25: 37：0塑｜洞悉III 60｜共鸣10 恍然惊诧｜狂想IV｜灵知当齐一 Lv60 A1
A26: 账号 | B26: 小瑞安侬：0塑｜洞悉III 60｜共鸣15 亢奋｜昨日雨声轻 Lv60 A5
A27: 账号 | B27: J：0塑｜洞悉III 60｜共鸣10 未调频｜狂想IV｜家庭指导员Lv60 A1。已确认1906攻击、12876生命、创伤加成2.5%来自装备心相后面板。心相360攻击、3000生命、双防160及16%生命不重复添加。
A28: 场地 | B28: 星/岩：攻击、现实防御、精神防御、最大生命+20%；全员：术法威力−40%，全程生效。统一术法减益在Boss参数B58修改。
A29: 说明 | B29: 黄色为可编辑输入；绿色为公式结果。基础面板直接使用游戏内显示值，避免重复叠加共鸣/调频/心相静态属性。

Sheet 技能数据库
A1: 技能数据库｜伤害倍率与核心机制
A3: 选择键 | B3: 角色 | C3: 技能 | D3: 阶次 | E3: 类型 | F3: 创伤类型 | G3: 基础倍率 | H3: 本源倍率 | I3: 代码 | J3: 目标 | K3: 机制摘要 | L3: 来源URL
A4: 系统｜进入弱点洞穿 | B4: 系统 | C4: 进入弱点洞穿 | D4: 0 | E4: 系统 | F4: 无 | G4: 0 | H4: 0 | I4: ENTER_INSIGHT | J4: 系统 | K4: 手动插入；重置洞穿阶段计数 | L4: https://res1999.huijiwiki.com/wiki/37
A5: 红弩箭｜极限俯冲Ⅰ | B5: 红弩箭 | C5: 极限俯冲 | D5: 1 | E5: 术法 | F5: 现实 | G5: 3 | H5: 0 | I5: LILYA_DIVE | J5: 单体 | K5: 2塑基础300%；吟诵追加倍率/伤害提升由后台计算 | L5: https://res1999.huijiwiki.com/wiki/狩勋女巫红弩箭
A6: 红弩箭｜极限俯冲Ⅱ | B6: 红弩箭 | C6: 极限俯冲 | D6: 2 | E6: 术法 | F6: 现实 | G6: 6 | H6: 0 | I6: LILYA_DIVE | J6: 单体 | K6: 2塑基础600% | L6: https://res1999.huijiwiki.com/wiki/狩勋女巫红弩箭
A7: 红弩箭｜极限俯冲Ⅲ | B7: 红弩箭 | C7: 极限俯冲 | D7: 3 | E7: 术法 | F7: 现实 | G7: 9 | H7: 0 | I7: LILYA_DIVE | J7: 单体 | K7: 2塑基础900% | L7: https://res1999.huijiwiki.com/wiki/狩勋女巫红弩箭
A8: 红弩箭｜眼镜蛇机动 | B8: 红弩箭 | C8: 眼镜蛇机动 | D8: 0 | E8: 增益 | F8: 无 | G8: 0 | H8: 0 | I8: LILYA_COBRA | J8: 自身 | K8: 自我吟诵，进入雷鸣引擎；已有雷鸣时获得1层弹药，已有极限时获得2层弹药。首次使用额外赋予5增压、6弹药及1激情。 | L8: 用户完整文本；保留原无阶次名称作为Ⅰ阶别名
A9: 红弩箭｜试试杀手锏 | B9: 红弩箭 | C9: 试试杀手锏 | D9: 0 | E9: 仪式 | F9: 现实 | G9: 18 | H9: 0 | I9: LILYA_ULT | J9: 主目标 | K9: 2塑主目标1800%；弹药≥6再追加1800%并强化仪式/暴创/穿透 | L9: https://res1999.huijiwiki.com/wiki/狩勋女巫红弩箭
A10: 红弩箭｜洞知咒语 | B10: 红弩箭 | C10: 洞知咒语 | D10: 0 | E10: 洞知 | F10: 现实 | G10: 15 | H10: 0 | I10: LILYA_INSIGHT | J10: 单体/强化群体 | K10: 1500%现实；普通洞知攻击时暴创+60%；自身每第三次强化3200%现实，攻击时暴创+80%。 | L10: 用户提供完整技能文字；开局13次主伤及4次附加精确
A11: 红弩箭｜洞知终结 | B11: 红弩箭 | C11: 洞知终结 | D11: 0 | E11: 洞知 | F11: 现实 | G11: 50 | H11: 0 | I11: LILYA_FINISH | J11: 群体 | K11: 5000%现实＋本阶段此前队伍每行动一次250%；攻击时暴创+100%；攻击后退出洞穿。 | L11: 用户提供完整技能文字；开局终结964769+385907精确
A12: 37｜三角正论Ⅰ | B12: 37 | C12: 三角正论 | D12: 1 | E12: 术法 | F12: 精神 | G12: 2.8 | H12: 0.8 | I12: 37_TRIANGLE | J12: 单体 | K12: 狂想III：基础值额外100%，精神280%+本源80%；基础逐阶值为原玩家记录，狂想增加由游戏截图确认。 | L12: https://bbs.4399.cn/thread-view-tid-44096347
A13: 37｜三角正论Ⅱ | B13: 37 | C13: 三角正论 | D13: 2 | E13: 术法 | F13: 精神 | G13: 4.2 | H13: 1.2 | I13: 37_TRIANGLE | J13: 单体 | K13: 狂想III：基础值额外100%，精神420%+本源120%；基础逐阶值为原玩家记录，狂想增加由游戏截图确认。 | L13: https://bbs.4399.cn/thread-view-tid-44096347
A14: 37｜三角正论Ⅲ | B14: 37 | C14: 三角正论 | D14: 3 | E14: 术法 | F14: 精神 | G14: 7 | H14: 2 | I14: 37_TRIANGLE | J14: 单体 | K14: 狂想III：基础值额外100%，精神700%+本源200%；基础逐阶值为原玩家记录，狂想增加由游戏截图确认。 | L14: https://bbs.4399.cn/thread-view-tid-44096347
A15: 37｜曲线映射Ⅰ | B15: 37 | C15: 曲线映射 | D15: 1 | E15: 术法 | F15: 精神 | G15: 1.4 | H15: 0.8 | I15: 37_CURVE | J15: 2目标 | K15: 狂想III：基础值额外100%，精神140%+本源80%；基础逐阶值为原玩家记录，狂想增加由游戏截图确认。 | L15: https://bbs.4399.cn/thread-view-tid-44096347
... A32: J｜飞跃海特街 | B32: J | C32: 飞跃海特街 | D32: 0 | E32: 仪式 | F32: 现实 | G32: 7 | H32: 0 | I32: J_ULT | J32: 主目标 | K32: 700%现实创伤；攻击前添加自身燃烧层数，J不获得燃烧。主目标每溢出1层，本表按额外100%现实创伤计算。伤后全队伤加每层燃烧＋2.5%，持续3回合。 | L32: 游戏文本为溢出每层50%；三次独立测试及原表两次仪式支持有效100%。怀疑游戏内bug或文本显示错误，具体原因未确认。
A33: 系统｜Boss行动 | B33: 系统 | C33: Boss行动 | D33: 0 | E33: 系统 | F33: 无 | G33: 0 | H33: 0 | I33: BOSS_ACTION | J33: 0 | K33: 0 | L33: 无反击时记录敌方行动开始；同阶段只记录一次，之后的J反击继续逐条填写
A34: 红弩箭｜眼镜蛇机动Ⅰ | B34: 红弩箭 | C34: 眼镜蛇机动 | D34: 1 | E34: 增益 | F34: 无 | G34: 0 | H34: 0 | I34: LILYA_COBRA | J34: 自身 | K34: Ⅰ阶：进入雷鸣；已有雷鸣时获得1弹药，已有极限时获得2弹药。 | L34: 用户完整文本
A35: 红弩箭｜眼镜蛇机动Ⅱ | B35: 红弩箭 | C35: 眼镜蛇机动 | D35: 2 | E35: 增益 | F35: 无 | G35: 0 | H35: 0 | I35: LILYA_COBRA | J35: 自身 | K35: Ⅱ阶：进入雷鸣；已有雷鸣时获得2弹药，已有极限时获得4弹药。 | L35: 用户完整文本
A36: 系统｜回合结束 | B36: 系统 | C36: 回合结束 | D36: 0 | E36: 系统 | F36: 无 | G36: 0 | H36: 0 | I36: END_TURN | J36: 系统 | K36: 仅结算回合末与阶段收尾，不是Boss攻击；没有敌方实际行动的阶段在交界仍会刷新仰望。 | L36: 小瑞额外回合第68行；本场10个阶段开局仰望检验支持。
A37: 系统｜Boss仪式·保守主义 | B37: 系统 | C37: Boss仪式·保守主义 | D37: 0 | E37: 系统 | F37: 无 | G37: 0 | H37: 0 | I37: BOSS_CONSERVATIVE | J37: 系统 | K37: 施加保守主义：额外行动暴击率－50个百分点、暴击创伤－70个百分点，持续2回合 | L37: 第5回合仪式后立即生效，施加回合不扣持续时间；第6回合剩2、第7回合剩1；洞知按用户要求不受影响。
A38: 红弩箭｜眼镜蛇机动Ⅲ | B38: 红弩箭 | C38: 眼镜蛇机动 | D38: 3 | E38: 增益 | F38: 无 | G38: 0 | H38: 0 | I38: LILYA_COBRA | J38: 自身 | K38: Ⅲ阶：进入雷鸣；已有雷鸣时获得3弹药，已有极限时获得6弹药。 | L38: 用户完整文本

Sheet Boss参数
A1: Boss参数｜太阳的宠臣
A3: 敌人 | B3: 灵感 | C3: 现实防御 | D3: 精神防御 | E3: 抗暴率 | F3: 暴击防御 | G3: 受创减免 | H3: 受到伤害提升 | I3: 燃烧上限
A4: 太阳的宠臣 | B4: 岩 | C4: 1200 | D4: 1000 | E4: 0 | F4: 0.4 | G4: 0.4 | H4: 0 | I4: 30
A7: 机制参数 | B7: 数值 | C7: 用途 | D7: 来源/说明
A8: 基础克制伤害加成 | B8: 0.3 | C8: 星→岩等基础克制 | D8: 游戏通用机制
A9: 攻防项最低攻击比例 | B9: 0.1 | C9: MAX(攻击×10%, 攻击-防御) | D9: 伤害公式参数
A10: 创伤乘区最低值 | B10: 0.3 | C10: MAX(30%,1+加成-减免) | D10: 伤害公式参数
A11: 归谬降低普通受创减免 | B11: 0.4 | C11: 弱点洞穿期间敌方普通受创减免降低40% | D11: 用户提供归谬完整效果
A12: 昨日雨声轻A5-主动咒语伤害 | B12: 0.02 | C12: 全队，最多6层，3回合 | D12: https://wiki.biligame.com/reverse1999/昨日雨声轻
A13: 昨日雨声轻A5-仪式暴创 | B13: 0.16 | C13: 全队，3回合 | D13: https://wiki.biligame.com/reverse1999/昨日雨声轻
A14: 灵知当齐一A1-洞知创伤 | B14: 0.04 | C14: 37额外行动后全队，最多4层，3回合 | D14: https://res1999.huijiwiki.com/wiki/37
A15: 立于风暴脊A5-洞知创伤 | B15: 0.06 | C15: 任意己方洞知攻击后红弩箭叠加；退出洞穿清空 | D15: https://www.taptap.cn/moment/852436614087970804
A16: 家庭指导员A1-反击后仪式威力 | B16: 0.04 | C16: J，最多3层 | D16: https://wiki.biligame.com/reverse1999/家庭指导员
A17: 家庭指导员A1-每激情暴创 | B17: 0.004 | C17: 全队，最多30层 | D17: https://wiki.biligame.com/reverse1999/家庭指导员
A18: J每层燃烧攻击提升 | B18: 0.01 | C18: 0塑狂想I：原0.5%提升100%，每层1%攻击 | D18: https://www.taptap.cn/moment/816407892969128552
A19: 小瑞安侬每层灵犀克制加成 | B19: 0.04 | C19: 上限5层 | D19: https://res1999.huijiwiki.com/wiki/小瑞安侬
... A33: 本源是否吃术法威力 | B33: 0 | C33: 0=保留独立本源倍率；1=本源也应用BO威力乘区 | D33: 待确认
A35: 参数依据 | B35: 现实1200、精神1000、基础暴防40%、基础受减40%已由用户确认；每回合5%在阶段表另算。
A39: J反击每层额外倍率 | B39: 0.05 | C39: 高温回火300%基础＋攻击前自身燃烧×5%；按用户当前卡面文字 | D39: 用户再次确认当前300%＋每层燃烧5%
A40: J回合开始每层反击创伤 | B40: 0.01 | C40: 仅回合开始燃烧≥Boss参数B59时授予，每层1%，持续本回合 | D40: 用户洞悉III完整文字
A41: J仪式每层团队伤害 | B41: 0.025 | C41: 攻击后按自身燃烧，持续3回合 | D41: 狂想III；公开游戏截图
A42: 启迪本源创伤提升 | B42: 1 | C42: 咒语附加的本源伤害提高100%，生效后减少1层；与仰望在本源增减区相加 | D42: https://bbs.4399.cn/thread-view-tid-44096347
A43: J反击享受群鸟之歌术法 | B43: 1 | C43: 默认1：反击既读取术法威力，就同时读取群鸟+30%、全员−40%、仰望减益；0仅用于比较 | D43: 用户群鸟完整文字无反击排除；撤销旧按接近实测而排除的假设
A44: J反击创伤与术法威力同区 | B44: 0 | C44: J回合开始获得的反击创伤加成进入创伤加成区，威力区不再重复计入 | D44: 用户确认；第4～6回合12次反击试算吻合
A45: J仪式每层溢出倍率 | B45: 1 | C45: 每溢出1层燃烧额外100%现实创伤 | D45: 文本50%；三次独立测试和两次原表记录支持有效100%，怀疑bug或文本显示错误
A46: 群鸟之歌术法/仪式威力 | B46: 0.3 | C46: 术法威力+30%，仪式威力+30% | D46: 用户确认
A47: 尘酿鹰攻击比例 | B47: 0.08 | C47: 施放时的小瑞有效攻击×8%；本段实测支持施放时快照 | D47: 用户确认比例；快照由实测支持
A48: 尘酿鹰攻击上限 | B48: 250 | C48: 最多250；再次仪式时刷新快照 | D48: 用户确认
A49: 尘酿鹰最大生命比例 | B49: 0.08 | C49: 获得小瑞最大生命×8%，最多1250；不参与伤害计算 | D49: 用户确认
A50: 尘酿鹰最大生命上限 | B50: 1250 | C50: 本表生命比例仍使用实战记录输入 | D50: 用户确认
... A77: 合计伤害上限启用 | B77: 0 | C77: 0=不限制主伤＋本源合计；本次按用户指定关闭合计300万封顶 | D77: 用户暂定合计；末次3877552与口径冲突
A78: 门槛结算时点 | B78: 下一次行动 | C78: 同一行动所有分段均使用攻击前档位 | D78: 用户暂定口径
A79: J狂想固定反击创伤加成 | B79: 0.1 | C79: J本人的高温回火、硬度测试在普通创伤区加10%；不作用于仪式或其他角色 | D79: 用户找到狂想来源并确认10%
A80: 红弩箭计算暴击创伤 | B80: 2.025 | C80: 面板显示202.6%；按技巧贡献向下取整，实际计算使用202.5% | D80: 用户指定计算口径
A81: J计算暴击创伤 | B81: 1.717 | C81: 面板显示171.8%；实际计算使用171.7%；37和小瑞保持原值 | D81: 用户指定计算口径
A82: 红普通洞知技能暴创 | B82: 0.6 | C82: 攻击时额外增加60个百分点暴击创伤，加入BA | D82: 用户完整技能文字；开局实测验证
A83: 红强化洞知技能暴创 | B83: 0.8 | C83: 自身每第三次洞知攻击增加80个百分点暴创 | D83: 用户完整技能文字；开局实测验证
A84: 红终结技能暴创 | B84: 1 | C84: 洞知终结额外增加100个百分点暴创 | D84: 用户完整技能文字；开局实测验证
A87: 雨声单层持续回合数 | B87: 3 | C87: 产生于计时回合t，t/t+1/t+2有效；t+3进入前移除 | D87: 心相完整文字：每层持续3回合
A89: 保守主义额外行动暴击率降低 | B89: 0.5 | C89: 减少50个百分点，只影响额外行动的暴击率 | D89: 用户第5回合Boss仪式备注
...

Sheet 行动模拟
A1: 洞知队伤害模拟器｜连续行动录入
A2: 黄色 B:I 为录入区；绿色 J:U 自动计算。原记录到第57行结束，后续从第58行连续追加；不要留空行。
A8: 事件 | B8: 阶段 | C8: 阶段内顺序 | D8: 技能选择（含阶次） | E8: 是否暴击 | F8: 实测主伤 | G8: 实测直接本源 | H8: 实测稳态附加 | I8: 备注 | J8: 角色 | K8: 有效攻击 | L8: 有效暴击率 | M8: 己方暴击创伤 | N8: 有效倍率 | O8: 预测不暴击合计 | P8: 预测暴击合计 | Q8: 对应预测 | R8: 实测合计 | S8: 预测－实测 | T8: 关键状态 | U8: 检查提示
A9: =IF(D9="","",ROW()-8) -> 1 | B9: 1 | C9: 1 | D9: 小瑞安侬｜悄冥冥术阵 | E9: — | J9: =IF(D9="","",后台计算!E3) -> 小瑞安侬 | K9: =IF(D9="","",后台计算!AY3) -> 2986 | L9: =IF(D9="","",后台计算!AZ3) -> 0.555 | M9: =IF(D9="","",后台计算!BA3) -> 1.55 | N9: =IF(D9="","",后台计算!BG3) -> 0 | O9: =IF(D9="","",后台计算!BU3) -> 0 | P9: =IF(D9="","",后台计算!BV3) -> 0 | Q9: =IF(D9="","",IF(E9="是",P9,IF(E9="否",O9,""))) | R9: =IF(COUNT(F9:H9)=0,"",SUM(F9:H9)) | S9: =IF(AND(ISNUMBER(Q9),ISNUMBER(R9)),Q9-R9,"") | T9: =IF(D9="","","红:"&IF(后台计算!U3=0,"无",IF(后台计算!U3=1,"雷鸣","极限"))&" 增压"&TEXT(后台计算!W3,"0")&" 弹药"&TEXT(后台计算!X3,"0")&"｜37灵光"&TEXT(后台计算!AB3,"0")&" 启迪"&TEXT(后台计算!AC3,"0")&"｜灵犀"&TEXT(后台计算!AV3,"0")&"｜J燃烧"&TEXT(后台计算!AD3,"0")&" 敌燃烧"&TEXT(后台计算!AE3,"0")) -> 红:无 增压0 弹药0｜37灵光0 启迪0｜灵犀3｜J燃烧0 敌燃烧0 | U9: =IF(D9="","",后台计算!BX3)
A10: =IF(D10="","",ROW()-8) -> 2 | B10: 1 | C10: 2 | D10: J｜热处理 | E10: — | J10: =IF(D10="","",后台计算!E4) -> J | K10: =IF(D10="","",后台计算!AY4) -> 1906 | L10: =IF(D10="","",后台计算!AZ4) -> 0.667 | M10: =IF(D10="","",后台计算!BA4) -> 1.717 | N10: =IF(D10="","",后台计算!BG4) -> 0 | O10: =IF(D10="","",后台计算!BU4) -> 0 | P10: =IF(D10="","",后台计算!BV4) -> 0 | Q10: =IF(D10="","",IF(E10="是",P10,IF(E10="否",O10,""))) | R10: =IF(COUNT(F10:H10)=0,"",SUM(F10:H10)) | S10: =IF(AND(ISNUMBER(Q10),ISNUMBER(R10)),Q10-R10,"") | T10: =IF(D10="","","红:"&IF(后台计算!U4=0,"无",IF(后台计算!U4=1,"雷鸣","极限"))&" 增压"&TEXT(后台计算!W4,"0")&" 弹药"&TEXT(后台计算!X4,"0")&"｜37灵光"&TEXT(后台计算!AB4,"0")&" 启迪"&TEXT(后台计算!AC4,"0")&"｜灵犀"&TEXT(后台计算!AV4,"0")&"｜J燃烧"&TEXT(后台计算!AD4,"0")&" 敌燃烧"&TEXT(后台计算!AE4,"0")) -> 红:无 增压0 弹药0｜37灵光1 启迪0｜灵犀3｜J燃烧0 敌燃烧0 | U10: =IF(D10="","",后台计算!BX4)
A11: =IF(D11="","",ROW()-8) -> 3 | B11: 1 | C11: 3 | D11: 红弩箭｜眼镜蛇机动 | E11: — | J11: =IF(D11="","",后台计算!E5) -> 红弩箭 | K11: =IF(D11="","",后台计算!AY5) -> 2755 | L11: =IF(D11="","",后台计算!AZ5) -> 1 | M11: =IF(D11="","",后台计算!BA5) -> 2.025 | N11: =IF(D11="","",后台计算!BG5) -> 0 | O11: =IF(D11="","",后台计算!BU5) -> 0 | P11: =IF(D11="","",后台计算!BV5) -> 0 | Q11: =IF(D11="","",IF(E11="是",P11,IF(E11="否",O11,""))) | R11: =IF(COUNT(F11:H11)=0,"",SUM(F11:H11)) | S11: =IF(AND(ISNUMBER(Q11),ISNUMBER(R11)),Q11-R11,"") | T11: =IF(D11="","","红:"&IF(后台计算!U5=0,"无",IF(后台计算!U5=1,"雷鸣","极限"))&" 增压"&TEXT(后台计算!W5,"0")&" 弹药"&TEXT(后台计算!X5,"0")&"｜37灵光"&TEXT(后台计算!AB5,"0")&" 启迪"&TEXT(后台计算!AC5,"0")&"｜灵犀"&TEXT(后台计算!AV5,"0")&"｜J燃烧"&TEXT(后台计算!AD5,"0")&" 敌燃烧"&TEXT(后台计算!AE5,"0")) -> 红:无 增压0 弹药0｜37灵光2 启迪0｜灵犀3｜J燃烧0 敌燃烧0 | U11: =IF(D11="","",后台计算!BX5)
A12: =IF(D12="","",ROW()-8) -> 4 | B12: 1 | C12: 4 | D12: 红弩箭｜极限俯冲Ⅰ | E12: 是 | F12: 73241 | G12: 0 | J12: =IF(D12="","",后台计算!E6) -> 红弩箭 | K12: =IF(D12="","",后台计算!AY6) -> 2755 | L12: =IF(D12="","",后台计算!AZ6) -> 1 | M12: =IF(D12="","",后台计算!BA6) -> 2.025 | N12: =IF(D12="","",后台计算!BG6) -> 9 | O12: =IF(D12="","",后台计算!BU6) -> 45071 | P12: =IF(D12="","",后台计算!BV6) -> 73241 | Q12: =IF(D12="","",IF(E12="是",P12,IF(E12="否",O12,""))) -> 73241 | R12: =IF(COUNT(F12:H12)=0,"",SUM(F12:H12)) -> 73241 | S12: =IF(AND(ISNUMBER(Q12),ISNUMBER(R12)),Q12-R12,"") -> 0 | T12: =IF(D12="","","红:"&IF(后台计算!U6=0,"无",IF(后台计算!U6=1,"雷鸣","极限"))&" 增压"&TEXT(后台计算!W6,"0")&" 弹药"&TEXT(后台计算!X6,"0")&"｜37灵光"&TEXT(后台计算!AB6,"0")&" 启迪"&TEXT(后台计算!AC6,"0")&"｜灵犀"&TEXT(后台计算!AV6,"0")&"｜J燃烧"&TEXT(后台计算!AD6,"0")&" 敌燃烧"&TEXT(后台计算!AE6,"0")) -> 红:雷鸣 增压5 弹药6｜37灵光3 启迪0｜灵犀3｜J燃烧0 敌燃烧0 | U12: =IF(D12="","",后台计算!BX6)
A13: =IF(D13="","",ROW()-8) -> 5 | B13: 1 | C13: 5 | D13: J｜高温回火 | E13: 否 | F13: 1231 | G13: 0 | I13: 回合末默契消耗按库存自动计算；发生于首次Boss反击前的时点由本场验证。 | J13: =IF(D13="","",后台计算!E7) -> J | K13: =IF(D13="","",后台计算!AY7) -> 1906 | L13: =IF(D13="","",后台计算!AZ7) -> 0.667 | M13: =IF(D13="","",后台计算!BA7) -> 1.717 | N13: =IF(D13="","",后台计算!BG7) -> 3 | O13: =IF(D13="","",后台计算!BU7) -> 1231 | P13: =IF(D13="","",后台计算!BV7) -> 1354 | Q13: =IF(D13="","",IF(E13="是",P13,IF(E13="否",O13,""))) -> 1231 | R13: =IF(COUNT(F13:H13)=0,"",SUM(F13:H13)) -> 1231 | S13: =IF(AND(ISNUMBER(Q13),ISNUMBER(R13)),Q13-R13,"") -> 0 | T13: =IF(D13="","","红:"&IF(后台计算!U7=0,"无",IF(后台计算!U7=1,"雷鸣","极限"))&" 增压"&TEXT(后台计算!W7,"0")&" 弹药"&TEXT(后台计算!X7,"0")&"｜37灵光"&TEXT(后台计算!AB7,"0")&" 启迪"&TEXT(后台计算!AC7,"0")&"｜灵犀"&TEXT(后台计算!AV7,"0")&"｜J燃烧"&TEXT(后台计算!AD7,"0")&" 敌燃烧"&TEXT(后台计算!AE7,"0")) -> 红:雷鸣 增压7 弹药6｜37灵光4 启迪0｜灵犀5｜J燃烧0 敌燃烧0 | U13: =IF(D13="","",后台计算!BX7)
A14: =IF(D14="","",ROW()-8) -> 6 | B14: 1 | C14: 6 | D14: 37｜补充算式 | E14: 是 | F14: 4932 | G14: 3482 | J14: =IF(D14="","",后台计算!E8) -> 37 | K14: =IF(D14="","",后台计算!AY8) -> 2767 | L14: =IF(D14="","",后台计算!AZ8) -> 0.76 | M14: =IF(D14="","",后台计算!BA8) -> 2.198 | N14: =IF(D14="","",后台计算!BG8) -> 3 | O14: =IF(D14="","",后台计算!BU8) -> 4679 | P14: =IF(D14="","",后台计算!BV8) -> 8414 | Q14: =IF(D14="","",IF(E14="是",P14,IF(E14="否",O14,""))) -> 8414 | R14: =IF(COUNT(F14:H14)=0,"",SUM(F14:H14)) -> 8414 | S14: =IF(AND(ISNUMBER(Q14),ISNUMBER(R14)),Q14-R14,"") -> 0 | T14: =IF(D14="","","红:"&IF(后台计算!U8=0,"无",IF(后台计算!U8=1,"雷鸣","极限"))&" 增压"&TEXT(后台计算!W8,"0")&" 弹药"&TEXT(后台计算!X8,"0")&"｜37灵光"&TEXT(后台计算!AB8,"0")&" 启迪"&TEXT(后台计算!AC8,"0")&"｜灵犀"&TEXT(后台计算!AV8,"0")&"｜J燃烧"&TEXT(后台计算!AD8,"0")&" 敌燃烧"&TEXT(后台计算!AE8,"0")) -> 红:雷鸣 增压10 弹药6｜37灵光5 启迪0｜灵犀5｜J燃烧2 敌燃烧2 | U14: =IF(D14="","",后台计算!BX8)
A15: =IF(D15="","",ROW()-8) -> 7 | B15: 1 | C15: 7 | D15: J｜高温回火 | E15: 是 | F15: 1474 | G15: 0 | J15: =IF(D15="","",后台计算!E9) -> J | K15: =IF(D15="","",后台计算!AY9) -> 1944 | L15: =IF(D15="","",后台计算!AZ9) -> 0.667 | M15: =IF(D15="","",后台计算!BA9) -> 1.717 | N15: =IF(D15="","",后台计算!BG9) -> 3.1 | O15: =IF(D15="","",后台计算!BU9) -> 1340 | P15: =IF(D15="","",后台计算!BV9) -> 1474 | Q15: =IF(D15="","",IF(E15="是",P15,IF(E15="否",O15,""))) -> 1474 | R15: =IF(COUNT(F15:H15)=0,"",SUM(F15:H15)) -> 1474 | S15: =IF(AND(ISNUMBER(Q15),ISNUMBER(R15)),Q15-R15,"") -> 0 | T15: =IF(D15="","","红:"&IF(后台计算!U9=0,"无",IF(后台计算!U9=1,"雷鸣","极限"))&" 增压"&TEXT(后台计算!W9,"0")&" 弹药"&TEXT(后台计算!X9,"0")&"｜37灵光"&TEXT(后台计算!AB9,"0")&" 启迪"&TEXT(后台计算!AC9,"0")&"｜灵犀"&TEXT(后台计算!AV9,"0")&"｜J燃烧"&TEXT(后台计算!AD9,"0")&" 敌燃烧"&TEXT(后台计算!AE9,"0")) -> 红:雷鸣 增压10 弹药6｜37灵光0 启迪0｜灵犀5｜J燃烧2 敌燃烧2 | U15: =IF(D15="","",后台计算!BX9)
A16: =IF(D16="","",ROW()-8) -> 8 | B16: 1 | C16: 8 | D16: J｜高温回火 | E16: 否 | F16: 1745 | G16: 0 | J16: =IF(D16="","",后台计算!E10) -> J | K16: =IF(D16="","",后台计算!AY10) -> 1982 | L16: =IF(D16="","",后台计算!AZ10) -> 0.667 | M16: =IF(D16="","",后台计算!BA10) -> 1.717 | N16: =IF(D16="","",后台计算!BG10) -> 3.2 | O16: =IF(D16="","",后台计算!BU10) -> 1745 | P16: =IF(D16="","",后台计算!BV10) -> 1919 | Q16: =IF(D16="","",IF(E16="是",P16,IF(E16="否",O16,""))) -> 1745 | R16: =IF(COUNT(F16:H16)=0,"",SUM(F16:H16)) -> 1745 | S16: =IF(AND(ISNUMBER(Q16),ISNUMBER(R16)),Q16-R16,"") -> 0 | T16: =IF(D16="","","红:"&IF(后台计算!U10=0,"无",IF(后台计算!U10=1,"雷鸣","极限"))&" 增压"&TEXT(后台计算!W10,"0")&" 弹药"&TEXT(后台计算!X10,"0")&"｜37灵光"&TEXT(后台计算!AB10,"0")&" 启迪"&TEXT(后台计算!AC10,"0")&"｜灵犀"&TEXT(后台计算!AV10,"0")&"｜J燃烧"&TEXT(后台计算!AD10,"0")&" 敌燃烧"&TEXT(后台计算!AE10,"0")) -> 红:雷鸣 增压10 弹药6｜37灵光1 启迪0｜灵犀5｜J燃烧4 敌燃烧4 | U16: =IF(D16="","",后台计算!BX10)
A17: =IF(D17="","",ROW()-8) -> 9 | B17: 1 | C17: 9 | D17: J｜高温回火 | E17: 是 | F17: 2076 | G17: 0 | J17: =IF(D17="","",后台计算!E11) -> J | K17: =IF(D17="","",后台计算!AY11) -> 2020 | L17: =IF(D17="","",后台计算!AZ11) -> 0.667 | M17: =IF(D17="","",后台计算!BA11) -> 1.717 | N17: =IF(D17="","",后台计算!BG11) -> 3.3 | O17: =IF(D17="","",后台计算!BU11) -> 1887 | P17: =IF(D17="","",后台计算!BV11) -> 2076 | Q17: =IF(D17="","",IF(E17="是",P17,IF(E17="否",O17,""))) -> 2076 | R17: =IF(COUNT(F17:H17)=0,"",SUM(F17:H17)) -> 2076 | S17: =IF(AND(ISNUMBER(Q17),ISNUMBER(R17)),Q17-R17,"") -> 0 | T17: =IF(D17="","","红:"&IF(后台计算!U11=0,"无",IF(后台计算!U11=1,"雷鸣","极限"))&" 增压"&TEXT(后台计算!W11,"0")&" 弹药"&TEXT(后台计算!X11,"0")&"｜37灵光"&TEXT(后台计算!AB11,"0")&" 启迪"&TEXT(后台计算!AC11,"0")&"｜灵犀"&TEXT(后台计算!AV11,"0")&"｜J燃烧"&TEXT(后台计算!AD11,"0")&" 敌燃烧"&TEXT(后台计算!AE11,"0")) -> 红:雷鸣 增压10 弹药6｜37灵光2 启迪0｜灵犀5｜J燃烧6 敌燃烧6 | U17: =IF(D17="","",后台计算!BX11)
A18: =IF(D18="","",ROW()-8) -> 10 | B18: 2 | C18: 1 | D18: 小瑞安侬｜唱予无忧之诗 | E18: — | J18: =IF(D18="","",后台计算!E12) -> 小瑞安侬 | K18: =IF(D18="","",后台计算!AY12) -> 2986 | L18: =IF(D18="","",后台计算!AZ12) -> 0.555 | M18: =IF(D18="","",后台计算!BA12) -> 1.55 | N18: =IF(D18="","",后台计算!BG12) -> 0 | O18: =IF(D18="","",后台计算!BU12) -> 0 | P18: =IF(D18="","",后台计算!BV12) -> 0 | Q18: =IF(D18="","",IF(E18="是",P18,IF(E18="否",O18,""))) | R18: =IF(COUNT(F18:H18)=0,"",SUM(F18:H18)) | S18: =IF(AND(ISNUMBER(Q18),ISNUMBER(R18)),Q18-R18,"") | T18: =IF(D18="","","红:"&IF(后台计算!U12=0,"无",IF(后台计算!U12=1,"雷鸣","极限"))&" 增压"&TEXT(后台计算!W12,"0")&" 弹药"&TEXT(后台计算!X12,"0")&"｜37灵光"&TEXT(后台计算!AB12,"0")&" 启迪"&TEXT(后台计算!AC12,"0")&"｜灵犀"&TEXT(后台计算!AV12,"0")&"｜J燃烧"&TEXT(后台计算!AD12,"0")&" 敌燃烧"&TEXT(后台计算!AE12,"0")) -> 红:极限 增压10 弹药6｜37灵光3 启迪0｜灵犀5｜J燃烧8 敌燃烧4 | U18: =IF(D18="","",后台计算!BX12)
A19: =IF(D19="","",ROW()-8) -> 11 | B19: 2 | C19: 2 | D19: J｜热处理 | E19: — | J19: =IF(D19="","",后台计算!E13) -> J | K19: =IF(D19="","",后台计算!AY13) -> 2296 | L19: =IF(D19="","",后台计算!AZ13) -> 0.667 | M19: =IF(D19="","",后台计算!BA13) -> 1.897 | N19: =IF(D19="","",后台计算!BG13) -> 0 | O19: =IF(D19="","",后台计算!BU13) -> 0 | P19: =IF(D19="","",后台计算!BV13) -> 0 | Q19: =IF(D19="","",IF(E19="是",P19,IF(E19="否",O19,""))) | R19: =IF(COUNT(F19:H19)=0,"",SUM(F19:H19)) | S19: =IF(AND(ISNUMBER(Q19),ISNUMBER(R19)),Q19-R19,"") | T19: =IF(D19="","","红:"&IF(后台计算!U13=0,"无",IF(后台计算!U13=1,"雷鸣","极限"))&" 增压"&TEXT(后台计算!W13,"0")&" 弹药"&TEXT(后台计算!X13,"0")&"｜37灵光"&TEXT(后台计算!AB13,"0")&" 启迪"&TEXT(后台计算!AC13,"0")&"｜灵犀"&TEXT(后台计算!AV13,"0")&"｜J燃烧"&TEXT(后台计算!AD13,"0")&" 敌燃烧"&TEXT(后台计算!AE13,"0")) -> 红:极限 增压10 弹药6｜37灵光4 启迪0｜灵犀5｜J燃烧8 敌燃烧4 | U19: =IF(D19="","",后台计算!BX13)
A20: =IF(D20="","",ROW()-8) -> 12 | B20: 2 | C20: 3 | D20: 37｜补充算式 | E20: 是 | F20: 6371 | G20: 4160 | J20: =IF(D20="","",后台计算!E14) -> 37 | K20: =IF(D20="","",后台计算!AY14) -> 3005 | L20: =IF(D20="","",后台计算!AZ14) -> 0.76 | M20: =IF(D20="","",后台计算!BA14) -> 2.378 | N20: =IF(D20="","",后台计算!BG14) -> 3 | O20: =IF(D20="","",后台计算!BU14) -> 5324 | P20: =IF(D20="","",后台计算!BV14) -> 10531 | Q20: =IF(D20="","",IF(E20="是",P20,IF(E20="否",O20,""))) -> 10531 | R20: =IF(COUNT(F20:H20)=0,"",SUM(F20:H20)) -> 10531 | S20: =IF(AND(ISNUMBER(Q20),ISNUMBER(R20)),Q20-R20,"") -> 0 | T20: =IF(D20="","","红:"&IF(后台计算!U14=0,"无",IF(后台计算!U14=1,"雷鸣","极限"))&" 增压"&TEXT(后台计算!W14,"0")&" 弹药"&TEXT(后台计算!X14,"0")&"｜37灵光"&TEXT(后台计算!AB14,"0")&" 启迪"&TEXT(后台计算!AC14,"0")&"｜灵犀"&TEXT(后台计算!AV14,"0")&"｜J燃烧"&TEXT(后台计算!AD14,"0")&" 敌燃烧"&TEXT(后台计算!AE14,"0")) -> 红:极限 增压10 弹药6｜37灵光5 启迪0｜灵犀5｜J燃烧8 敌燃烧4 | U20: =IF(D20="","",后台计算!BX14)
A21: =IF(D21="","",ROW()-8) -> 13 | B21: 2 | C21: 4 | D21: 37｜曲线映射Ⅰ | E21: 否 | F21: 1878 | G21: 2043 | J21: =IF(D21="","",后台计算!E15) -> 37 | K21: =IF(D21="","",后台计算!AY15) -> 3005 | L21: =IF(D21="","",后台计算!AZ15) -> 0.76 | M21: =IF(D21="","",后台计算!BA15) -> 2.378 | N21: =IF(D21="","",后台计算!BG15) -> 1.4 | O21: =IF(D21="","",后台计算!BU15) -> 3921 | P21: =IF(D21="","",后台计算!BV15) -> 7757 | Q21: =IF(D21="","",IF(E21="是",P21,IF(E21="否",O21,""))) -> 3921 | R21: =IF(COUNT(F21:H21)=0,"",SUM(F21:H21)) -> 3921 | S21: =IF(AND(ISNUMBER(Q21),ISNUMBER(R21)),Q21-R21,"") -> 0 | T21: =IF(D21="","","红:"&IF(后台计算!U15=0,"无",IF(后台计算!U15=1,"雷鸣","极限"))&" 增压"&TEXT(后台计算!W15,"0")&" 弹药"&TEXT(后台计算!X15,"0")&"｜37灵光"&TEXT(后台计算!AB15,"0")&" 启迪"&TEXT(后台计算!AC15,"0")&"｜灵犀"&TEXT(后台计算!AV15,"0")&"｜J燃烧"&TEXT(后台计算!AD15,"0")&" 敌燃烧"&TEXT(后台计算!AE15,"0")) -> 红:极限 增压10 弹药6｜37灵光0 启迪0｜灵犀5｜J燃烧8 敌燃烧4 | U21: =IF(D21="","",后台计算!BX15)
A22: =IF(D22="","",ROW()-8) -> 14 | B22: 2 | C22: 5 | D22: 37｜三角正论Ⅰ | E22: 是 | F22: 8919 | G22: 4755 | J22: =IF(D22="","",后台计算!E16) -> 37 | K22: =IF(D22="","",后台计算!AY16) -> 3005 | L22: =IF(D22="","",后台计算!AZ16) -> 0.76 | M22: =IF(D22="","",后台计算!BA16) -> 2.378 | N22: =IF(D22="","",后台计算!BG16) -> 2.8 | O22: =IF(D22="","",后台计算!BU16) -> 6913 | P22: =IF(D22="","",后台计算!BV16) -> 13674 | Q22: =IF(D22="","",IF(E22="是",P22,IF(E22="否",O22,""))) -> 13674 | R22: =IF(COUNT(F22:H22)=0,"",SUM(F22:H22)) -> 13674 | S22: =IF(AND(ISNUMBER(Q22),ISNUMBER(R22)),Q22-R22,"") -> 0 | T22: =IF(D22="","","红:"&IF(后台计算!U16=0,"无",IF(后台计算!U16=1,"雷鸣","极限"))&" 增压"&TEXT(后台计算!W16,"0")&" 弹药"&TEXT(后台计算!X16,"0")&"｜37灵光"&TEXT(后台计算!AB16,"0")&" 启迪"&TEXT(后台计算!AC16,"0")&"｜灵犀"&TEXT(后台计算!AV16,"0")&"｜J燃烧"&TEXT(后台计算!AD16,"0")&" 敌燃烧"&TEXT(后台计算!AE16,"0")) -> 红:极限 增压10 弹药6｜37灵光1 启迪0｜灵犀5｜J燃烧8 敌燃烧4 | U22: =IF(D22="","",后台计算!BX16)
A23: =IF(D23="","",ROW()-8) -> 15 | B23: 2 | C23: 6 | D23: J｜高温回火 | E23: 是 | F23: 2290 | G23: 0 | I23: 回合末默契消耗按库存自动计算；发生于首次Boss反击前的时点由本场验证。 | J23: =IF(D23="","",后台计算!E17) -> J | K23: =IF(D23="","",后台计算!AY17) -> 2296 | L23: =IF(D23="","",后台计算!AZ17) -> 0.667 | M23: =IF(D23="","",后台计算!BA17) -> 1.897 | N23: =IF(D23="","",后台计算!BG17) -> 3.4 | O23: =IF(D23="","",后台计算!BU17) -> 2082 | P23: =IF(D23="","",后台计算!BV17) -> 2290 | Q23: =IF(D23="","",IF(E23="是",P23,IF(E23="否",O23,""))) -> 2290 | R23: =IF(COUNT(F23:H23)=0,"",SUM(F23:H23)) -> 2290 | S23: =IF(AND(ISNUMBER(Q23),ISNUMBER(R23)),Q23-R23,"") -> 0 | T23: =IF(D23="","","红:"&IF(后台计算!U17=0,"无",IF(后台计算!U17=1,"雷鸣","极限"))&" 增压"&TEXT(后台计算!W17,"0")&" 弹药"&TEXT(后台计算!X17,"0")&"｜37灵光"&TEXT(后台计算!AB17,"0")&" 启迪"&TEXT(后台计算!AC17,"0")&"｜灵犀"&TEXT(后台计算!AV17,"0")&"｜J燃烧"&TEXT(后台计算!AD17,"0")&" 敌燃烧"&TEXT(后台计算!AE17,"0")) -> 红:极限 增压10 弹药6｜37灵光2 启迪1｜灵犀5｜J燃烧8 敌燃烧4 | U23: =IF(D23="","",后台计算!BX17)
A24: =IF(D24="","",ROW()-8) -> 16 | B24: 2 | C24: 7 | D24: J｜高温回火 | E24: 否 | F24: 2661 | G24: 0 | J24: =IF(D24="","",后台计算!E18) -> J | K24: =IF(D24="","",后台计算!AY18) -> 2334 | L24: =IF(D24="","",后台计算!AZ18) -> 0.667 | M24: =IF(D24="","",后台计算!BA18) -> 1.897 | N24: =IF(D24="","",后台计算!BG18) -> 3.5 | O24: =IF(D24="","",后台计算!BU18) -> 2661 | P24: =IF(D24="","",后台计算!BV18) -> 2927 | Q24: =IF(D24="","",IF(E24="是",P24,IF(E24="否",O24,""))) -> 2661 | R24: =IF(COUNT(F24:H24)=0,"",SUM(F24:H24)) -> 2661 | S24: =IF(AND(ISNUMBER(Q24),ISNUMBER(R24)),Q24-R24,"") -> 0 | T24: =IF(D24="","","红:"&IF(后台计算!U18=0,"无",IF(后台计算!U18=1,"雷鸣","极限"))&" 增压"&TEXT(后台计算!W18,"0")&" 弹药"&TEXT(后台计算!X18,"0")&"｜37灵光"&TEXT(后台计算!AB18,"0")&" 启迪"&TEXT(后台计算!AC18,"0")&"｜灵犀"&TEXT(后台计算!AV18,"0")&"｜J燃烧"&TEXT(后台计算!AD18,"0")&" 敌燃烧"&TEXT(后台计算!AE18,"0")) -> 红:极限 增压10 弹药6｜37灵光3 启迪1｜灵犀5｜J燃烧10 敌燃烧6 | U24: =IF(D24="","",后台计算!BX18)
A25: =IF(D25="","",ROW()-8) -> 17 | B25: 2 | C25: 8 | D25: J｜高温回火 | E25: 是 | F25: 3111 | G25: 0 | J25: =IF(D25="","",后台计算!E19) -> J | K25: =IF(D25="","",后台计算!AY19) -> 2372 | L25: =IF(D25="","",后台计算!AZ19) -> 0.667 | M25: =IF(D25="","",后台计算!BA19) -> 1.897 | N25: =IF(D25="","",后台计算!BG19) -> 3.6 | O25: =IF(D25="","",后台计算!BU19) -> 2828 | P25: =IF(D25="","",后台计算!BV19) -> 3111 | Q25: =IF(D25="","",IF(E25="是",P25,IF(E25="否",O25,""))) -> 3111 | R25: =IF(COUNT(F25:H25)=0,"",SUM(F25:H25)) -> 3111 | S25: =IF(AND(ISNUMBER(Q25),ISNUMBER(R25)),Q25-R25,"") -> 0 | T25: =IF(D25="","","红:"&IF(后台计算!U19=0,"无",IF(后台计算!U19=1,"雷鸣","极限"))&" 增压"&TEXT(后台计算!W19,"0")&" 弹药"&TEXT(后台计算!X19,"0")&"｜37灵光"&TEXT(后台计算!AB19,"0")&" 启迪"&TEXT(后台计算!AC19,"0")&"｜灵犀"&TEXT(后台计算!AV19,"0")&"｜J燃烧"&TEXT(后台计算!AD19,"0")&" 敌燃烧"&TEXT(后台计算!AE19,"0")) -> 红:极限 增压10 弹药6｜37灵光4 启迪1｜灵犀5｜J燃烧12 敌燃烧8 | U25: =IF(D25="","",后台计算!BX19)
A26: =IF(D26="","",ROW()-8) -> 18 | B26: 2 | C26: 9 | D26: 37｜补充算式 | E26: 是 | F26: 5835 | G26: 10104 | J26: =IF(D26="","",后台计算!E20) -> 37 | K26: =IF(D26="","",后台计算!AY20) -> 3005 | L26: =IF(D26="","",后台计算!AZ20) -> 0.76 | M26: =IF(D26="","",后台计算!BA20) -> 2.378 | N26: =IF(D26="","",后台计算!BG20) -> 3 | O26: =IF(D26="","",后台计算!BU20) -> 8058 | P26: =IF(D26="","",后台计算!BV20) -> 15939 | Q26: =IF(D26="","",IF(E26="是",P26,IF(E26="否",O26,""))) -> 15939 | R26: =IF(COUNT(F26:H26)=0,"",SUM(F26:H26)) -> 15939 | S26: =IF(AND(ISNUMBER(Q26),ISNUMBER(R26)),Q26-R26,"") -> 0 | T26: =IF(D26="","","红:"&IF(后台计算!U20=0,"无",IF(后台计算!U20=1,"雷鸣","极限"))&" 增压"&TEXT(后台计算!W20,"0")&" 弹药"&TEXT(后台计算!X20,"0")&"｜37灵光"&TEXT(后台计算!AB20,"0")&" 启迪"&TEXT(后台计算!AC20,"0")&"｜灵犀"&TEXT(后台计算!AV20,"0")&"｜J燃烧"&TEXT(后台计算!AD20,"0")&" 敌燃烧"&TEXT(后台计算!AE20,"0")) -> 红:极限 增压10 弹药6｜37灵光5 启迪1｜灵犀5｜J燃烧14 敌燃烧10 | U26: =IF(D26="","",后台计算!BX20)
A27: =IF(D27="","",ROW()-8) -> 19 | B27: 2 | C27: 10 | D27: J｜高温回火 | E27: 否 | F27: 2501 | G27: 0 | J27: =IF(D27="","",后台计算!E21) -> J | K27: =IF(D27="","",后台计算!AY21) -> 2410 | L27: =IF(D27="","",后台计算!AZ21) -> 0.667 | M27: =IF(D27="","",后台计算!BA21) -> 1.897 | N27: =IF(D27="","",后台计算!BG21) -> 3.7 | O27: =IF(D27="","",后台计算!BU21) -> 2501 | P27: =IF(D27="","",后台计算!BV21) -> 2751 | Q27: =IF(D27="","",IF(E27="是",P27,IF(E27="否",O27,""))) -> 2501 | R27: =IF(COUNT(F27:H27)=0,"",SUM(F27:H27)) -> 2501 | S27: =IF(AND(ISNUMBER(Q27),ISNUMBER(R27)),Q27-R27,"") -> 0 | T27: =IF(D27="","","红:"&IF(后台计算!U21=0,"无",IF(后台计算!U21=1,"雷鸣","极限"))&" 增压"&TEXT(后台计算!W21,"0")&" 弹药"&TEXT(后台计算!X21,"0")&"｜37灵光"&TEXT(后台计算!AB21,"0")&" 启迪"&TEXT(后台计算!AC21,"0")&"｜灵犀"&TEXT(后台计算!AV21,"0")&"｜J燃烧"&TEXT(后台计算!AD21,"0")&" 敌燃烧"&TEXT(后台计算!AE21,"0")) -> 红:极限 增压10 弹药6｜37灵光0 启迪0｜灵犀5｜J燃烧14 敌燃烧10 | U27: =IF(D27="","",后台计算!BX21)
A28: =IF(D28="","",ROW()-8) -> 20 | B28: 3 | C28: 1 | D28: 小瑞安侬｜悄冥冥术阵 | E28: — | J28: =IF(D28="","",后台计算!E22) -> 小瑞安侬 | K28: =IF(D28="","",后台计算!AY22) -> 2986 | L28: =IF(D28="","",后台计算!AZ22) -> 0.555 | M28: =IF(D28="","",后台计算!BA22) -> 1.73 | N28: =IF(D28="","",后台计算!BG22) -> 0 | O28: =IF(D28="","",后台计算!BU22) -> 0 | P28: =IF(D28="","",后台计算!BV22) -> 0 | Q28: =IF(D28="","",IF(E28="是",P28,IF(E28="否",O28,""))) | R28: =IF(COUNT(F28:H28)=0,"",SUM(F28:H28)) | S28: =IF(AND(ISNUMBER(Q28),ISNUMBER(R28)),Q28-R28,"") | T28: =IF(D28="","","红:"&IF(后台计算!U22=0,"无",IF(后台计算!U22=1,"雷鸣","极限"))&" 增压"&TEXT(后台计算!W22,"0")&" 弹药"&TEXT(后台计算!X22,"0")&"｜37灵光"&TEXT(后台计算!AB22,"0")&" 启迪"&TEXT(后台计算!AC22,"0")&"｜灵犀"&TEXT(后台计算!AV22,"0")&"｜J燃烧"&TEXT(后台计算!AD22,"0")&" 敌燃烧"&TEXT(后台计算!AE22,"0")) -> 红:极限 增压10 弹药6｜37灵光1 启迪0｜灵犀5｜J燃烧16 敌燃烧6 | U28: =IF(D28="","",后台计算!BX22)
A29: =IF(D29="","",ROW()-8) -> 21 | B29: 3 | C29: 2 | D29: 37｜数与几何的王国 | E29: — | J29: =IF(D29="","",后台计算!E23) -> 37 | K29: =IF(D29="","",后台计算!AY23) -> 3005 | L29: =IF(D29="","",后台计算!AZ23) -> 0.76 | M29: =IF(D29="","",后台计算!BA23) -> 2.378 | N29: =IF(D29="","",后台计算!BG23) -> 0 | O29: =IF(D29="","",后台计算!BU23) -> 0 | P29: =IF(D29="","",后台计算!BV23) -> 0 | Q29: =IF(D29="","",IF(E29="是",P29,IF(E29="否",O29,""))) | R29: =IF(COUNT(F29:H29)=0,"",SUM(F29:H29)) | S29: =IF(AND(ISNUMBER(Q29),ISNUMBER(R29)),Q29-R29,"") | T29: =IF(D29="","","红:"&IF(后台计算!U23=0,"无",IF(后台计算!U23=1,"雷鸣","极限"))&" 增压"&TEXT(后台计算!W23,"0")&" 弹药"&TEXT(后台计算!X23,"0")&"｜37灵光"&TEXT(后台计算!AB23,"0")&" 启迪"&TEXT(后台计算!AC23,"0")&"｜灵犀"&TEXT(后台计算!AV23,"0")&"｜J燃烧"&TEXT(后台计算!AD23,"0")&" 敌燃烧"&TEXT(后台计算!AE23,"0")) -> 红:极限 增压10 弹药6｜37灵光2 启迪0｜灵犀5｜J燃烧16 敌燃烧6 | U29: =IF(D29="","",后台计算!BX23)
A30: =IF(D30="","",ROW()-8) -> 22 | B30: 3 | C30: 3 | D30: 37｜补充算式 | E30: 是 | F30: 11689 | G30: 11905 | J30: =IF(D30="","",后台计算!E24) -> 37 | K30: =IF(D30="","",后台计算!AY24) -> 3505 | L30: =IF(D30="","",后台计算!AZ24) -> 0.76 | M30: =IF(D30="","",后台计算!BA24) -> 2.398 | N30: =IF(D30="","",后台计算!BG24) -> 3 | O30: =IF(D30="","",后台计算!BU24) -> 11808 | P30: =IF(D30="","",后台计算!BV24) -> 23594 | Q30: =IF(D30="","",IF(E30="是",P30,IF(E30="否",O30,""))) -> 23594 | R30: =IF(COUNT(F30:H30)=0,"",SUM(F30:H30)) -> 23594 | S30: =IF(AND(ISNUMBER(Q30),ISNUMBER(R30)),Q30-R30,"") -> 0 | T30: =IF(D30="","","红:"&IF(后台计算!U24=0,"无",IF(后台计算!U24=1,"雷鸣","极限"))&" 增压"&TEXT(后台计算!W24,"0")&" 弹药"&TEXT(后台计算!X24,"0")&"｜37灵光"&TEXT(后台计算!AB24,"0")&" 启迪"&TEXT(后台计算!AC24,"0")&"｜灵犀"&TEXT(后台计算!AV24,"0")&"｜J燃烧"&TEXT(后台计算!AD24,"0")&" 敌燃烧"&TEXT(后台计算!AE24,"0")) -> 红:极限 增压10 弹药6｜37灵光5 启迪2｜灵犀5｜J燃烧16 敌燃烧6 | U30: =IF(D30="","",后台计算!BX24)
A31: =IF(D31="","",ROW()-8) -> 23 | B31: 3 | C31: 4 | D31: J｜飞跃海特街 | E31: 是 | F31: 34123 | G31: 0 | J31: =IF(D31="","",后台计算!E25) -> J | K31: =IF(D31="","",后台计算!AY25) -> 2948 | L31: =IF(D31="","",后台计算!AZ25) -> 0.667 | M31: =IF(D31="","",后台计算!BA25) -> 1.917 | N31: =IF(D31="","",后台计算!BG25) -> 7 | O31: =IF(D31="","",后台计算!BU25) -> 22493 | P31: =IF(D31="","",后台计算!BV25) -> 34123 | Q31: =IF(D31="","",IF(E31="是",P31,IF(E31="否",O31,""))) -> 34123 | R31: =IF(COUNT(F31:H31)=0,"",SUM(F31:H31)) -> 34123 | S31: =IF(AND(ISNUMBER(Q31),ISNUMBER(R31)),Q31-R31,"") -> 0 | T31: =IF(D31="","","红:"&IF(后台计算!U25=0,"无",IF(后台计算!U25=1,"雷鸣","极限"))&" 增压"&TEXT(后台计算!W25,"0")&" 弹药"&TEXT(后台计算!X25,"0")&"｜37灵光"&TEXT(后台计算!AB25,"0")&" 启迪"&TEXT(后台计算!AC25,"0")&"｜灵犀"&TEXT(后台计算!AV25,"0")&"｜J燃烧"&TEXT(后台计算!AD25,"0")&" 敌燃烧"&TEXT(后台计算!AE25,"0")) -> 红:极限 增压10 弹药6｜37灵光0 启迪1｜灵犀5｜J燃烧16 敌燃烧6 | U31: =IF(D31="","",后台计算!BX25)
A32: =IF(D32="","",ROW()-8) -> 24 | B32: 3 | C32: 5 | D32: 小瑞安侬｜囫囵囵咒Ⅰ | E32: 是 | F32: 4467 | G32: 0 | J32: =IF(D32="","",后台计算!E26) -> 小瑞安侬 | K32: =IF(D32="","",后台计算!AY26) -> 3798 | L32: =IF(D32="","",后台计算!AZ26) -> 0.555 | M32: =IF(D32="","",后台计算!BA26) -> 1.77 | N32: =IF(D32="","",后台计算!BG26) -> 4 | O32: =IF(D32="","",后台计算!BU26) -> 3261 | P32: =IF(D32="","",后台计算!BV26) -> 4467 | Q32: =IF(D32="","",IF(E32="是",P32,IF(E32="否",O32,""))) -> 4467 | R32: =IF(COUNT(F32:H32)=0,"",SUM(F32:H32)) -> 4467 | S32: =IF(AND(ISNUMBER(Q32),ISNUMBER(R32)),Q32-R32,"") -> 0 | T32: =IF(D32="","","红:"&IF(后台计算!U26=0,"无",IF(后台计算!U26=1,"雷鸣","极限"))&" 增压"&TEXT(后台计算!W26,"0")&" 弹药"&TEXT(后台计算!X26,"0")&"｜37灵光"&TEXT(后台计算!AB26,"0")&" 启迪"&TEXT(后台计算!AC26,"0")&"｜灵犀"&TEXT(后台计算!AV26,"0")&"｜J燃烧"&TEXT(后台计算!AD26,"0")&" 敌燃烧"&TEXT(后台计算!AE26,"0")) -> 红:极限 增压10 弹药6｜37灵光1 启迪1｜灵犀5｜J燃烧16 敌燃烧22 | U32: =IF(D32="","",后台计算!BX26)
A33: =IF(D33="","",ROW()-8) -> 25 | B33: 3 | C33: 6 | D33: 小瑞安侬｜囫囵囵咒Ⅰ | E33: 否 | F33: 9934 | G33: 0 | J33: =IF(D33="","",后台计算!E27) -> 小瑞安侬 | K33: =IF(D33="","",后台计算!AY27) -> 3798 | L33: =IF(D33="","",后台计算!AZ27) -> 0.555 | M33: =IF(D33="","",后台计算!BA27) -> 1.77 | N33: =IF(D33="","",后台计算!BG27) -> 4 | O33: =IF(D33="","",后台计算!BU27) -> 9934 | P33: =IF(D33="","",后台计算!BV27) -> 16590 | Q33: =IF(D33="","",IF(E33="是",P33,IF(E33="否",O33,""))) -> 9934 | R33: =IF(COUNT(F33:H33)=0,"",SUM(F33:H33)) -> 9934 | S33: =IF(AND(ISNUMBER(Q33),ISNUMBER(R33)),Q33-R33,"") -> 0 | T33: =IF(D33="","","红:"&IF(后台计算!U27=0,"无",IF(后台计算!U27=1,"雷鸣","极限"))&" 增压"&TEXT(后台计算!W27,"0")&" 弹药"&TEXT(后台计算!X27,"0")&"｜37灵光"&TEXT(后台计算!AB27,"0")&" 启迪"&TEXT(后台计算!AC27,"0")&"｜灵犀"&TEXT(后台计算!AV27,"0")&"｜J燃烧"&TEXT(后台计算!AD27,"0")&" 敌燃烧"&TEXT(后台计算!AE27,"0")) -> 红:极限 增压10 弹药6｜37灵光2 启迪1｜灵犀5｜J燃烧16 敌燃烧22 | U33: =IF(D33="","",后台计算!BX27)
A34: =IF(D34="","",ROW()-8) -> 26 | B34: 3 | C34: 7 | D34: 红弩箭｜试试杀手锏 | E34: 是 | F34: 1199340 | G34: 0 | J34: =IF(D34="","",后台计算!E28) -> 红弩箭 | K34: =IF(D34="","",后台计算!AY28) -> 3493 | L34: =IF(D34="","",后台计算!AZ28) -> 1 | M34: =IF(D34="","",后台计算!BA28) -> 3.245 | N34: =IF(D34="","",后台计算!BG28) -> 36 | O34: =IF(D34="","",后台计算!BU28) -> 381348 | P34: =IF(D34="","",后台计算!BV28) -> 1199340 | Q34: =IF(D34="","",IF(E34="是",P34,IF(E34="否",O34,""))) -> 1199340 | R34: =IF(COUNT(F34:H34)=0,"",SUM(F34:H34)) -> 1199340 | S34: =IF(AND(ISNUMBER(Q34),ISNUMBER(R34)),Q34-R34,"") -> 0 | T34: =IF(D34="","","红:"&IF(后台计算!U28=0,"无",IF(后台计算!U28=1,"雷鸣","极限"))&" 增压"&TEXT(后台计算!W28,"0")&" 弹药"&TEXT(后台计算!X28,"0")&"｜37灵光"&TEXT(后台计算!AB28,"0")&" 启迪"&TEXT(后台计算!AC28,"0")&"｜灵犀"&TEXT(后台计算!AV28,"0")&"｜J燃烧"&TEXT(后台计算!AD28,"0")&" 敌燃烧"&TEXT(后台计算!AE28,"0")) -> 红:极限 增压10 弹药6｜37灵光3 启迪1｜灵犀5｜J燃烧16 敌燃烧22 | U34: =IF(D34="","",后台计算!BX28)
A35: =IF(D35="","",ROW()-8) -> 27 | B35: 3 | C35: 8 | D35: 红弩箭｜极限俯冲Ⅲ | E35: 是 | F35: 1990454 | G35: 0 | J35: =IF(D35="","",后台计算!E29) -> 红弩箭 | K35: =IF(D35="","",后台计算!AY29) -> 3493 | L35: =IF(D35="","",后台计算!AZ29) -> 1 | M35: =IF(D35="","",后台计算!BA29) -> 2.265 | N35: =IF(D35="","",后台计算!BG29) -> 45 | O35: =IF(D35="","",后台计算!BU29) -> 919378 | P35: =IF(D35="","",后台计算!BV29) -> 1990454 | Q35: =IF(D35="","",IF(E35="是",P35,IF(E35="否",O35,""))) -> 1990454 | R35: =IF(COUNT(F35:H35)=0,"",SUM(F35:H35)) -> 1990454 | S35: =IF(AND(ISNUMBER(Q35),ISNUMBER(R35)),Q35-R35,"") -> 0 | T35: =IF(D35="","","红:"&IF(后台计算!U29=0,"无",IF(后台计算!U29=1,"雷鸣","极限"))&" 增压"&TEXT(后台计算!W29,"0")&" 弹药"&TEXT(后台计算!X29,"0")&"｜37灵光"&TEXT(后台计算!AB29,"0")&" 启迪"&TEXT(后台计算!AC29,"0")&"｜灵犀"&TEXT(后台计算!AV29,"0")&"｜J燃烧"&TEXT(后台计算!AD29,"0")&" 敌燃烧"&TEXT(后台计算!AE29,"0")) -> 红:极限 增压10 弹药0｜37灵光4 启迪1｜灵犀5｜J燃烧16 敌燃烧22 | U35: =IF(D35="","",后台计算!BX29)
A36: =IF(D36="","",ROW()-8) -> 28 | B36: 3 | C36: 9 | D36: 37｜补充算式 | E36: 是 | F36: 4127 | G36: 7784 | J36: =IF(D36="","",后台计算!E30) -> 37 | K36: =IF(D36="","",后台计算!AY30) -> 3505 | L36: =IF(D36="","",后台计算!AZ30) -> 0.76 | M36: =IF(D36="","",后台计算!BA30) -> 2.438 | N36: =IF(D36="","",后台计算!BG30) -> 3 | O36: =IF(D36="","",后台计算!BU30) -> 5094 | P36: =IF(D36="","",后台计算!BV30) -> 11911 | Q36: =IF(D36="","",IF(E36="是",P36,IF(E36="否",O36,""))) -> 11911 | R36: =IF(COUNT(F36:H36)=0,"",SUM(F36:H36)) -> 11911 | S36: =IF(AND(ISNUMBER(Q36),ISNUMBER(R36)),Q36-R36,"") -> 0 | T36: =IF(D36="","","红:"&IF(后台计算!U30=0,"无",IF(后台计算!U30=1,"雷鸣","极限"))&" 增压"&TEXT(后台计算!W30,"0")&" 弹药"&TEXT(后台计算!X30,"0")&"｜37灵光"&TEXT(后台计算!AB30,"0")&" 启迪"&TEXT(后台计算!AC30,"0")&"｜灵犀"&TEXT(后台计算!AV30,"0")&"｜J燃烧"&TEXT(后台计算!AD30,"0")&" 敌燃烧"&TEXT(后台计算!AE30,"0")) -> 红:极限 增压10 弹药0｜37灵光5 启迪1｜灵犀5｜J燃烧16 敌燃烧22 | U36: =IF(D36="","",后台计算!BX30)
A37: =IF(D37="","",ROW()-8) -> 29 | B37: 3 | C37: 10 | D37: J｜高温回火 | E37: 否 | F37: 5798 | G37: 0 | I37: 回合末默契消耗按库存自动计算；发生于首次Boss反击前的时点由本场验证。 | J37: =IF(D37="","",后台计算!E31) -> J | K37: =IF(D37="","",后台计算!AY31) -> 2948 | L37: =IF(D37="","",后台计算!AZ31) -> 0.667 | M37: =IF(D37="","",后台计算!BA31) -> 1.957 | N37: =IF(D37="","",后台计算!BG31) -> 3.8 | O37: =IF(D37="","",后台计算!BU31) -> 5798 | P37: =IF(D37="","",后台计算!BV31) -> 6378 | Q37: =IF(D37="","",IF(E37="是",P37,IF(E37="否",O37,""))) -> 5798 | R37: =IF(COUNT(F37:H37)=0,"",SUM(F37:H37)) -> 5798 | S37: =IF(AND(ISNUMBER(Q37),ISNUMBER(R37)),Q37-R37,"") -> 0 | T37: =IF(D37="","","红:"&IF(后台计算!U31=0,"无",IF(后台计算!U31=1,"雷鸣","极限"))&" 增压"&TEXT(后台计算!W31,"0")&" 弹药"&TEXT(后台计算!X31,"0")&"｜37灵光"&TEXT(后台计算!AB31,"0")&" 启迪"&TEXT(后台计算!AC31,"0")&"｜灵犀"&TEXT(后台计算!AV31,"0")&"｜J燃烧"&TEXT(后台计算!AD31,"0")&" 敌燃烧"&TEXT(后台计算!AE31,"0")) -> 红:极限 增压10 弹药0｜37灵光0 启迪0｜灵犀5｜J燃烧16 敌燃烧22 | U37: =IF(D37="","",后台计算!BX31)
A38: =IF(D38="","",ROW()-8) -> 30 | B38: 3 | C38: 11 | D38: J｜高温回火 | E38: 是 | F38: 8031 | G38: 0 | J38: =IF(D38="","",后台计算!E32) -> J | K38: =IF(D38="","",后台计算!AY32) -> 2987 | L38: =IF(D38="","",后台计算!AZ32) -> 0.667 | M38: =IF(D38="","",后台计算!BA32) -> 1.957 | N38: =IF(D38="","",后台计算!BG32) -> 3.9 | O38: =IF(D38="","",后台计算!BU32) -> 7301 | P38: =IF(D38="","",后台计算!BV32) -> 8031 | Q38: =IF(D38="","",IF(E38="是",P38,IF(E38="否",O38,""))) -> 8031 | R38: =IF(COUNT(F38:H38)=0,"",SUM(F38:H38)) -> 8031 | S38: =IF(AND(ISNUMBER(Q38),ISNUMBER(R38)),Q38-R38,"") -> 0 | T38: =IF(D38="","","红:"&IF(后台计算!U32=0,"无",IF(后台计算!U32=1,"雷鸣","极限"))&" 增压"&TEXT(后台计算!W32,"0")&" 弹药"&TEXT(后台计算!X32,"0")&"｜37灵光"&TEXT(后台计算!AB32,"0")&" 启迪"&TEXT(后台计算!AC32,"0")&"｜灵犀"&TEXT(后台计算!AV32,"0")&"｜J燃烧"&TEXT(后台计算!AD32,"0")&" 敌燃烧"&TEXT(后台计算!AE32,"0")) -> 红:极限 增压10 弹药0｜37灵光1 启迪0｜灵犀5｜J燃烧18 敌燃烧24 | U38: =IF(D38="","",后台计算!BX32)
A39: =IF(D39="","",ROW()-8) -> 31 | B39: 3 | C39: 12 | D39: J｜高温回火 | E39: 是 | F39: 8412 | G39: 0 | J39: =IF(D39="","",后台计算!E33) -> J | K39: =IF(D39="","",后台计算!AY33) -> 3025 | L39: =IF(D39="","",后台计算!AZ33) -> 0.667 | M39: =IF(D39="","",后台计算!BA33) -> 1.957 | N39: =IF(D39="","",后台计算!BG33) -> 4 | O39: =IF(D39="","",后台计算!BU33) -> 7647 | P39: =IF(D39="","",后台计算!BV33) -> 8412 | Q39: =IF(D39="","",IF(E39="是",P39,IF(E39="否",O39,""))) -> 8412 | R39: =IF(COUNT(F39:H39)=0,"",SUM(F39:H39)) -> 8412 | S39: =IF(AND(ISNUMBER(Q39),ISNUMBER(R39)),Q39-R39,"") -> 0 | T39: =IF(D39="","","红:"&IF(后台计算!U33=0,"无",IF(后台计算!U33=1,"雷鸣","极限"))&" 增压"&TEXT(后台计算!W33,"0")&" 弹药"&TEXT(后台计算!X33,"0")&"｜37灵光"&TEXT(后台计算!AB33,"0")&" 启迪"&TEXT(后台计算!AC33,"0")&"｜灵犀"&TEXT(后台计算!AV33,"0")&"｜J燃烧"&TEXT(后台计算!AD33,"0")&" 敌燃烧"&TEXT(后台计算!AE33,"0")) -> 红:极限 增压10 弹药0｜37灵光2 启迪0｜灵犀5｜J燃烧20 敌燃烧26 | U39: =IF(D39="","",后台计算!BX33)
A40: =IF(D40="","",ROW()-8) -> 32 | B40: 3 | C40: 13 | D40: J｜高温回火 | E40: 否 | F40: 8001 | G40: 0 | J40: =IF(D40="","",后台计算!E34) -> J | K40: =IF(D40="","",后台计算!AY34) -> 3063 | L40: =IF(D40="","",后台计算!AZ34) -> 0.667 | M40: =IF(D40="","",后台计算!BA34) -> 1.957 | N40: =IF(D40="","",后台计算!BG34) -> 4.1 | O40: =IF(D40="","",后台计算!BU34) -> 8001 | P40: =IF(D40="","",后台计算!BV34) -> 8802 | Q40: =IF(D40="","",IF(E40="是",P40,IF(E40="否",O40,""))) -> 8001 | R40: =IF(COUNT(F40:H40)=0,"",SUM(F40:H40)) -> 8001 | S40: =IF(AND(ISNUMBER(Q40),ISNUMBER(R40)),Q40-R40,"") -> 0 | T40: =IF(D40="","","红:"&IF(后台计算!U34=0,"无",IF(后台计算!U34=1,"雷鸣","极限"))&" 增压"&TEXT(后台计算!W34,"0")&" 弹药"&TEXT(后台计算!X34,"0")&"｜37灵光"&TEXT(后台计算!AB34,"0")&" 启迪"&TEXT(后台计算!AC34,"0")&"｜灵犀"&TEXT(后台计算!AV34,"0")&"｜J燃烧"&TEXT(后台计算!AD34,"0")&" 敌燃烧"&TEXT(后台计算!AE34,"0")) -> 红:极限 增压10 弹药0｜37灵光3 启迪0｜灵犀5｜J燃烧22 敌燃烧28 | U40: =IF(D40="","",后台计算!BX34)
A41: =IF(D41="","",ROW()-8) -> 33 | B41: 洞知 | C41: 1 | D41: 系统｜进入弱点洞穿 | E41: — | J41: =IF(D41="","",后台计算!E35) -> 系统 | K41: =IF(D41="","",后台计算!AY35) -> 0 | L41: =IF(D41="","",后台计算!AZ35) -> 0 | M41: =IF(D41="","",后台计算!BA35) -> 0.24 | N41: =IF(D41="","",后台计算!BG35) -> 0 | O41: =IF(D41="","",后台计算!BU35) -> 0 | P41: =IF(D41="","",后台计算!BV35) -> 0 | Q41: =IF(D41="","",IF(E41="是",P41,IF(E41="否",O41,""))) | R41: =IF(COUNT(F41:H41)=0,"",SUM(F41:H41)) | S41: =IF(AND(ISNUMBER(Q41),ISNUMBER(R41)),Q41-R41,"") | T41: =IF(D41="","","红:"&IF(后台计算!U35=0,"无",IF(后台计算!U35=1,"雷鸣","极限"))&" 增压"&TEXT(后台计算!W35,"0")&" 弹药"&TEXT(后台计算!X35,"0")&"｜37灵光"&TEXT(后台计算!AB35,"0")&" 启迪"&TEXT(后台计算!AC35,"0")&"｜灵犀"&TEXT(后台计算!AV35,"0")&"｜J燃烧"&TEXT(后台计算!AD35,"0")&" 敌燃烧"&TEXT(后台计算!AE35,"0")) -> 红:极限 增压10 弹药0｜37灵光4 启迪0｜灵犀5｜J燃烧24 敌燃烧15 | U41: =IF(D41="","",后台计算!BX35)
A42: =IF(D42="","",ROW()-8) -> 34 | B42: 洞知 | C42: 2 | D42: 红弩箭｜洞知咒语 | E42: 是 | F42: 350721 | G42: 0 | J42: =IF(D42="","",后台计算!E36) -> 红弩箭 | K42: =IF(D42="","",后台计算!AY36) -> 3493 | L42: =IF(D42="","",后台计算!AZ36) -> 1 | M42: =IF(D42="","",后台计算!BA36) -> 2.865 | N42: =IF(D42="","",后台计算!BG36) -> 15 | O42: =IF(D42="","",后台计算!BU36) -> 126843 | P42: =IF(D42="","",后台计算!BV36) -> 350721 | Q42: =IF(D42="","",IF(E42="是",P42,IF(E42="否",O42,""))) -> 350721 | R42: =IF(COUNT(F42:H42)=0,"",SUM(F42:H42)) -> 350721 | S42: =IF(AND(ISNUMBER(Q42),ISNUMBER(R42)),Q42-R42,"") -> 0 | T42: =IF(D42="","","红:"&IF(后台计算!U36=0,"无",IF(后台计算!U36=1,"雷鸣","极限"))&" 增压"&TEXT(后台计算!W36,"0")&" 弹药"&TEXT(后台计算!X36,"0")&"｜37灵光"&TEXT(后台计算!AB36,"0")&" 启迪"&TEXT(后台计算!AC36,"0")&"｜灵犀"&TEXT(后台计算!AV36,"0")&"｜J燃烧"&TEXT(后台计算!AD36,"0")&" 敌燃烧"&TEXT(后台计算!AE36,"0")) -> 红:极限 增压10 弹药0｜37灵光4 启迪0｜灵犀5｜J燃烧24 敌燃烧15 | U42: =IF(D42="","",后台计算!BX36)
A43: =IF(D43="","",ROW()-8) -> 35 | B43: 洞知 | C43: 3 | D43: 红弩箭｜洞知咒语 | E43: 是 | F43: 364210 | G43: 0 | J43: =IF(D43="","",后台计算!E37) -> 红弩箭 | K43: =IF(D43="","",后台计算!AY37) -> 3493 | L43: =IF(D43="","",后台计算!AZ37) -> 1 | M43: =IF(D43="","",后台计算!BA37) -> 2.865 | N43: =IF(D43="","",后台计算!BG37) -> 15 | O43: =IF(D43="","",后台计算!BU37) -> 131721 | P43: =IF(D43="","",后台计算!BV37) -> 364210 | Q43: =IF(D43="","",IF(E43="是",P43,IF(E43="否",O43,""))) -> 364210 | R43: =IF(COUNT(F43:H43)=0,"",SUM(F43:H43)) -> 364210 | S43: =IF(AND(ISNUMBER(Q43),ISNUMBER(R43)),Q43-R43,"") -> 0 | T43: =IF(D43="","","红:"&IF(后台计算!U37=0,"无",IF(后台计算!U37=1,"雷鸣","极限"))&" 增压"&TEXT(后台计算!W37,"0")&" 弹药"&TEXT(后台计算!X37,"0")&"｜37灵光"&TEXT(后台计算!AB37,"0")&" 启迪"&TEXT(后台计算!AC37,"0")&"｜灵犀"&TEXT(后台计算!AV37,"0")&"｜J燃烧"&TEXT(后台计算!AD37,"0")&" 敌燃烧"&TEXT(后台计算!AE37,"0")) -> 红:极限 增压10 弹药1｜37灵光5 启迪0｜灵犀5｜J燃烧24 敌燃烧15 | U43: =IF(D43="","",后台计算!BX37)
A44: =IF(D44="","",ROW()-8) -> 36 | B44: 洞知 | C44: 4 | D44: 37｜洞知咒语 | E44: 否 | F44: 46002 | G44: 0 | J44: =IF(D44="","",后台计算!E38) -> 37 | K44: =IF(D44="","",后台计算!AY38) -> 3505 | L44: =IF(D44="","",后台计算!AZ38) -> 0.76 | M44: =IF(D44="","",后台计算!BA38) -> 2.438 | N44: =IF(D44="","",后台计算!BG38) -> 8 | O44: =IF(D44="","",后台计算!BU38) -> 46002 | P44: =IF(D44="","",后台计算!BV38) -> 107554 | Q44: =IF(D44="","",IF(E44="是",P44,IF(E44="否",O44,""))) -> 46002 | R44: =IF(COUNT(F44:H44)=0,"",SUM(F44:H44)) -> 46002 | S44: =IF(AND(ISNUMBER(Q44),ISNUMBER(R44)),Q44-R44,"") -> 0 | T44: =IF(D44="","","红:"&IF(后台计算!U38=0,"无",IF(后台计算!U38=1,"雷鸣","极限"))&" 增压"&TEXT(后台计算!W38,"0")&" 弹药"&TEXT(后台计算!X38,"0")&"｜37灵光"&TEXT(后台计算!AB38,"0")&" 启迪"&TEXT(后台计算!AC38,"0")&"｜灵犀"&TEXT(后台计算!AV38,"0")&"｜J燃烧"&TEXT(后台计算!AD38,"0")&" 敌燃烧"&TEXT(后台计算!AE38,"0")) -> 红:极限 增压10 弹药2｜37灵光6 启迪0｜灵犀5｜J燃烧24 敌燃烧15 | U44: =IF(D44="","",后台计算!BX38)
A45: =IF(D45="","",ROW()-8) -> 37 | B45: 洞知 | C45: 5 | D45: 红弩箭｜洞知咒语 | E45: 是 | F45: 671176 | H45: 268470 | I45: 稳态本源自动：先消耗已有两分悖论；37攻击后再获得1层。 | J45: =IF(D45="","",后台计算!E39) -> 红弩箭 | K45: =IF(D45="","",后台计算!AY39) -> 3493 | L45: =IF(D45="","",后台计算!AZ39) -> 1 | M45: =IF(D45="","",后台计算!BA39) -> 3.065 | N45: =IF(D45="","",后台计算!BG39) -> 32 | O45: =IF(D45="","",后台计算!BU39) -> 316912 | P45: =IF(D45="","",后台计算!BV39) -> 939646 | Q45: =IF(D45="","",IF(E45="是",P45,IF(E45="否",O45,""))) -> 939646 | R45: =IF(COUNT(F45:H45)=0,"",SUM(F45:H45)) -> 939646 | S45: =IF(AND(ISNUMBER(Q45),ISNUMBER(R45)),Q45-R45,"") -> 0 | T45: =IF(D45="","","红:"&IF(后台计算!U39=0,"无",IF(后台计算!U39=1,"雷鸣","极限"))&" 增压"&TEXT(后台计算!W39,"0")&" 弹药"&TEXT(后台计算!X39,"0")&"｜37灵光"&TEXT(后台计算!AB39,"0")&" 启迪"&TEXT(后台计算!AC39,"0")&"｜灵犀"&TEXT(后台计算!AV39,"0")&"｜J燃烧"&TEXT(后台计算!AD39,"0")&" 敌燃烧"&TEXT(后台计算!AE39,"0")) -> 红:极限 增压10 弹药2｜37灵光7 启迪0｜灵犀5｜J燃烧24 敌燃烧15 | U45: =IF(D45="","",后台计算!BX39)
...

Sheet 验证表
A1: 实测验证｜49个事件逐项比较
A3: 指标 | B3: 数值 | C3: 说明
A4: 已有实测数据行动数 | B4: =COUNT(H9:H88) -> 64 | C4: 填写实测伤害后自动统计
A5: 总绝对误差率 | B5: =IF(SUM(H9:H88)=0,"",SUM(K9:K88)/SUM(H9:H88)) -> 0 | C5: SUM(|实测-预测|)/SUM(实测)
A6: 按每个实测暴击判定比较预测，分列主伤害与本源/附加。Boss基础参数已确认；未解释的技能和行动类别差异见“核对说明”。
A8: 事件 | B8: 回合 | C8: 位 | D8: 技能 | E8: 预测不暴击 | F8: 预测暴击 | G8: 是否暴击 | H8: 实测伤害 | I8: 对应预测 | J8: 误差 | K8: 绝对误差 | L8: 误差率 | M8: 备注 | N8: 实测主伤害 | O8: 实测本源/附加 | P8: 预测主伤害 | Q8: 预测本源/附加 | R8: 主伤害差 | S8: 本源/附加差 | T8: 附加关系 | U8: Boss攻击前损失段 | V8: 本源减伤 | W8: 最终免伤 | X8: 生命状态来源 | Y8: 实测超合计上限
A9: =行动模拟!A9 -> 1 | B9: =行动模拟!B9 -> 1 | C9: =行动模拟!C9 -> 1 | D9: =行动模拟!D9 -> 小瑞安侬｜悄冥冥术阵 | E9: =行动模拟!O9 -> 0 | F9: =行动模拟!P9 -> 0 | G9: =IF(行动模拟!D9="","",行动模拟!E9) -> — | H9: =IF(COUNT(行动模拟!F9:H9)=0,"",SUM(行动模拟!F9:H9)) | I9: =IF(H9="","",IF(G9="是",F9,IF(G9="否",E9,""))) | J9: =IF(OR(H9="",I9=""),"",H9-I9) | K9: =IF(J9="","",ABS(J9)) | L9: =IF(OR(H9="",I9=""),"",IF(H9=0,IF(I9=0,0,"实测为0"),ABS(J9)/H9)) | M9: =IF(H9="","",IF(AND(G9<>"是",G9<>"否"),"缺少暴击判定",IF(L9>0.03,"存在差异：请看核对说明并核对行动状态","数值差异≤3%；机制仍需核实"))) | N9: =IF(ISNUMBER(行动模拟!F9),行动模拟!F9,"") | O9: =IF(COUNT(行动模拟!G9:H9)=0,"",SUM(行动模拟!G9:H9)) | P9: =IF(H9="","",IF(G9="是",后台计算!DX3,IF(G9="否",后台计算!DW3,""))) | Q9: =IF(H9="","",IF(G9="是",后台计算!BV3-后台计算!DX3,IF(G9="否",后台计算!BU3-后台计算!DW3,""))) | R9: =IF(OR(N9="",P9=""),"",N9-P9) | S9: =IF(OR(O9="",Q9=""),"",O9-Q9) | T9: =IF(AND(后台计算!DH3="洞穿",O9>0),IF(O9=ROUNDDOWN(N9*0.4,0),"实测附加=floor(主伤害×40%)；稳态来源待确认","实测附加关系需核对"),"") | U9: =IF(D9="","",后台计算!EQ3) -> 0 | V9: =IF(D9="","",后台计算!ER3) -> 0 | W9: =IF(D9="","",后台计算!ES3) -> 0 | X9: =IF(D9="","",IF(Boss参数!$B$60=1,"此前实测；缺失用预测","此前预测")) -> 此前实测；缺失用预测 | Y9: =IF(H9="","",IF(H9>Boss参数!$B$63*Boss参数!$B$62,"超过暂定合计上限",""))
A10: =行动模拟!A10 -> 2 | B10: =行动模拟!B10 -> 1 | C10: =行动模拟!C10 -> 2 | D10: =行动模拟!D10 -> J｜热处理 | E10: =行动模拟!O10 -> 0 | F10: =行动模拟!P10 -> 0 | G10: =IF(行动模拟!D10="","",行动模拟!E10) -> — | H10: =IF(COUNT(行动模拟!F10:H10)=0,"",SUM(行动模拟!F10:H10)) | I10: =IF(H10="","",IF(G10="是",F10,IF(G10="否",E10,""))) | J10: =IF(OR(H10="",I10=""),"",H10-I10) | K10: =IF(J10="","",ABS(J10)) | L10: =IF(OR(H10="",I10=""),"",IF(H10=0,IF(I10=0,0,"实测为0"),ABS(J10)/H10)) | M10: =IF(H10="","",IF(AND(G10<>"是",G10<>"否"),"缺少暴击判定",IF(L10>0.03,"存在差异：请看核对说明并核对行动状态","数值差异≤3%；机制仍需核实"))) | N10: =IF(ISNUMBER(行动模拟!F10),行动模拟!F10,"") | O10: =IF(COUNT(行动模拟!G10:H10)=0,"",SUM(行动模拟!G10:H10)) | P10: =IF(H10="","",IF(G10="是",后台计算!DX4,IF(G10="否",后台计算!DW4,""))) | Q10: =IF(H10="","",IF(G10="是",后台计算!BV4-后台计算!DX4,IF(G10="否",后台计算!BU4-后台计算!DW4,""))) | R10: =IF(OR(N10="",P10=""),"",N10-P10) | S10: =IF(OR(O10="",Q10=""),"",O10-Q10) | T10: =IF(AND(后台计算!DH4="洞穿",O10>0),IF(O10=ROUNDDOWN(N10*0.4,0),"实测附加=floor(主伤害×40%)；稳态来源待确认","实测附加关系需核对"),"") | U10: =IF(D10="","",后台计算!EQ4) -> 0 | V10: =IF(D10="","",后台计算!ER4) -> 0 | W10: =IF(D10="","",后台计算!ES4) -> 0 | X10: =IF(D10="","",IF(Boss参数!$B$60=1,"此前实测；缺失用预测","此前预测")) -> 此前实测；缺失用预测 | Y10: =IF(H10="","",IF(H10>Boss参数!$B$63*Boss参数!$B$62,"超过暂定合计上限",""))
A11: =行动模拟!A11 -> 3 | B11: =行动模拟!B11 -> 1 | C11: =行动模拟!C11 -> 3 | D11: =行动模拟!D11 -> 红弩箭｜眼镜蛇机动 | E11: =行动模拟!O11 -> 0 | F11: =行动模拟!P11 -> 0 | G11: =IF(行动模拟!D11="","",行动模拟!E11) -> — | H11: =IF(COUNT(行动模拟!F11:H11)=0,"",SUM(行动模拟!F11:H11)) | I11: =IF(H11="","",IF(G11="是",F11,IF(G11="否",E11,""))) | J11: =IF(OR(H11="",I11=""),"",H11-I11) | K11: =IF(J11="","",ABS(J11)) | L11: =IF(OR(H11="",I11=""),"",IF(H11=0,IF(I11=0,0,"实测为0"),ABS(J11)/H11)) | M11: =IF(H11="","",IF(AND(G11<>"是",G11<>"否"),"缺少暴击判定",IF(L11>0.03,"存在差异：请看核对说明并核对行动状态","数值差异≤3%；机制仍需核实"))) | N11: =IF(ISNUMBER(行动模拟!F11),行动模拟!F11,"") | O11: =IF(COUNT(行动模拟!G11:H11)=0,"",SUM(行动模拟!G11:H11)) | P11: =IF(H11="","",IF(G11="是",后台计算!DX5,IF(G11="否",后台计算!DW5,""))) | Q11: =IF(H11="","",IF(G11="是",后台计算!BV5-后台计算!DX5,IF(G11="否",后台计算!BU5-后台计算!DW5,""))) | R11: =IF(OR(N11="",P11=""),"",N11-P11) | S11: =IF(OR(O11="",Q11=""),"",O11-Q11) | T11: =IF(AND(后台计算!DH5="洞穿",O11>0),IF(O11=ROUNDDOWN(N11*0.4,0),"实测附加=floor(主伤害×40%)；稳态来源待确认","实测附加关系需核对"),"") | U11: =IF(D11="","",后台计算!EQ5) -> 0 | V11: =IF(D11="","",后台计算!ER5) -> 0 | W11: =IF(D11="","",后台计算!ES5) -> 0 | X11: =IF(D11="","",IF(Boss参数!$B$60=1,"此前实测；缺失用预测","此前预测")) -> 此前实测；缺失用预测 | Y11: =IF(H11="","",IF(H11>Boss参数!$B$63*Boss参数!$B$62,"超过暂定合计上限",""))
A12: =行动模拟!A12 -> 4 | B12: =行动模拟!B12 -> 1 | C12: =行动模拟!C12 -> 4 | D12: =行动模拟!D12 -> 红弩箭｜极限俯冲Ⅰ | E12: =行动模拟!O12 -> 45071 | F12: =行动模拟!P12 -> 73241 | G12: =IF(行动模拟!D12="","",行动模拟!E12) -> 是 | H12: =IF(COUNT(行动模拟!F12:H12)=0,"",SUM(行动模拟!F12:H12)) -> 73241 | I12: =IF(H12="","",IF(G12="是",F12,IF(G12="否",E12,""))) -> 73241 | J12: =IF(OR(H12="",I12=""),"",H12-I12) -> 0 | K12: =IF(J12="","",ABS(J12)) -> 0 | L12: =IF(OR(H12="",I12=""),"",IF(H12=0,IF(I12=0,0,"实测为0"),ABS(J12)/H12)) -> 0 | M12: =IF(H12="","",IF(AND(G12<>"是",G12<>"否"),"缺少暴击判定",IF(L12>0.03,"存在差异：请看核对说明并核对行动状态","数值差异≤3%；机制仍需核实"))) -> 数值差异≤3%；机制仍需核实 | N12: =IF(ISNUMBER(行动模拟!F12),行动模拟!F12,"") -> 73241 | O12: =IF(COUNT(行动模拟!G12:H12)=0,"",SUM(行动模拟!G12:H12)) -> 0 | P12: =IF(H12="","",IF(G12="是",后台计算!DX6,IF(G12="否",后台计算!DW6,""))) -> 73241 | Q12: =IF(H12="","",IF(G12="是",后台计算!BV6-后台计算!DX6,IF(G12="否",后台计算!BU6-后台计算!DW6,""))) -> 0 | R12: =IF(OR(N12="",P12=""),"",N12-P12) -> 0 | S12: =IF(OR(O12="",Q12=""),"",O12-Q12) -> 0 | T12: =IF(AND(后台计算!DH6="洞穿",O12>0),IF(O12=ROUNDDOWN(N12*0.4,0),"实测附加=floor(主伤害×40%)；稳态来源待确认","实测附加关系需核对"),"") | U12: =IF(D12="","",后台计算!EQ6) -> 0 | V12: =IF(D12="","",后台计算!ER6) -> 0 | W12: =IF(D12="","",后台计算!ES6) -> 0 | X12: =IF(D12="","",IF(Boss参数!$B$60=1,"此前实测；缺失用预测","此前预测")) -> 此前实测；缺失用预测 | Y12: =IF(H12="","",IF(H12>Boss参数!$B$63*Boss参数!$B$62,"超过暂定合计上限",""))
A13: =行动模拟!A13 -> 5 | B13: =行动模拟!B13 -> 1 | C13: =行动模拟!C13 -> 5 | D13: =行动模拟!D13 -> J｜高温回火 | E13: =行动模拟!O13 -> 1231 | F13: =行动模拟!P13 -> 1354 | G13: =IF(行动模拟!D13="","",行动模拟!E13) -> 否 | H13: =IF(COUNT(行动模拟!F13:H13)=0,"",SUM(行动模拟!F13:H13)) -> 1231 | I13: =IF(H13="","",IF(G13="是",F13,IF(G13="否",E13,""))) -> 1231 | J13: =IF(OR(H13="",I13=""),"",H13-I13) -> 0 | K13: =IF(J13="","",ABS(J13)) -> 0 | L13: =IF(OR(H13="",I13=""),"",IF(H13=0,IF(I13=0,0,"实测为0"),ABS(J13)/H13)) -> 0 | M13: =IF(H13="","",IF(AND(G13<>"是",G13<>"否"),"缺少暴击判定",IF(L13>0.03,"存在差异：请看核对说明并核对行动状态","数值差异≤3%；机制仍需核实"))) -> 数值差异≤3%；机制仍需核实 | N13: =IF(ISNUMBER(行动模拟!F13),行动模拟!F13,"") -> 1231 | O13: =IF(COUNT(行动模拟!G13:H13)=0,"",SUM(行动模拟!G13:H13)) -> 0 | P13: =IF(H13="","",IF(G13="是",后台计算!DX7,IF(G13="否",后台计算!DW7,""))) -> 1231 | Q13: =IF(H13="","",IF(G13="是",后台计算!BV7-后台计算!DX7,IF(G13="否",后台计算!BU7-后台计算!DW7,""))) -> 0 | R13: =IF(OR(N13="",P13=""),"",N13-P13) -> 0 | S13: =IF(OR(O13="",Q13=""),"",O13-Q13) -> 0 | T13: =IF(AND(后台计算!DH7="洞穿",O13>0),IF(O13=ROUNDDOWN(N13*0.4,0),"实测附加=floor(主伤害×40%)；稳态来源待确认","实测附加关系需核对"),"") | U13: =IF(D13="","",后台计算!EQ7) -> 0 | V13: =IF(D13="","",后台计算!ER7) -> 0 | W13: =IF(D13="","",后台计算!ES7) -> 0 | X13: =IF(D13="","",IF(Boss参数!$B$60=1,"此前实测；缺失用预测","此前预测")) -> 此前实测；缺失用预测 | Y13: =IF(H13="","",IF(H13>Boss参数!$B$63*Boss参数!$B$62,"超过暂定合计上限",""))
A14: =行动模拟!A14 -> 6 | B14: =行动模拟!B14 -> 1 | C14: =行动模拟!C14 -> 6 | D14: =行动模拟!D14 -> 37｜补充算式 | E14: =行动模拟!O14 -> 4679 | F14: =行动模拟!P14 -> 8414 | G14: =IF(行动模拟!D14="","",行动模拟!E14) -> 是 | H14: =IF(COUNT(行动模拟!F14:H14)=0,"",SUM(行动模拟!F14:H14)) -> 8414 | I14: =IF(H14="","",IF(G14="是",F14,IF(G14="否",E14,""))) -> 8414 | J14: =IF(OR(H14="",I14=""),"",H14-I14) -> 0 | K14: =IF(J14="","",ABS(J14)) -> 0 | L14: =IF(OR(H14="",I14=""),"",IF(H14=0,IF(I14=0,0,"实测为0"),ABS(J14)/H14)) -> 0 | M14: =IF(H14="","",IF(AND(G14<>"是",G14<>"否"),"缺少暴击判定",IF(L14>0.03,"存在差异：请看核对说明并核对行动状态","数值差异≤3%；机制仍需核实"))) -> 数值差异≤3%；机制仍需核实 | N14: =IF(ISNUMBER(行动模拟!F14),行动模拟!F14,"") -> 4932 | O14: =IF(COUNT(行动模拟!G14:H14)=0,"",SUM(行动模拟!G14:H14)) -> 3482 | P14: =IF(H14="","",IF(G14="是",后台计算!DX8,IF(G14="否",后台计算!DW8,""))) -> 4932 | Q14: =IF(H14="","",IF(G14="是",后台计算!BV8-后台计算!DX8,IF(G14="否",后台计算!BU8-后台计算!DW8,""))) -> 3482 | R14: =IF(OR(N14="",P14=""),"",N14-P14) -> 0 | S14: =IF(OR(O14="",Q14=""),"",O14-Q14) -> 0 | T14: =IF(AND(后台计算!DH8="洞穿",O14>0),IF(O14=ROUNDDOWN(N14*0.4,0),"实测附加=floor(主伤害×40%)；稳态来源待确认","实测附加关系需核对"),"") | U14: =IF(D14="","",后台计算!EQ8) -> 0 | V14: =IF(D14="","",后台计算!ER8) -> 0 | W14: =IF(D14="","",后台计算!ES8) -> 0 | X14: =IF(D14="","",IF(Boss参数!$B$60=1,"此前实测；缺失用预测","此前预测")) -> 此前实测；缺失用预测 | Y14: =IF(H14="","",IF(H14>Boss参数!$B$63*Boss参数!$B$62,"超过暂定合计上限",""))
A15: =行动模拟!A15 -> 7 | B15: =行动模拟!B15 -> 1 | C15: =行动模拟!C15 -> 7 | D15: =行动模拟!D15 -> J｜高温回火 | E15: =行动模拟!O15 -> 1340 | F15: =行动模拟!P15 -> 1474 | G15: =IF(行动模拟!D15="","",行动模拟!E15) -> 是 | H15: =IF(COUNT(行动模拟!F15:H15)=0,"",SUM(行动模拟!F15:H15)) -> 1474 | I15: =IF(H15="","",IF(G15="是",F15,IF(G15="否",E15,""))) -> 1474 | J15: =IF(OR(H15="",I15=""),"",H15-I15) -> 0 | K15: =IF(J15="","",ABS(J15)) -> 0 | L15: =IF(OR(H15="",I15=""),"",IF(H15=0,IF(I15=0,0,"实测为0"),ABS(J15)/H15)) -> 0 | M15: =IF(H15="","",IF(AND(G15<>"是",G15<>"否"),"缺少暴击判定",IF(L15>0.03,"存在差异：请看核对说明并核对行动状态","数值差异≤3%；机制仍需核实"))) -> 数值差异≤3%；机制仍需核实 | N15: =IF(ISNUMBER(行动模拟!F15),行动模拟!F15,"") -> 1474 | O15: =IF(COUNT(行动模拟!G15:H15)=0,"",SUM(行动模拟!G15:H15)) -> 0 | P15: =IF(H15="","",IF(G15="是",后台计算!DX9,IF(G15="否",后台计算!DW9,""))) -> 1474 | Q15: =IF(H15="","",IF(G15="是",后台计算!BV9-后台计算!DX9,IF(G15="否",后台计算!BU9-后台计算!DW9,""))) -> 0 | R15: =IF(OR(N15="",P15=""),"",N15-P15) -> 0 | S15: =IF(OR(O15="",Q15=""),"",O15-Q15) -> 0 | T15: =IF(AND(后台计算!DH9="洞穿",O15>0),IF(O15=ROUNDDOWN(N15*0.4,0),"实测附加=floor(主伤害×40%)；稳态来源待确认","实测附加关系需核对"),"") | U15: =IF(D15="","",后台计算!EQ9) -> 0 | V15: =IF(D15="","",后台计算!ER9) -> 0 | W15: =IF(D15="","",后台计算!ES9) -> 0 | X15: =IF(D15="","",IF(Boss参数!$B$60=1,"此前实测；缺失用预测","此前预测")) -> 此前实测；缺失用预测 | Y15: =IF(H15="","",IF(H15>Boss参数!$B$63*Boss参数!$B$62,"超过暂定合计上限",""))
A16: =行动模拟!A16 -> 8 | B16: =行动模拟!B16 -> 1 | C16: =行动模拟!C16 -> 8 | D16: =行动模拟!D16 -> J｜高温回火 | E16: =行动模拟!O16 -> 1745 | F16: =行动模拟!P16 -> 1919 | G16: =IF(行动模拟!D16="","",行动模拟!E16) -> 否 | H16: =IF(COUNT(行动模拟!F16:H16)=0,"",SUM(行动模拟!F16:H16)) -> 1745 | I16: =IF(H16="","",IF(G16="是",F16,IF(G16="否",E16,""))) -> 1745 | J16: =IF(OR(H16="",I16=""),"",H16-I16) -> 0 | K16: =IF(J16="","",ABS(J16)) -> 0 | L16: =IF(OR(H16="",I16=""),"",IF(H16=0,IF(I16=0,0,"实测为0"),ABS(J16)/H16)) -> 0 | M16: =IF(H16="","",IF(AND(G16<>"是",G16<>"否"),"缺少暴击判定",IF(L16>0.03,"存在差异：请看核对说明并核对行动状态","数值差异≤3%；机制仍需核实"))) -> 数值差异≤3%；机制仍需核实 | N16: =IF(ISNUMBER(行动模拟!F16),行动模拟!F16,"") -> 1745 | O16: =IF(COUNT(行动模拟!G16:H16)=0,"",SUM(行动模拟!G16:H16)) -> 0 | P16: =IF(H16="","",IF(G16="是",后台计算!DX10,IF(G16="否",后台计算!DW10,""))) -> 1745 | Q16: =IF(H16="","",IF(G16="是",后台计算!BV10-后台计算!DX10,IF(G16="否",后台计算!BU10-后台计算!DW10,""))) -> 0 | R16: =IF(OR(N16="",P16=""),"",N16-P16) -> 0 | S16: =IF(OR(O16="",Q16=""),"",O16-Q16) -> 0 | T16: =IF(AND(后台计算!DH10="洞穿",O16>0),IF(O16=ROUNDDOWN(N16*0.4,0),"实测附加=floor(主伤害×40%)；稳态来源待确认","实测附加关系需核对"),"") | U16: =IF(D16="","",后台计算!EQ10) -> 0 | V16: =IF(D16="","",后台计算!ER10) -> 0 | W16: =IF(D16="","",后台计算!ES10) -> 0 | X16: =IF(D16="","",IF(Boss参数!$B$60=1,"此前实测；缺失用预测","此前预测")) -> 此前实测；缺失用预测 | Y16: =IF(H16="","",IF(H16>Boss参数!$B$63*Boss参数!$B$62,"超过暂定合计上限",""))
A17: =行动模拟!A17 -> 9 | B17: =行动模拟!B17 -> 1 | C17: =行动模拟!C17 -> 9 | D17: =行动模拟!D17 -> J｜高温回火 | E17: =行动模拟!O17 -> 1887 | F17: =行动模拟!P17 -> 2076 | G17: =IF(行动模拟!D17="","",行动模拟!E17) -> 是 | H17: =IF(COUNT(行动模拟!F17:H17)=0,"",SUM(行动模拟!F17:H17)) -> 2076 | I17: =IF(H17="","",IF(G17="是",F17,IF(G17="否",E17,""))) -> 2076 | J17: =IF(OR(H17="",I17=""),"",H17-I17) -> 0 | K17: =IF(J17="","",ABS(J17)) -> 0 | L17: =IF(OR(H17="",I17=""),"",IF(H17=0,IF(I17=0,0,"实测为0"),ABS(J17)/H17)) -> 0 | M17: =IF(H17="","",IF(AND(G17<>"是",G17<>"否"),"缺少暴击判定",IF(L17>0.03,"存在差异：请看核对说明并核对行动状态","数值差异≤3%；机制仍需核实"))) -> 数值差异≤3%；机制仍需核实 | N17: =IF(ISNUMBER(行动模拟!F17),行动模拟!F17,"") -> 2076 | O17: =IF(COUNT(行动模拟!G17:H17)=0,"",SUM(行动模拟!G17:H17)) -> 0 | P17: =IF(H17="","",IF(G17="是",后台计算!DX11,IF(G17="否",后台计算!DW11,""))) -> 2076 | Q17: =IF(H17="","",IF(G17="是",后台计算!BV11-后台计算!DX11,IF(G17="否",后台计算!BU11-后台计算!DW11,""))) -> 0 | R17: =IF(OR(N17="",P17=""),"",N17-P17) -> 0 | S17: =IF(OR(O17="",Q17=""),"",O17-Q17) -> 0 | T17: =IF(AND(后台计算!DH11="洞穿",O17>0),IF(O17=ROUNDDOWN(N17*0.4,0),"实测附加=floor(主伤害×40%)；稳态来源待确认","实测附加关系需核对"),"") | U17: =IF(D17="","",后台计算!EQ11) -> 0 | V17: =IF(D17="","",后台计算!ER11) -> 0 | W17: =IF(D17="","",后台计算!ES11) -> 0 | X17: =IF(D17="","",IF(Boss参数!$B$60=1,"此前实测；缺失用预测","此前预测")) -> 此前实测；缺失用预测 | Y17: =IF(H17="","",IF(H17>Boss参数!$B$63*Boss参数!$B$62,"超过暂定合计上限",""))
A18: =行动模拟!A18 -> 10 | B18: =行动模拟!B18 -> 2 | C18: =行动模拟!C18 -> 1 | D18: =行动模拟!D18 -> 小瑞安侬｜唱予无忧之诗 | E18: =行动模拟!O18 -> 0 | F18: =行动模拟!P18 -> 0 | G18: =IF(行动模拟!D18="","",行动模拟!E18) -> — | H18: =IF(COUNT(行动模拟!F18:H18)=0,"",SUM(行动模拟!F18:H18)) | I18: =IF(H18="","",IF(G18="是",F18,IF(G18="否",E18,""))) | J18: =IF(OR(H18="",I18=""),"",H18-I18) | K18: =IF(J18="","",ABS(J18)) | L18: =IF(OR(H18="",I18=""),"",IF(H18=0,IF(I18=0,0,"实测为0"),ABS(J18)/H18)) | M18: =IF(H18="","",IF(AND(G18<>"是",G18<>"否"),"缺少暴击判定",IF(L18>0.03,"存在差异：请看核对说明并核对行动状态","数值差异≤3%；机制仍需核实"))) | N18: =IF(ISNUMBER(行动模拟!F18),行动模拟!F18,"") | O18: =IF(COUNT(行动模拟!G18:H18)=0,"",SUM(行动模拟!G18:H18)) | P18: =IF(H18="","",IF(G18="是",后台计算!DX12,IF(G18="否",后台计算!DW12,""))) | Q18: =IF(H18="","",IF(G18="是",后台计算!BV12-后台计算!DX12,IF(G18="否",后台计算!BU12-后台计算!DW12,""))) | R18: =IF(OR(N18="",P18=""),"",N18-P18) | S18: =IF(OR(O18="",Q18=""),"",O18-Q18) | T18: =IF(AND(后台计算!DH12="洞穿",O18>0),IF(O18=ROUNDDOWN(N18*0.4,0),"实测附加=floor(主伤害×40%)；稳态来源待确认","实测附加关系需核对"),"") | U18: =IF(D18="","",后台计算!EQ12) -> 0 | V18: =IF(D18="","",后台计算!ER12) -> 0 | W18: =IF(D18="","",后台计算!ES12) -> 0 | X18: =IF(D18="","",IF(Boss参数!$B$60=1,"此前实测；缺失用预测","此前预测")) -> 此前实测；缺失用预测 | Y18: =IF(H18="","",IF(H18>Boss参数!$B$63*Boss参数!$B$62,"超过暂定合计上限",""))
A19: =行动模拟!A19 -> 11 | B19: =行动模拟!B19 -> 2 | C19: =行动模拟!C19 -> 2 | D19: =行动模拟!D19 -> J｜热处理 | E19: =行动模拟!O19 -> 0 | F19: =行动模拟!P19 -> 0 | G19: =IF(行动模拟!D19="","",行动模拟!E19) -> — | H19: =IF(COUNT(行动模拟!F19:H19)=0,"",SUM(行动模拟!F19:H19)) | I19: =IF(H19="","",IF(G19="是",F19,IF(G19="否",E19,""))) | J19: =IF(OR(H19="",I19=""),"",H19-I19) | K19: =IF(J19="","",ABS(J19)) | L19: =IF(OR(H19="",I19=""),"",IF(H19=0,IF(I19=0,0,"实测为0"),ABS(J19)/H19)) | M19: =IF(H19="","",IF(AND(G19<>"是",G19<>"否"),"缺少暴击判定",IF(L19>0.03,"存在差异：请看核对说明并核对行动状态","数值差异≤3%；机制仍需核实"))) | N19: =IF(ISNUMBER(行动模拟!F19),行动模拟!F19,"") | O19: =IF(COUNT(行动模拟!G19:H19)=0,"",SUM(行动模拟!G19:H19)) | P19: =IF(H19="","",IF(G19="是",后台计算!DX13,IF(G19="否",后台计算!DW13,""))) | Q19: =IF(H19="","",IF(G19="是",后台计算!BV13-后台计算!DX13,IF(G19="否",后台计算!BU13-后台计算!DW13,""))) | R19: =IF(OR(N19="",P19=""),"",N19-P19) | S19: =IF(OR(O19="",Q19=""),"",O19-Q19) | T19: =IF(AND(后台计算!DH13="洞穿",O19>0),IF(O19=ROUNDDOWN(N19*0.4,0),"实测附加=floor(主伤害×40%)；稳态来源待确认","实测附加关系需核对"),"") | U19: =IF(D19="","",后台计算!EQ13) -> 0 | V19: =IF(D19="","",后台计算!ER13) -> 0 | W19: =IF(D19="","",后台计算!ES13) -> 0 | X19: =IF(D19="","",IF(Boss参数!$B$60=1,"此前实测；缺失用预测","此前预测")) -> 此前实测；缺失用预测 | Y19: =IF(H19="","",IF(H19>Boss参数!$B$63*Boss参数!$B$62,"超过暂定合计上限",""))
A20: =行动模拟!A20 -> 12 | B20: =行动模拟!B20 -> 2 | C20: =行动模拟!C20 -> 3 | D20: =行动模拟!D20 -> 37｜补充算式 | E20: =行动模拟!O20 -> 5324 | F20: =行动模拟!P20 -> 10531 | G20: =IF(行动模拟!D20="","",行动模拟!E20) -> 是 | H20: =IF(COUNT(行动模拟!F20:H20)=0,"",SUM(行动模拟!F20:H20)) -> 10531 | I20: =IF(H20="","",IF(G20="是",F20,IF(G20="否",E20,""))) -> 10531 | J20: =IF(OR(H20="",I20=""),"",H20-I20) -> 0 | K20: =IF(J20="","",ABS(J20)) -> 0 | L20: =IF(OR(H20="",I20=""),"",IF(H20=0,IF(I20=0,0,"实测为0"),ABS(J20)/H20)) -> 0 | M20: =IF(H20="","",IF(AND(G20<>"是",G20<>"否"),"缺少暴击判定",IF(L20>0.03,"存在差异：请看核对说明并核对行动状态","数值差异≤3%；机制仍需核实"))) -> 数值差异≤3%；机制仍需核实 | N20: =IF(ISNUMBER(行动模拟!F20),行动模拟!F20,"") -> 6371 | O20: =IF(COUNT(行动模拟!G20:H20)=0,"",SUM(行动模拟!G20:H20)) -> 4160 | P20: =IF(H20="","",IF(G20="是",后台计算!DX14,IF(G20="否",后台计算!DW14,""))) -> 6371 | Q20: =IF(H20="","",IF(G20="是",后台计算!BV14-后台计算!DX14,IF(G20="否",后台计算!BU14-后台计算!DW14,""))) -> 4160 | R20: =IF(OR(N20="",P20=""),"",N20-P20) -> 0 | S20: =IF(OR(O20="",Q20=""),"",O20-Q20) -> 0 | T20: =IF(AND(后台计算!DH14="洞穿",O20>0),IF(O20=ROUNDDOWN(N20*0.4,0),"实测附加=floor(主伤害×40%)；稳态来源待确认","实测附加关系需核对"),"") | U20: =IF(D20="","",后台计算!EQ14) -> 0 | V20: =IF(D20="","",后台计算!ER14) -> 0 | W20: =IF(D20="","",后台计算!ES14) -> 0 | X20: =IF(D20="","",IF(Boss参数!$B$60=1,"此前实测；缺失用预测","此前预测")) -> 此前实测；缺失用预测 | Y20: =IF(H20="","",IF(H20>Boss参数!$B$63*Boss参数!$B$62,"超过暂定合计上限",""))
